Workbook
Name A83728543L: 'ABS-total-value-dwellings'!$AF$1:$AF$10,'ABS-total-value-dwellings'!$AF$11:$AF$106
Name A83728543L_Data: 'ABS-total-value-dwellings'!$AF$11:$AF$106
Name A83728543L_Latest: 'ABS-total-value-dwellings'!$AF$106
Name A83728544R: 'ABS-total-value-dwellings'!$AU$1:$AU$10,'ABS-total-value-dwellings'!$AU$17:$AU$106
Name A83728544R_Data: 'ABS-total-value-dwellings'!$AU$17:$AU$106
Name A83728544R_Latest: 'ABS-total-value-dwellings'!$AU$106
Name A83728545T: 'ABS-total-value-dwellings'!$B$1:$B$10,'ABS-total-value-dwellings'!$B$11:$B$106
Name A83728545T_Data: 'ABS-total-value-dwellings'!$B$11:$B$106
Name A83728545T_Latest: 'ABS-total-value-dwellings'!$B$106
Name A83728546V: 'ABS-total-value-dwellings'!$Q$1:$Q$10,'ABS-total-value-dwellings'!$Q$17:$Q$106
Name A83728546V_Data: 'ABS-total-value-dwellings'!$Q$17:$Q$106
Name A83728546V_Latest: 'ABS-total-value-dwellings'!$Q$106
Name A83728547W: 'ABS-total-value-dwellings'!$AH$1:$AH$10,'ABS-total-value-dwellings'!$AH$11:$AH$106
Name A83728547W_Data: 'ABS-total-value-dwellings'!$AH$11:$AH$106
Name A83728547W_Latest: 'ABS-total-value-dwellings'!$AH$106
Name A83728548X: 'ABS-total-value-dwellings'!$AW$1:$AW$10,'ABS-total-value-dwellings'!$AW$17:$AW$106
Name A83728548X_Data: 'ABS-total-value-dwellings'!$AW$17:$AW$106
Name A83728548X_Latest: 'ABS-total-value-dwellings'!$AW$106
Name A83728549A: 'ABS-total-value-dwellings'!$D$1:$D$10,'ABS-total-value-dwellings'!$D$11:$D$106
Name A83728549A_Data: 'ABS-total-value-dwellings'!$D$11:$D$106
Name A83728549A_Latest: 'ABS-total-value-dwellings'!$D$106
Name A83728550K: 'ABS-total-value-dwellings'!$S$1:$S$10,'ABS-total-value-dwellings'!$S$17:$S$106
Name A83728550K_Data: 'ABS-total-value-dwellings'!$S$17:$S$106
Name A83728550K_Latest: 'ABS-total-value-dwellings'!$S$106
Name A83728551L: 'ABS-total-value-dwellings'!$AJ$1:$AJ$10,'ABS-total-value-dwellings'!$AJ$11:$AJ$106
Name A83728551L_Data: 'ABS-total-value-dwellings'!$AJ$11:$AJ$106
Name A83728551L_Latest: 'ABS-total-value-dwellings'!$AJ$106
Name A83728552R: 'ABS-total-value-dwellings'!$AY$1:$AY$10,'ABS-total-value-dwellings'!$AY$17:$AY$106
Name A83728552R_Data: 'ABS-total-value-dwellings'!$AY$17:$AY$106
Name A83728552R_Latest: 'ABS-total-value-dwellings'!$AY$106
Name A83728553T: 'ABS-total-value-dwellings'!$F$1:$F$10,'ABS-total-value-dwellings'!$F$11:$F$106
Name A83728553T_Data: 'ABS-total-value-dwellings'!$F$11:$F$106
Name A83728553T_Latest: 'ABS-total-value-dwellings'!$F$106
Name A83728554V: 'ABS-total-value-dwellings'!$U$1:$U$10,'ABS-total-value-dwellings'!$U$17:$U$106
Name A83728554V_Data: 'ABS-total-value-dwellings'!$U$17:$U$106
Name A83728554V_Latest: 'ABS-total-value-dwellings'!$U$106
Name A83728555W: 'ABS-total-value-dwellings'!$AL$1:$AL$10,'ABS-total-value-dwellings'!$AL$11:$AL$106
Name A83728555W_Data: 'ABS-total-value-dwellings'!$AL$11:$AL$106
Name A83728555W_Latest: 'ABS-total-value-dwellings'!$AL$106
Name A83728556X: 'ABS-total-value-dwellings'!$BA$1:$BA$10,'ABS-total-value-dwellings'!$BA$17:$BA$106
Name A83728556X_Data: 'ABS-total-value-dwellings'!$BA$17:$BA$106
Name A83728556X_Latest: 'ABS-total-value-dwellings'!$BA$106
Name A83728557A: 'ABS-total-value-dwellings'!$H$1:$H$10,'ABS-total-value-dwellings'!$H$11:$H$106
Name A83728557A_Data: 'ABS-total-value-dwellings'!$H$11:$H$106
Name A83728557A_Latest: 'ABS-total-value-dwellings'!$H$106
Name A83728558C: 'ABS-total-value-dwellings'!$W$1:$W$10,'ABS-total-value-dwellings'!$W$17:$W$106
Name A83728558C_Data: 'ABS-total-value-dwellings'!$W$17:$W$106
Name A83728558C_Latest: 'ABS-total-value-dwellings'!$W$106
Name A83728559F: 'ABS-total-value-dwellings'!$AN$1:$AN$10,'ABS-total-value-dwellings'!$AN$11:$AN$106
Name A83728559F_Data: 'ABS-total-value-dwellings'!$AN$11:$AN$106
Name A83728559F_Latest: 'ABS-total-value-dwellings'!$AN$106
Name A83728560R: 'ABS-total-value-dwellings'!$BC$1:$BC$10,'ABS-total-value-dwellings'!$BC$17:$BC$106
Name A83728560R_Data: 'ABS-total-value-dwellings'!$BC$17:$BC$106
Name A83728560R_Latest: 'ABS-total-value-dwellings'!$BC$106
Name A83728561T: 'ABS-total-value-dwellings'!$J$1:$J$10,'ABS-total-value-dwellings'!$J$11:$J$106
Name A83728561T_Data: 'ABS-total-value-dwellings'!$J$11:$J$106
Name A83728561T_Latest: 'ABS-total-value-dwellings'!$J$106
Name A83728562V: 'ABS-total-value-dwellings'!$Y$1:$Y$10,'ABS-total-value-dwellings'!$Y$17:$Y$106
Name A83728562V_Data: 'ABS-total-value-dwellings'!$Y$17:$Y$106
Name A83728562V_Latest: 'ABS-total-value-dwellings'!$Y$106

Sheet analysis
A1: Rent vs buy analysis - Sydney | B1: Set values | C1: Default values | T1: Renter calcs >> | X1: {=SUM(_xlfn._xlws.FILTER(X3:X82,ISNUMBER(X3:X82)))} -> 495610.31 | AI1: CGT calcs | AR1: Buyer calcs >> | AY1: Maintenance and renovation | BB1: Mortgage | BG1: {=SUM(_xlfn._xlws.FILTER(BG3:BG82,ISNUMBER(BG3:BG82)))} -> 847025.77 | BH1: Comparison vs inflation
A2: Ending renter-to-owner wealth ratio | B2: =_xlfn.XLOOKUP(Q_end,L:L,O:O) -> 1.5721835 | E2: ="Renter vs owner wealth, "&IF(Council_Area="Greater Sydney","Sydney",Council_Area)&IF(B10="2BR_F"," 2-bedroom flat"," 3-bedroom house") -> Renter vs owner wealth, Sydney 3-bedroom house | L2: Quarter ending | M2: Renter's portfolio | N2: Owner's home equity | O2: Renter-to-owner wealth ratio | P2: Renter-to-owner cash needs | Q2: Quarter of analysis | R2: Days in quarter | T2: Median weekly rents, new bonds | U2: Renter's rents | V2: Quarterly rent | W2: Other renter costs | X2: Renter's cashflow costs | Y2: Renter additional cashflow | Z2: Tax concessions | AA2: Renter investment contributions | AB2: Contributions (CPI-adjusted to Q_end) | AC2: MSCI World index, start Q | AD2: MSCI Aus index, start Q | AE2: Portfolio, start Q | AF2: MSCI World index, end Q | AG2: MSCI Aus index, end Q | AH2: Investment fees | AI2: Portfolio, end Q, before CGT | AJ2: Cost base (nominal) | AK2: Nominal gains ($) | AL2: Cost base (CPI-adjusted to Q_end) | AM2: Cost base + CPI to current quarter | AN2: Real gains ($) | AO2: CGT on withdrawals | AP2: Portfolio, end Q | AR2: Median home price | AS2: Depreciation | AT2: Home purchase costs | AU2: Home sale costs | AV2: Renovation | AW2: Renovation, cumulative | AX2: Adjusted home price | AY2: Maintenance | AZ2: Total p.a. as % of home value | BA2: Total p.a. as % of rent | BB2: Mortgage rates | BC2: Loan balance | BD2: Mortgage payment | BE2: Mortgage interest | BF2: Mortgage - principal component | BG2: Owner's cashflow costs | BH2: CPI | BI2: CPI (Q_st art = 100) | BJ2: MSCI World (Q_start=100) | BK2: MSCI Aus (Q_start=100) | BL2: Portfolio index (Q_start=100) | BM2: Portfolio (Q_start=100) | BN2: Median home price (Q_start = 100) | BO2: Adjusted home price (Q_start = 100)
A3: Average renter-to-owner cashflow needs excl. home purchase costs | B3: {=SUM(_xlfn._xlws.FILTER($X$3:$X$82,ISNUMBER($X$3:$X$82)))/(SUM(_xlfn._xlws.FILTER($BG$3:$BG$82,ISNUMBER($BG$3:$BG$82)))-AT3)} -> 0.67712268 | L3: =Q_start -> 38777 | M3: =AP3 -> 171246 | N3: =AX3-BC3 -> 80327.5 | O3: =M3/N3 -> 2.1318478 | P3: =X3/BG3 -> 0.028454399 | Q3: 1 | R3: =EOMONTH(L3,0)-EOMONTH(L3,-3) -> 90 | T3: =IF($B$10="3BR_H", INDEX('3BR_H-combined'!$C:$BH,MATCH($L3,'3BR_H-combined'!$B:$B,0),MATCH(Council_Area,'3BR_H-combined'!$C$1:$BH$1,0)), INDEX('2BR_F-combined'!$C:$BH,MATCH($L3,'2BR_F-combined'!$B:$B,0),MATCH(Council_Area,'2BR_F-combined'!$C$1:$BH$1,0))) -> 265 | U3: =IF(MOD(Q3,4)=1,T3,U2) -> 265 | V3: =U3*(R3)/7 -> 3407.1429 | W3: =$B$53/4*BH3/_xlfn.XLOOKUP(Q_end,cpi!A:A,cpi!B:B) -> 116.93158 | X3: =V3+W3 -> 3524.0744 | Y3: =BG3-X3 -> 120325.83 | Z3: =MAX(0,Y3*$B$47) -> 38504.264 | AA3: =(Y3+Z3)*eff_invest -> 158830.09 | AB3: =AA3*(_xlfn.XLOOKUP(Q_end,cpi!A:A,cpi!B:B)/BH3) -> 271663.29 | AC3: {=INDEX('msci-indices'!C:C,MATCH($L3,'msci-indices'!$B:$B)-2)} -> 754.87961 | AD3: {=INDEX('msci-indices'!D:D,MATCH($L3,'msci-indices'!$B:$B)-2)} -> 712.95625 | AE3: =AA3 -> 158830.09 | AF3: {=INDEX('msci-indices'!C:C,MATCH($L3,'msci-indices'!$B:$B)+1)} -> 809.32012 | AG3: {=INDEX('msci-indices'!D:D,MATCH($L3,'msci-indices'!$B:$B)+1)} -> 780.24347 | AH3: =(InvestFees/4)*AE3 -> 99.268806 | AI3: =((AF3/AC3)*GlobalPortfolio+(AG3/AD3)*AusPortfolio)*AE3-AH3 -> 171246 | AJ3: =AA3 -> 158830.09 | AK3: =AI3-AJ3 -> 12415.911 | AL3: =AJ3*(_xlfn.XLOOKUP(Q_end,cpi!A:A,cpi!B:B)/BH3) -> 271663.29 | AM3: =AA3 -> 158830.09 | AN3: =AI3-AM3 -> 12415.911 | AO3: =IF($B$49="Real gains",MAX($B$50*AN3,0),IF($B$49="Discounted nominal gains",MAX($B$50*AK3/2,0),0)) -> 0 | AP3: =AI3-AO3 -> 171246 | AR3: =IF($B$10="3BR_H", INDEX('ns-combined'!$C:$BH,MATCH($L3,'ns-combined'!$B:$B,0),MATCH(Council_Area,'ns-combined'!$C$1:$BH$1,0))*1000, INDEX('s-combined'!$C:$BH,MATCH($L3,'s-combined'!$B:$B,0),MATCH(Council_Area,'s-combined'!$C$1:$BH$1,0))*1000) -> 460000 | AS3: =AR3*$B$14/4 -> 1150 | AT3: =SUM(B20:B26)*AR3 -> 115090 | AU3: =SUM($B$28:$B$29)*AR3 -> 9200 | AV3: =AR3*$B$15/4 -> 1322.5 | AW3: =SUM($AV$3:AV3) -> 1322.5 | AX3: =AR3-AS3-AU3-AW3 -> 448327.5 | AY3: =$B$36*V3 -> 1192.5 | AZ3: =SUM(AY3:AY3)*4/AR3 -> 0.010369565 | BA3: =SUM(AY3:AY3)/V3 -> 0.35 | BB3: =IF(MortgageRate="Discounted",_xlfn.XLOOKUP(L3,'mortgage-rates'!$A:$A,'mortgage-rates'!$E:$E)/100,_xlfn.XLOOKUP(L3,'mortgage-rates'!$A:$A,'mortgage-rates'!$D:$D)/100) -> 0.0664 | BC3: =(1-B20)*AR3 -> 368000 | BD3: =IF($B$16*12/3-Q3+1>0,-PMT($BB3/4,$B$16*12/3-Q3+1,BC3),0) -> 7567.3998 | BE3: =BC3*($BB3/4) -> 6108.8 | BF3: =BD3-BE3 -> 1458.5998 | BG3: =AT3+AY3+BD3 -> 123849.9 | BH3: =INDEX(cpi!B:B,MATCH($L3,cpi!A:A)) -> 84.6 | BI3: =100*BH3/BH$3 -> 100 | BJ3: =100*AC3/AC$3 -> 100 | BK3: =100*AD3/AD$3 -> 100 | BL3: =BJ3*GlobalPortfolio+BK3*AusPortfolio -> 100 | BM3: =100*AE3/$AE$3 -> 100 | BN3: =100*AR3/AR$3 -> 100 | BO3: =100*AX3/AX$3 -> 100
A4: Median home price growth p.a. | B4: =((_xlfn.XLOOKUP(Q_end,L:L,AR:AR)/_xlfn.XLOOKUP(Q_start,L:L,AR:AR))^(1/YEARFRAC(EOMONTH(Q_start,-3)+1,EOMONTH(Q_end,0))))-1 -> 0.063057079 | L4: =IF(DATE(YEAR(L3),MONTH(L3)+3,1)<=Q_end,DATE(YEAR(L3),MONTH(L3)+3,1),"") -> 38869 | M4: =AP4 -> 177232.23 | N4: =AX4-BC4 -> 103741.72 | O4: =M4/N4 -> 1.7083988 | P4: =X4/BG4 -> 0.39708887 | Q4: 2 | R4: =EOMONTH(L4,0)-EOMONTH(L4,-3) -> 91 | T4: =IF($B$10="3BR_H", INDEX('3BR_H-combined'!$C:$BH,MATCH($L4,'3BR_H-combined'!$B:$B,0),MATCH(Council_Area,'3BR_H-combined'!$C$1:$BH$1,0)), INDEX('2BR_F-combined'!$C:$BH,MATCH($L4,'2BR_F-combined'!$B:$B,0),MATCH(Council_Area,'2BR_F-combined'!$C$1:$BH$1,0))) -> 265 | U4: =IF(MOD(Q4,4)=1,T4,U3) -> 265 | V4: =U4*(R4)/7 -> 3445 | W4: =$B$53/4*BH4/_xlfn.XLOOKUP(Q_end,cpi!A:A,cpi!B:B) -> 118.7284 | X4: =V4+W4 -> 3563.7284 | Y4: =BG4-X4 -> 5410.9084 | Z4: =Y4*$B$47 -> 1731.4907 | AA4: =(Y4+Z4)*eff_invest -> 7142.3991 | AB4: =AA4*(_xlfn.XLOOKUP(Q_end,cpi!A:A,cpi!B:B)/BH4) -> 12031.492 | AC4: {=INDEX('msci-indices'!C:C,MATCH($L4,'msci-indices'!$B:$B)-2)} -> 809.32012 | AD4: {=INDEX('msci-indices'!D:D,MATCH($L4,'msci-indices'!$B:$B)-2)} -> 780.24347 | AE4: =AI3+AA4 -> 178388.4 | AF4: {=INDEX('msci-indices'!C:C,MATCH($L4,'msci-indices'!$B:$B)+1)} -> 802.64573 | AG4: {=INDEX('msci-indices'!D:D,MATCH($L4,'msci-indices'!$B:$B)+1)} -> 780.02674 | AH4: =(InvestFees/4)*AE4 -> 111.49275 | AI4: =((AF4/AC4)*GlobalPortfolio+(AG4/AD4)*AusPortfolio)*AE4-AH4 -> 177232.23 | AJ4: =AJ3+AA4 -> 165972.49 | AK4: =AI4-AJ4 -> 11259.746 | AL4: =AJ4*(_xlfn.XLOOKUP(Q_end,cpi!A:A,cpi!B:B)/BH4) -> 279583.46 | AM4: {=SUMPRODUCT($AA$3:AA4,_xlfn.SORTBY($BH$3:BH4,_xlfn.SEQUENCE(ROWS($BH$3:BH4)),-1)/$BH$3)} -> 168413.14 | AN4: =AI4-AM4 -> 8819.0946 | AO4: =IF($B$49="Real gains",MAX($B$50*AN4,0),IF($B$49="Discounted nominal gains",MAX($B$50*AK4/2,0),0)) -> 0 | AP4: =AI4-AO4 -> 177232.23 | AR4: =IF($B$10="3BR_H", INDEX('ns-combined'!$C:$BH,MATCH($L4,'ns-combined'!$B:$B,0),MATCH(Council_Area,'ns-combined'!$C$1:$BH$1,0))*1000, INDEX('s-combined'!$C:$BH,MATCH($L4,'s-combined'!$B:$B,0),MATCH(Council_Area,'s-combined'!$C$1:$BH$1,0))*1000) -> 485000 | AS4: =AS3+$AS$3 -> 2300 | AT4: 0 | AU4: =SUM($B$28:$B$29)*AR4 -> 9700 | AV4: =AR4*$B$15/4 -> 1394.375 | AW4: =SUM($AV$3:AV4) -> 2716.875 | AX4: =AR4-AS4-AU4-AW4 -> 470283.12 | AY4: =$B$36*V4 -> 1205.75 | AZ4: =SUM(AY4:AY4)*4/AR4 -> 0.0099443299 | BA4: =SUM(AY4:AY4)/V4 -> 0.35 | BB4: =IF(MortgageRate="Discounted",_xlfn.XLOOKUP(L4,'mortgage-rates'!$A:$A,'mortgage-rates'!$E:$E)/100,_xlfn.XLOOKUP(L4,'mortgage-rates'!$A:$A,'mortgage-rates'!$D:$D)/100) -> 0.0693 | BC4: =BC3-BF3 -> 366541.4 | BD4: =IF($B$16*12/3-Q4+1>0,-PMT($BB4/4,$B$16*12/3-Q4+1,BC4),0) -> 7768.8868 | BE4: =BC4*($BB4/4) -> 6350.3298 | BF4: =BD4-BE4 -> 1418.557 | BG4: =AT4+AY4+BD4 -> 8974.6368 | BH4: =INDEX(cpi!B:B,MATCH($L4,cpi!A:A)) -> 85.9 | BI4: =100*BH4/BH$3 -> 101.53664 | BJ4: =100*AC4/AC$3 -> 107.21181 | BK4: =100*AD4/AD$3 -> 109.43778 | BL4: =BJ4*GlobalPortfolio+BK4*AusPortfolio -> 107.8796 | BM4: =100*AE4/$AE$3 -> 112.31398 | BN4: =100*AR4/AR$3 -> 105.43478 | BO4: =100*AX4/AX$3 -> 104.89723
A5: Adjusted home price growth p.a. | B5: =((_xlfn.XLOOKUP(Q_end,L:L,AX:AX)/_xlfn.XLOOKUP(Q_start,L:L,AX:AX))^(1/YEARFRAC(EOMONTH(Q_start,-3)+1,EOMONTH(Q_end,0))))-1 -> 0.052061806 | L5: =DATE(YEAR(L4),MONTH(L4)+3,1) -> 38961 | M5: =AP5 -> 191229.57 | N5: =AX5-BC5 -> 89913.282 | O5: =M5/N5 -> 2.1268222 | P5: =X5/BG5 -> 0.39199261 | Q5: 3 | R5: =EOMONTH(L5,0)-EOMONTH(L5,-3) -> 92 | T5: =IF($B$10="3BR_H", INDEX('3BR_H-combined'!$C:$BH,MATCH($L5,'3BR_H-combined'!$B:$B,0),MATCH(Council_Area,'3BR_H-combined'!$C$1:$BH$1,0)), INDEX('2BR_F-combined'!$C:$BH,MATCH($L5,'2BR_F-combined'!$B:$B,0),MATCH(Council_Area,'2BR_F-combined'!$C$1:$BH$1,0))) -> 270 | U5: =IF(MOD(Q5,4)=1,T5,U4) -> 265 | V5: =U5*(R5)/7 -> 3482.8571 | W5: =$B$53/4*BH5/_xlfn.XLOOKUP(Q_end,cpi!A:A,cpi!B:B) -> 119.69592 | X5: =V5+W5 -> 3602.5531 | Y5: =BG5-X5 -> 5587.8065 | Z5: =Y5*$B$47 -> 1788.0981 | AA5: =(Y5+Z5)*eff_invest -> 7375.9046 | AB5: =AA5*(_xlfn.XLOOKUP(Q_end,cpi!A:A,cpi!B:B)/BH5) -> 12324.404 | AC5: {=INDEX('msci-indices'!C:C,MATCH($L5,'msci-indices'!$B:$B)-2)} -> 802.64573 | AD5: {=INDEX('msci-indices'!D:D,MATCH($L5,'msci-indices'!$B:$B)-2)} -> 780.02674 | AE5: =AI4+AA5 -> 184608.14 | AF5: {=INDEX('msci-indices'!C:C,MATCH($L5,'msci-indices'!$B:$B)+1)} -> 835.13401 | AG5: {=INDEX('msci-indices'!D:D,MATCH($L5,'msci-indices'!$B:$B)+1)} -> 801.24067 | AH5: =(InvestFees/4)*AE5 -> 115.38009 | AI5: =((AF5/AC5)*GlobalPortfolio+(AG5/AD5)*AusPortfolio)*AE5-AH5 -> 191229.57 | AJ5: =AJ4+AA5 -> 173348.39 | AK5: =AI5-AJ5 -> 17881.172 | AL5: =AJ5*(_xlfn.XLOOKUP(Q_end,cpi!A:A,cpi!B:B)/BH5) -> 289647.95 | AM5: {=SUMPRODUCT($AA$3:AA5,_xlfn.SORTBY($BH$3:BH5,_xlfn.SEQUENCE(ROWS($BH$3:BH5)),-1)/$BH$3)} -> 177212.99 | AN5: =AI5-AM5 -> 14016.571 | AO5: =IF($B$49="Real gains",MAX($B$50*AN5,0),IF($B$49="Discounted nominal gains",MAX($B$50*AK5/2,0),0)) -> 0 | AP5: =AI5-AO5 -> 191229.57 | AR5: =IF($B$10="3BR_H", INDEX('ns-combined'!$C:$BH,MATCH($L5,'ns-combined'!$B:$B,0),MATCH(Council_Area,'ns-combined'!$C$1:$BH$1,0))*1000, INDEX('s-combined'!$C:$BH,MATCH($L5,'s-combined'!$B:$B,0),MATCH(Council_Area,'s-combined'!$C$1:$BH$1,0))*1000) -> 472000 | AS5: =AS4+$AS$3 -> 3450 | AT5: 0 | AU5: =SUM($B$28:$B$29)*AR5 -> 9440 | AV5: =AR5*$B$15/4 -> 1357 | AW5: =SUM($AV$3:AV5) -> 4073.875 | AX5: =AR5-AS5-AU5-AW5 -> 455036.12 | AY5: =$B$36*V5 -> 1219 | AZ5: =SUM(AY5:AY5)*4/AR5 -> 0.010330508 | BA5: =SUM(AY5:AY5)/V5 -> 0.35 | BB5: =IF(MortgageRate="Discounted",_xlfn.XLOOKUP(L5,'mortgage-rates'!$A:$A,'mortgage-rates'!$E:$E)/100,_xlfn.XLOOKUP(L5,'mortgage-rates'!$A:$A,'mortgage-rates'!$D:$D)/100) -> 0.0722 | BC5: =BC4-BF4 -> 365122.84 | BD5: =IF($B$16*12/3-Q5+1>0,-PMT($BB5/4,$B$16*12/3-Q5+1,BC5),0) -> 7971.3596 | BE5: =BC5*($BB5/4) -> 6590.4673 | BF5: =BD5-BE5 -> 1380.8922 | BG5: =AT5+AY5+BD5 -> 9190.3596 | BH5: =INDEX(cpi!B:B,MATCH($L5,cpi!A:A)) -> 86.6 | BI5: =100*BH5/BH$3 -> 102.36407 | BJ5: =100*AC5/AC$3 -> 106.32765 | BK5: =100*AD5/AD$3 -> 109.40738 | BL5: =BJ5*GlobalPortfolio+BK5*AusPortfolio -> 107.25157 | BM5: =100*AE5/$AE$3 -> 116.22995 | BN5: =100*AR5/AR$3 -> 102.6087 | BO5: =100*AX5/AX$3 -> 101.49637
A6: Rent growth p.a. | B6: =((_xlfn.XLOOKUP(Q_end,L:L,U:U)/_xlfn.XLOOKUP(Q_start,L:L,U:U))^(1/YEARFRAC(EOMONTH(Q_start,-3)+1,EOMONTH(Q_end,0))))-1 -> 0.049766255 | L6: =DATE(YEAR(L5),MONTH(L5)+3,1) -> 39052 | M6: =AP6 -> 216879.36 | N6: =AX6-BC6 -> 109306.8 | O6: =M6/N6 -> 1.9841342 | P6: =X6/BG6 -> 0.3846743 | Q6: 4 | R6: =EOMONTH(L6,0)-EOMONTH(L6,-3) -> 92 | T6: =IF($B$10="3BR_H", INDEX('3BR_H-combined'!$C:$BH,MATCH($L6,'3BR_H-combined'!$B:$B,0),MATCH(Council_Area,'3BR_H-combined'!$C$1:$BH$1,0)), INDEX('2BR_F-combined'!$C:$BH,MATCH($L6,'2BR_F-combined'!$B:$B,0),MATCH(Council_Area,'2BR_F-combined'!$C$1:$BH$1,0))) -> 275 | U6: =IF(MOD(Q6,4)=1,T6,U5) -> 265 | V6: =U6*(R6)/7 -> 3482.8571 | W6: =$B$53/4*BH6/_xlfn.XLOOKUP(Q_end,cpi!A:A,cpi!B:B) -> 119.83414 | X6: =V6+W6 -> 3602.6913 | Y6: =BG6-X6 -> 5762.8713 | Z6: =Y6*$B$47 -> 1844.1188 | AA6: =(Y6+Z6)*eff_invest -> 7606.9901 | AB6: =AA6*(_xlfn.XLOOKUP(Q_end,cpi!A:A,cpi!B:B)/BH6) -> 12695.865 | AC6: {=INDEX('msci-indices'!C:C,MATCH($L6,'msci-indices'!$B:$B)-2)} -> 835.13401 | AD6: {=INDEX('msci-indices'!D:D,MATCH($L6,'msci-indices'!$B:$B)-2)} -> 801.24067 | AE6: =AI5+AA6 -> 198836.56 | AF6: {=INDEX('msci-indices'!C:C,MATCH($L6,'msci-indices'!$B:$B)+1)} -> 906.58022 | AG6: {=INDEX('msci-indices'!D:D,MATCH($L6,'msci-indices'!$B:$B)+1)} -> 885.32149 | AH6: =(InvestFees/4)*AE6 -> 124.27285 | AI6: =((AF6/AC6)*GlobalPortfolio+(AG6/AD6)*AusPortfolio)*AE6-AH6 -> 216879.36 | AJ6: =AJ5+AA6 -> 180955.38 | AK6: =AI6-AJ6 -> 35923.979 | AL6: =AJ6*(_xlfn.XLOOKUP(Q_end,cpi!A:A,cpi!B:B)/BH6) -> 302009.73 | AM6: {=SUMPRODUCT($AA$3:AA6,_xlfn.SORTBY($BH$3:BH6,_xlfn.SEQUENCE(ROWS($BH$3:BH6)),-1)/$BH$3)} -> 185180.17 | AN6: =AI6-AM6 -> 31699.196 | AO6: =IF($B$49="Real gains",MAX($B$50*AN6,0),IF($B$49="Discounted nominal gains",MAX($B$50*AK6/2,0),0)) -> 0 | AP6: =AI6-AO6 -> 216879.36 | AR6: =IF($B$10="3BR_H", INDEX('ns-combined'!$C:$BH,MATCH($L6,'ns-combined'!$B:$B,0),MATCH(Council_Area,'ns-combined'!$C$1:$BH$1,0))*1000, INDEX('s-combined'!$C:$BH,MATCH($L6,'s-combined'!$B:$B,0),MATCH(Council_Area,'s-combined'!$C$1:$BH$1,0))*1000) -> 493000 | AS6: =AS5+$AS$3 -> 4600 | AT6: 0 | AU6: =SUM($B$28:$B$29)*AR6 -> 9860 | AV6: =AR6*$B$15/4 -> 1417.375 | AW6: =SUM($AV$3:AV6) -> 5491.25 | AX6: =AR6-AS6-AU6-AW6 -> 473048.75 | AY6: =$B$36*V6 -> 1219 | AZ6: =SUM(AY6:AY6)*4/AR6 -> 0.0098904665 | BA6: =SUM(AY6:AY6)/V6 -> 0.35 | BB6: =IF(MortgageRate="Discounted",_xlfn.XLOOKUP(L6,'mortgage-rates'!$A:$A,'mortgage-rates'!$E:$E)/100,_xlfn.XLOOKUP(L6,'mortgage-rates'!$A:$A,'mortgage-rates'!$D:$D)/100) -> 0.0747 | BC6: =BC5-BF5 -> 363741.95 | BD6: =IF($B$16*12/3-Q6+1>0,-PMT($BB6/4,$B$16*12/3-Q6+1,BC6),0) -> 8146.5626 | BE6: =BC6*($BB6/4) -> 6792.8809 | BF6: =BD6-BE6 -> 1353.6817 | BG6: =AT6+AY6+BD6 -> 9365.5626 | BH6: =INDEX(cpi!B:B,MATCH($L6,cpi!A:A)) -> 86.7 | BI6: =100*BH6/BH$3 -> 102.48227 | BJ6: =100*AC6/AC$3 -> 110.63142 | BK6: =100*AD6/AD$3 -> 112.38287 | BL6: =BJ6*GlobalPortfolio+BK6*AusPortfolio -> 111.15685 | BM6: =100*AE6/$AE$3 -> 125.18822 | BN6: =100*AR6/AR$3 -> 107.17391 | BO6: =100*AX6/AX$3 -> 105.51411
A7: Investment index (country-weighted) growth p.a. | B7: =((_xlfn.XLOOKUP(Q_end,L:L,BL:BL)/_xlfn.XLOOKUP(Q_start,L:L,BL:BL))^(1/YEARFRAC(EOMONTH(Q_start,-3)+1,EOMONTH(Q_end,0))))-1 -> 0.080631422 | L7: =DATE(YEAR(L6),MONTH(L6)+3,1) -> 39142 | M7: =AP7 -> 233286.98 | N7: =AX7-BC7 -> 87573.481 | O7: =M7/N7 -> 2.6638999 | P7: =X7/BG7 -> 0.39545095 | Q7: 5 | R7: =EOMONTH(L7,0)-EOMONTH(L7,-3) -> 90 | T7: =IF($B$10="3BR_H", INDEX('3BR_H-combined'!$C:$BH,MATCH($L7,'3BR_H-combined'!$B:$B,0),MATCH(Council_Area,'3BR_H-combined'!$C$1:$BH$1,0)), INDEX('2BR_F-combined'!$C:$BH,MATCH($L7,'2BR_F-combined'!$B:$B,0),MATCH(Council_Area,'2BR_F-combined'!$C$1:$BH$1,0))) -> 280 | U7: =IF(MOD(Q7,4)=1,T7,U6) -> 280 | V7: =U7*(R7)/7 -> 3600 | W7: =$B$53/4*BH7/_xlfn.XLOOKUP(Q_end,cpi!A:A,cpi!B:B) -> 119.83414 | X7: =V7+W7 -> 3719.8341 | Y7: =BG7-X7 -> 5686.7285 | Z7: =Y7*$B$47 -> 1819.7531 | AA7: =(Y7+Z7)*eff_invest -> 7506.4816 | AB7: =AA7*(_xlfn.XLOOKUP(Q_end,cpi!A:A,cpi!B:B)/BH7) -> 12528.119 | AC7: {=INDEX('msci-indices'!C:C,MATCH($L7,'msci-indices'!$B:$B)-2)} -> 906.58022 | AD7: {=INDEX('msci-indices'!D:D,MATCH($L7,'msci-indices'!$B:$B)-2)} -> 885.32149 | AE7: =AI6+AA7 -> 224385.84 | AF7: {=INDEX('msci-indices'!C:C,MATCH($L7,'msci-indices'!$B:$B)+1)} -> 932.09759 | AG7: {=INDEX('msci-indices'!D:D,MATCH($L7,'msci-indices'!$B:$B)+1)} -> 946.08734 | AH7: =(InvestFees/4)*AE7 -> 140.24115 | AI7: =((AF7/AC7)*GlobalPortfolio+(AG7/AD7)*AusPortfolio)*AE7-AH7 -> 233286.98 | AJ7: =AJ6+AA7 -> 188461.86 | AK7: =AI7-AJ7 -> 44825.12 | AL7: =AJ7*(_xlfn.XLOOKUP(Q_end,cpi!A:A,cpi!B:B)/BH7) -> 314537.85 | AM7: {=SUMPRODUCT($AA$3:AA7,_xlfn.SORTBY($BH$3:BH7,_xlfn.SEQUENCE(ROWS($BH$3:BH7)),-1)/$BH$3)} -> 192873.01 | AN7: =AI7-AM7 -> 40413.972 | AO7: =IF($B$49="Real gains",MAX($B$50*AN7,0),IF($B$49="Discounted nominal gains",MAX($B$50*AK7/2,0),0)) -> 0 | AP7: =AI7-AO7 -> 233286.98 | AR7: =IF($B$10="3BR_H", INDEX('ns-combined'!$C:$BH,MATCH($L7,'ns-combined'!$B:$B,0),MATCH(Council_Area,'ns-combined'!$C$1:$BH$1,0))*1000, INDEX('s-combined'!$C:$BH,MATCH($L7,'s-combined'!$B:$B,0),MATCH(Council_Area,'s-combined'!$C$1:$BH$1,0))*1000) -> 472000 | AS7: =AS6+$AS$3 -> 5750 | AT7: 0 | AU7: =SUM($B$28:$B$29)*AR7 -> 9440 | AV7: =AR7*$B$15/4 -> 1357 | AW7: =SUM($AV$3:AV7) -> 6848.25 | AX7: =AR7-AS7-AU7-AW7 -> 449961.75 | AY7: =$B$36*V7 -> 1260 | AZ7: =SUM(AY7:AY7)*4/AR7 -> 0.010677966 | BA7: =SUM(AY7:AY7)/V7 -> 0.35 | BB7: =IF(MortgageRate="Discounted",_xlfn.XLOOKUP(L7,'mortgage-rates'!$A:$A,'mortgage-rates'!$E:$E)/100,_xlfn.XLOOKUP(L7,'mortgage-rates'!$A:$A,'mortgage-rates'!$D:$D)/100) -> 0.0747 | BC7: =BC6-BF6 -> 362388.27 | BD7: =IF($B$16*12/3-Q7+1>0,-PMT($BB7/4,$B$16*12/3-Q7+1,BC7),0) -> 8146.5626 | BE7: =BC7*($BB7/4) -> 6767.6009 | BF7: =BD7-BE7 -> 1378.9617 | BG7: =AT7+AY7+BD7 -> 9406.5626 | BH7: =INDEX(cpi!B:B,MATCH($L7,cpi!A:A)) -> 86.7 | BI7: =100*BH7/BH$3 -> 102.48227 | BJ7: =100*AC7/AC$3 -> 120.096 | BK7: =100*AD7/AD$3 -> 124.17613 | BL7: =BJ7*GlobalPortfolio+BK7*AusPortfolio -> 121.32004 | BM7: =100*AE7/$AE$3 -> 141.27414 | BN7: =100*AR7/AR$3 -> 102.6087 | BO7: =100*AX7/AX$3 -> 100.36452
A8: CPI growth p.a. | B8: =((_xlfn.XLOOKUP(Q_end,L:L,BI:BI)/_xlfn.XLOOKUP(Q_start,L:L,BI:BI))^(1/YEARFRAC(EOMONTH(Q_start,-3)+1,EOMONTH(Q_end,0))))-1 -> 0.027199758 | L8: =DATE(YEAR(L7),MONTH(L7)+3,1) -> 39234 | M8: =AP8 -> 255575.37 | N8: =AX8-BC8 -> 113804.94 | O8: =M8/N8 -> 2.2457317 | P8: =X8/BG8 -> 0.39925602 | Q8: 6 | R8: =EOMONTH(L8,0)-EOMONTH(L8,-3) -> 91 | T8: =IF($B$10="3BR_H", INDEX('3BR_H-combined'!$C:$BH,MATCH($L8,'3BR_H-combined'!$B:$B,0),MATCH(Council_Area,'3BR_H-combined'!$C$1:$BH$1,0)), INDEX('2BR_F-combined'!$C:$BH,MATCH($L8,'2BR_F-combined'!$B:$B,0),MATCH(Council_Area,'2BR_F-combined'!$C$1:$BH$1,0))) -> 280 | U8: =IF(MOD(Q8,4)=1,T8,U7) -> 280 | V8: =U8*(R8)/7 -> 3640 | W8: =$B$53/4*BH8/_xlfn.XLOOKUP(Q_end,cpi!A:A,cpi!B:B) -> 121.21631 | X8: =V8+W8 -> 3761.2163 | Y8: =BG8-X8 -> 5659.3463 | Z8: =Y8*$B$47 -> 1810.9908 | AA8: =(Y8+Z8)*eff_invest -> 7470.3371 | AB8: =AA8*(_xlfn.XLOOKUP(Q_end,cpi!A:A,cpi!B:B)/BH8) -> 12325.63 | AC8: {=INDEX('msci-indices'!C:C,MATCH($L8,'msci-indices'!$B:$B)-2)} -> 932.09759 | AD8: {=INDEX('msci-indices'!D:D,MATCH($L8,'msci-indices'!$B:$B)-2)} -> 946.08734 | AE8: =AI7+AA8 -> 240757.32 | AF8: {=INDEX('msci-indices'!C:C,MATCH($L8,'msci-indices'!$B:$B)+1)} -> 991.70582 | AG8: {=INDEX('msci-indices'!D:D,MATCH($L8,'msci-indices'!$B:$B)+1)} -> 1000.9831 | AH8: =(InvestFees/4)*AE8 -> 150.47333 | AI8: =((AF8/AC8)*GlobalPortfolio+(AG8/AD8)*AusPortfolio)*AE8-AH8 -> 255575.37 | AJ8: =AJ7+AA8 -> 195932.2 | AK8: =AI8-AJ8 -> 59643.165 | AL8: =AJ8*(_xlfn.XLOOKUP(Q_end,cpi!A:A,cpi!B:B)/BH8) -> 323276.96 | AM8: {=SUMPRODUCT($AA$3:AA8,_xlfn.SORTBY($BH$3:BH8,_xlfn.SEQUENCE(ROWS($BH$3:BH8)),-1)/$BH$3)} -> 202407.78 | AN8: =AI8-AM8 -> 53167.584 | AO8: =IF($B$49="Real gains",MAX($B$50*AN8,0),IF($B$49="Discounted nominal gains",MAX($B$50*AK8/2,0),0)) -> 0 | AP8: =AI8-AO8 -> 255575.37 | AR8: =IF($B$10="3BR_H", INDEX('ns-combined'!$C:$BH,MATCH($L8,'ns-combined'!$B:$B,0),MATCH(Council_Area,'ns-combined'!$C$1:$BH$1,0))*1000, INDEX('s-combined'!$C:$BH,MATCH($L8,'s-combined'!$B:$B,0),MATCH(Council_Area,'s-combined'!$C$1:$BH$1,0))*1000) -> 500000 | AS8: =AS7+$AS$3 -> 6900 | AT8: 0 | AU8: =SUM($B$28:$B$29)*AR8 -> 10000 | AV8: =AR8*$B$15/4 -> 1437.5 | AW8: =SUM($AV$3:AV8) -> 8285.75 | AX8: =AR8-AS8-AU8-AW8 -> 474814.25 | AY8: =$B$36*V8 -> 1274 | AZ8: =SUM(AY8:AY8)*4/AR8 -> 0.010192 | BA8: =SUM(AY8:AY8)/V8 -> 0.35 | BB8: =IF(MortgageRate="Discounted",_xlfn.XLOOKUP(L8,'mortgage-rates'!$A:$A,'mortgage-rates'!$E:$E)/100,_xlfn.XLOOKUP(L8,'mortgage-rates'!$A:$A,'mortgage-rates'!$D:$D)/100) -> 0.0747 | BC8: =BC7-BF7 -> 361009.31 | BD8: =IF($B$16*12/3-Q8+1>0,-PMT($BB8/4,$B$16*12/3-Q8+1,BC8),0) -> 8146.5626 | BE8: =BC8*($BB8/4) -> 6741.8488 | BF8: =BD8-BE8 -> 1404.7138 | BG8: =AT8+AY8+BD8 -> 9420.5626 | BH8: =INDEX(cpi!B:B,MATCH($L8,cpi!A:A)) -> 87.7 | BI8: =100*BH8/BH$3 -> 103.6643 | BJ8: =100*AC8/AC$3 -> 123.47632 | BK8: =100*AD8/AD$3 -> 132.69921 | BL8: =BJ8*GlobalPortfolio+BK8*AusPortfolio -> 126.24319 | BM8: =100*AE8/$AE$3 -> 151.58168 | BN8: =100*AR8/AR$3 -> 108.69565 | BO8: =100*AX8/AX$3 -> 105.9079
L9: =DATE(YEAR(L8),MONTH(L8)+3,1) -> 39326 | M9: =AP9 -> 271190.09 | N9: =AX9-BC9 -> 113599.28 | O9: =M9/N9 -> 2.3872518 | P9: =X9/BG9 -> 0.39570697 | Q9: 7 | R9: =EOMONTH(L9,0)-EOMONTH(L9,-3) -> 92 | T9: =IF($B$10="3BR_H", INDEX('3BR_H-combined'!$C:$BH,MATCH($L9,'3BR_H-combined'!$B:$B,0),MATCH(Council_Area,'3BR_H-combined'!$C$1:$BH$1,0)), INDEX('2BR_F-combined'!$C:$BH,MATCH($L9,'2BR_F-combined'!$B:$B,0),MATCH(Council_Area,'2BR_F-combined'!$C$1:$BH$1,0))) -> 295 | U9: =IF(MOD(Q9,4)=1,T9,U8) -> 280 | V9: =U9*(R9)/7 -> 3680 | W9: =$B$53/4*BH9/_xlfn.XLOOKUP(Q_end,cpi!A:A,cpi!B:B) -> 121.90739 | X9: =V9+W9 -> 3801.9074 | Y9: =BG9-X9 -> 5805.9784 | Z9: =Y9*$B$47 -> 1857.9131 | AA9: =(Y9+Z9)*eff_invest -> 7663.8914 | AB9: =AA9*(_xlfn.XLOOKUP(Q_end,cpi!A:A,cpi!B:B)/BH9) -> 12573.3 | AC9: {=INDEX('msci-indices'!C:C,MATCH($L9,'msci-indices'!$B:$B)-2)} -> 991.70582 | AD9: {=INDEX('msci-indices'!D:D,MATCH($L9,'msci-indices'!$B:$B)-2)} -> 1000.9831 | AE9: =AI8+AA9 -> 263239.26 | AF9: {=INDEX('msci-indices'!C:C,MATCH($L9,'msci-indices'!$B:$B)+1)} -> 1009.8701 | AG9: {=INDEX('msci-indices'!D:D,MATCH($L9,'msci-indices'!$B:$B)+1)} -> 1061.067 | AH9: =(InvestFees/4)*AE9 -> 164.52454 | AI9: =((AF9/AC9)*GlobalPortfolio+(AG9/AD9)*AusPortfolio)*AE9-AH9 -> 271190.09 | AJ9: =AJ8+AA9 -> 203596.09 | AK9: =AI9-AJ9 -> 67593.998 | AL9: =AJ9*(_xlfn.XLOOKUP(Q_end,cpi!A:A,cpi!B:B)/BH9) -> 334017.63 | AM9: {=SUMPRODUCT($AA$3:AA9,_xlfn.SORTBY($BH$3:BH9,_xlfn.SEQUENCE(ROWS($BH$3:BH9)),-1)/$BH$3)} -> 211280.71 | AN9: =AI9-AM9 -> 59909.385 | AO9: =IF($B$49="Real gains",MAX($B$50*AN9,0),IF($B$49="Discounted nominal gains",MAX($B$50*AK9/2,0),0)) -> 0 | AP9: =AI9-AO9 -> 271190.09 | AR9: =IF($B$10="3BR_H", INDEX('ns-combined'!$C:$BH,MATCH($L9,'ns-combined'!$B:$B,0),MATCH(Council_Area,'ns-combined'!$C$1:$BH$1,0))*1000, INDEX('s-combined'!$C:$BH,MATCH($L9,'s-combined'!$B:$B,0),MATCH(Council_Area,'s-combined'!$C$1:$BH$1,0))*1000) -> 501000 | AS9: =AS8+$AS$3 -> 8050 | AT9: 0 | AU9: =SUM($B$28:$B$29)*AR9 -> 10020 | AV9: =AR9*$B$15/4 -> 1440.375 | AW9: =SUM($AV$3:AV9) -> 9726.125 | AX9: =AR9-AS9-AU9-AW9 -> 473203.88 | AY9: =$B$36*V9 -> 1288 | AZ9: =SUM(AY9:AY9)*4/AR9 -> 0.010283433 | BA9: =SUM(AY9:AY9)/V9 -> 0.35 | BB9: =IF(MortgageRate="Discounted",_xlfn.XLOOKUP(L9,'mortgage-rates'!$A:$A,'mortgage-rates'!$E:$E)/100,_xlfn.XLOOKUP(L9,'mortgage-rates'!$A:$A,'mortgage-rates'!$D:$D)/100) -> 0.0772 | BC9: =BC8-BF8 -> 359604.59 | BD9: =IF($B$16*12/3-Q9+1>0,-PMT($BB9/4,$B$16*12/3-Q9+1,BC9),0) -> 8319.8858 | BE9: =BC9*($BB9/4) -> 6940.3687 | BF9: =BD9-BE9 -> 1379.5171 | BG9: =AT9+AY9+BD9 -> 9607.8858 | BH9: =INDEX(cpi!B:B,MATCH($L9,cpi!A:A)) -> 88.2 | BI9: =100*BH9/BH$3 -> 104.25532 | BJ9: =100*AC9/AC$3 -> 131.37271 | BK9: =100*AD9/AD$3 -> 140.39895 | BL9: =BJ9*GlobalPortfolio+BK9*AusPortfolio -> 134.08059 | BM9: =100*AE9/$AE$3 -> 165.73639 | BN9: =100*AR9/AR$3 -> 108.91304 | BO9: =100*AX9/AX$3 -> 105.54871
A10: Dwelling type (3br house, 3BR_H; or 2br flat, 2BR_F) | B10: 3BR_H | C10: 3BR_H | L10: =DATE(YEAR(L9),MONTH(L9)+3,1) -> 39417 | M10: =AP10 -> 271364.42 | N10: =AX10-BC10 -> 140725.05 | O10: =M10/N10 -> 1.9283306 | P10: =X10/BG10 -> 0.38883535 | Q10: 8 | R10: =EOMONTH(L10,0)-EOMONTH(L10,-3) -> 92 | T10: =IF($B$10="3BR_H", INDEX('3BR_H-combined'!$C:$BH,MATCH($L10,'3BR_H-combined'!$B:$B,0),MATCH(Council_Area,'3BR_H-combined'!$C$1:$BH$1,0)), INDEX('2BR_F-combined'!$C:$BH,MATCH($L10,'2BR_F-combined'!$B:$B,0),MATCH(Council_Area,'2BR_F-combined'!$C$1:$BH$1,0))) -> 310 | U10: =IF(MOD(Q10,4)=1,T10,U9) -> 280 | V10: =U10*(R10)/7 -> 3680 | W10: =$B$53/4*BH10/_xlfn.XLOOKUP(Q_end,cpi!A:A,cpi!B:B) -> 123.42778 | X10: =V10+W10 -> 3803.4278 | Y10: =BG10-X10 -> 5978.1617 | Z10: =Y10*$B$47 -> 1913.0117 | AA10: =(Y10+Z10)*eff_invest -> 7891.1734 | AB10: =AA10*(_xlfn.XLOOKUP(Q_end,cpi!A:A,cpi!B:B)/BH10) -> 12786.705 | AC10: {=INDEX('msci-indices'!C:C,MATCH($L10,'msci-indices'!$B:$B)-2)} -> 1009.8701 | AD10: {=INDEX('msci-indices'!D:D,MATCH($L10,'msci-indices'!$B:$B)-2)} -> 1061.067 | AE10: =AI9+AA10 -> 279081.26 | AF10: {=INDEX('msci-indices'!C:C,MATCH($L10,'msci-indices'!$B:$B)+1)} -> 983.50383 | AG10: {=INDEX('msci-indices'!D:D,MATCH($L10,'msci-indices'!$B:$B)+1)} -> 1030.1196 | AH10: =(InvestFees/4)*AE10 -> 174.42579 | AI10: =((AF10/AC10)*GlobalPortfolio+(AG10/AD10)*AusPortfolio)*AE10-AH10 -> 271364.42 | AJ10: =AJ9+AA10 -> 211487.27 | AK10: =AI10-AJ10 -> 59877.149 | AL10: =AJ10*(_xlfn.XLOOKUP(Q_end,cpi!A:A,cpi!B:B)/BH10) -> 342689.89 | AM10: {=SUMPRODUCT($AA$3:AA10,_xlfn.SORTBY($BH$3:BH10,_xlfn.SEQUENCE(ROWS($BH$3:BH10)),-1)/$BH$3)} -> 221554.9 | AN10: =AI10-AM10 -> 49809.52 | AO10: =IF($B$49="Real gains",MAX($B$50*AN10,0),IF($B$49="Discounted nominal gains",MAX($B$50*AK10/2,0),0)) -> 0 | AP10: =AI10-AO10 -> 271364.42 | AR10: =IF($B$10="3BR_H", INDEX('ns-combined'!$C:$BH,MATCH($L10,'ns-combined'!$B:$B,0),MATCH(Council_Area,'ns-combined'!$C$1:$BH$1,0))*1000, INDEX('s-combined'!$C:$BH,MATCH($L10,'s-combined'!$B:$B,0),MATCH(Council_Area,'s-combined'!$C$1:$BH$1,0))*1000) -> 530000 | AS10: =AS9+$AS$3 -> 9200 | AT10: 0 | AU10: =SUM($B$28:$B$29)*AR10 -> 10600 | AV10: =AR10*$B$15/4 -> 1523.75 | AW10: =SUM($AV$3:AV10) -> 11249.875 | AX10: =AR10-AS10-AU10-AW10 -> 498950.12 | AY10: =$B$36*V10 -> 1288 | AZ10: =SUM(AY10:AY10)*4/AR10 -> 0.0097207547 | BA10: =SUM(AY10:AY10)/V10 -> 0.35 | BB10: =IF(MortgageRate="Discounted",_xlfn.XLOOKUP(L10,'mortgage-rates'!$A:$A,'mortgage-rates'!$E:$E)/100,_xlfn.XLOOKUP(L10,'mortgage-rates'!$A:$A,'mortgage-rates'!$D:$D)/100) -> 0.0797 | BC10: =BC9-BF9 -> 358225.08 | BD10: =IF($B$16*12/3-Q10+1>0,-PMT($BB10/4,$B$16*12/3-Q10+1,BC10),0) -> 8493.5894 | BE10: =BC10*($BB10/4) -> 7137.6347 | BF10: =BD10-BE10 -> 1355.9548 | BG10: =AT10+AY10+BD10 -> 9781.5894 | BH10: =INDEX(cpi!B:B,MATCH($L10,cpi!A:A)) -> 89.3 | BI10: =100*BH10/BH$3 -> 105.55556 | BJ10: =100*AC10/AC$3 -> 133.77897 | BK10: =100*AD10/AD$3 -> 148.82639 | BL10: =BJ10*GlobalPortfolio+BK10*AusPortfolio -> 138.29319 | BM10: =100*AE10/$AE$3 -> 175.71058 | BN10: =100*AR10/AR$3 -> 115.21739 | BO10: =100*AX10/AX$3 -> 111.29144
A11: Analysis start quarter | B11: 38777 | C11: 38777 | L11: =DATE(YEAR(L10),MONTH(L10)+3,1) -> 39508 | M11: =AP11 -> 249614.15 | N11: =AX11-BC11 -> 95436.628 | O11: =M11/N11 -> 2.6154964 | P11: =X11/BG11 -> 0.40957642 | Q11: 9 | R11: =EOMONTH(L11,0)-EOMONTH(L11,-3) -> 91 | T11: =IF($B$10="3BR_H", INDEX('3BR_H-combined'!$C:$BH,MATCH($L11,'3BR_H-combined'!$B:$B,0),MATCH(Council_Area,'3BR_H-combined'!$C$1:$BH$1,0)), INDEX('2BR_F-combined'!$C:$BH,MATCH($L11,'2BR_F-combined'!$B:$B,0),MATCH(Council_Area,'2BR_F-combined'!$C$1:$BH$1,0))) -> 320 | U11: =IF(MOD(Q11,4)=1,T11,U10) -> 320 | V11: =U11*(R11)/7 -> 4160 | W11: =$B$53/4*BH11/_xlfn.XLOOKUP(Q_end,cpi!A:A,cpi!B:B) -> 124.94817 | X11: =V11+W11 -> 4284.9482 | Y11: =BG11-X11 -> 6176.9534 | Z11: =Y11*$B$47 -> 1976.6251 | AA11: =(Y11+Z11)*eff_invest -> 8153.5784 | AB11: =AA11*(_xlfn.XLOOKUP(Q_end,cpi!A:A,cpi!B:B)/BH11) -> 13051.137 | AC11: {=INDEX('msci-indices'!C:C,MATCH($L11,'msci-indices'!$B:$B)-2)} -> 983.50383 | AD11: {=INDEX('msci-indices'!D:D,MATCH($L11,'msci-indices'!$B:$B)-2)} -> 1030.1196 | AE11: =AI10+AA11 -> 279517.99 | AF11: {=INDEX('msci-indices'!C:C,MATCH($L11,'msci-indices'!$B:$B)+1)} -> 894.99836 | AG11: {=INDEX('msci-indices'!D:D,MATCH($L11,'msci-indices'!$B:$B)+1)} -> 881.21373 | AH11: =(InvestFees/4)*AE11 -> 174.69875 | AI11: =((AF11/AC11)*GlobalPortfolio+(AG11/AD11)*AusPortfolio)*AE11-AH11 -> 249614.15 | AJ11: =AJ10+AA11 -> 219640.85 | AK11: =AI11-AJ11 -> 29973.31 | AL11: =AJ11*(_xlfn.XLOOKUP(Q_end,cpi!A:A,cpi!B:B)/BH11) -> 351571.13 | AM11: {=SUMPRODUCT($AA$3:AA11,_xlfn.SORTBY($BH$3:BH11,_xlfn.SEQUENCE(ROWS($BH$3:BH11)),-1)/$BH$3)} -> 232193.52 | AN11: =AI11-AM11 -> 17420.634 | AO11: =IF($B$49="Real gains",MAX($B$50*AN11,0),IF($B$49="Discounted nominal gains",MAX($B$50*AK11/2,0),0)) -> 0 | AP11: =AI11-AO11 -> 249614.15 | AR11: =IF($B$10="3BR_H", INDEX('ns-combined'!$C:$BH,MATCH($L11,'ns-combined'!$B:$B,0),MATCH(Council_Area,'ns-combined'!$C$1:$BH$1,0))*1000, INDEX('s-combined'!$C:$BH,MATCH($L11,'s-combined'!$B:$B,0),MATCH(Council_Area,'s-combined'!$C$1:$BH$1,0))*1000) -> 485000 | AS11: =AS10+$AS$3 -> 10350 | AT11: 0 | AU11: =SUM($B$28:$B$29)*AR11 -> 9700 | AV11: =AR11*$B$15/4 -> 1394.375 | AW11: =SUM($AV$3:AV11) -> 12644.25 | AX11: =AR11-AS11-AU11-AW11 -> 452305.75 | AY11: =$B$36*V11 -> 1456 | AZ11: =SUM(AY11:AY11)*4/AR11 -> 0.012008247 | BA11: =SUM(AY11:AY11)/V11 -> 0.35 | BB11: =IF(MortgageRate="Discounted",_xlfn.XLOOKUP(L11,'mortgage-rates'!$A:$A,'mortgage-rates'!$E:$E)/100,_xlfn.XLOOKUP(L11,'mortgage-rates'!$A:$A,'mortgage-rates'!$D:$D)/100) -> 0.087 | BC11: =BC10-BF10 -> 356869.12 | BD11: =IF($B$16*12/3-Q11+1>0,-PMT($BB11/4,$B$16*12/3-Q11+1,BC11),0) -> 9005.9015 | BE11: =BC11*($BB11/4) -> 7761.9034 | BF11: =BD11-BE11 -> 1243.9981 | BG11: =AT11+AY11+BD11 -> 10461.902 | BH11: =INDEX(cpi!B:B,MATCH($L11,cpi!A:A)) -> 90.4 | BI11: =100*BH11/BH$3 -> 106.85579 | BJ11: =100*AC11/AC$3 -> 130.28618 | BK11: =100*AD11/AD$3 -> 144.48568 | BL11: =BJ11*GlobalPortfolio+BK11*AusPortfolio -> 134.54603 | BM11: =100*AE11/$AE$3 -> 175.98554 | BN11: =100*AR11/AR$3 -> 105.43478 | BO11: =100*AX11/AX$3 -> 100.88735
A12: Analysis end quarter | B12: 45992 | C12: 45992 | L12: =DATE(YEAR(L11),MONTH(L11)+3,1) -> 39600 | M12: =AP12 -> 253859.37 | N12: =AX12-BC12 -> 107816 | O12: =M12/N12 -> 2.3545612 | P12: =X12/BG12 -> 0.40589362 | Q12: 10 | R12: =EOMONTH(L12,0)-EOMONTH(L12,-3) -> 91 | T12: =IF($B$10="3BR_H", INDEX('3BR_H-combined'!$C:$BH,MATCH($L12,'3BR_H-combined'!$B:$B,0),MATCH(Council_Area,'3BR_H-combined'!$C$1:$BH$1,0)), INDEX('2BR_F-combined'!$C:$BH,MATCH($L12,'2BR_F-combined'!$B:$B,0),MATCH(Council_Area,'2BR_F-combined'!$C$1:$BH$1,0))) -> 330 | U12: =IF(MOD(Q12,4)=1,T12,U11) -> 320 | V12: =U12*(R12)/7 -> 4160 | W12: =$B$53/4*BH12/_xlfn.XLOOKUP(Q_end,cpi!A:A,cpi!B:B) -> 126.60677 | X12: =V12+W12 -> 4286.6068 | Y12: =BG12-X12 -> 6274.3051 | Z12: =Y12*$B$47 -> 2007.7776 | AA12: =(Y12+Z12)*eff_invest -> 8282.0827 | AB12: =AA12*(_xlfn.XLOOKUP(Q_end,cpi!A:A,cpi!B:B)/BH12) -> 13083.159 | AC12: {=INDEX('msci-indices'!C:C,MATCH($L12,'msci-indices'!$B:$B)-2)} -> 894.99836 | AD12: {=INDEX('msci-indices'!D:D,MATCH($L12,'msci-indices'!$B:$B)-2)} -> 881.21373 | AE12: =AI11+AA12 -> 257896.24 | AF12: {=INDEX('msci-indices'!C:C,MATCH($L12,'msci-indices'!$B:$B)+1)} -> 881.79174 | AG12: {=INDEX('msci-indices'!D:D,MATCH($L12,'msci-indices'!$B:$B)+1)} -> 867.41147 | AH12: =(InvestFees/4)*AE12 -> 161.18515 | AI12: =((AF12/AC12)*GlobalPortfolio+(AG12/AD12)*AusPortfolio)*AE12-AH12 -> 253859.37 | AJ12: =AJ11+AA12 -> 227922.93 | AK12: =AI12-AJ12 -> 25936.445 | AL12: =AJ12*(_xlfn.XLOOKUP(Q_end,cpi!A:A,cpi!B:B)/BH12) -> 360048.56 | AM12: {=SUMPRODUCT($AA$3:AA12,_xlfn.SORTBY($BH$3:BH12,_xlfn.SEQUENCE(ROWS($BH$3:BH12)),-1)/$BH$3)} -> 243250.62 | AN12: =AI12-AM12 -> 10608.756 | AO12: =IF($B$49="Real gains",MAX($B$50*AN12,0),IF($B$49="Discounted nominal gains",MAX($B$50*AK12/2,0),0)) -> 0 | AP12: =AI12-AO12 -> 253859.37 | AR12: =IF($B$10="3BR_H", INDEX('ns-combined'!$C:$BH,MATCH($L12,'ns-combined'!$B:$B,0),MATCH(Council_Area,'ns-combined'!$C$1:$BH$1,0))*1000, INDEX('s-combined'!$C:$BH,MATCH($L12,'s-combined'!$B:$B,0),MATCH(Council_Area,'s-combined'!$C$1:$BH$1,0))*1000) -> 499000 | AS12: =AS11+$AS$3 -> 11500 | AT12: 0 | AU12: =SUM($B$28:$B$29)*AR12 -> 9980 | AV12: =AR12*$B$15/4 -> 1434.625 | AW12: =SUM($AV$3:AV12) -> 14078.875 | AX12: =AR12-AS12-AU12-AW12 -> 463441.12 | AY12: =$B$36*V12 -> 1456 | AZ12: =SUM(AY12:AY12)*4/AR12 -> 0.011671343 | BA12: =SUM(AY12:AY12)/V12 -> 0.35 | BB12: =IF(MortgageRate="Discounted",_xlfn.XLOOKUP(L12,'mortgage-rates'!$A:$A,'mortgage-rates'!$E:$E)/100,_xlfn.XLOOKUP(L12,'mortgage-rates'!$A:$A,'mortgage-rates'!$D:$D)/100) -> 0.0884 | BC12: =BC11-BF11 -> 355625.12 | BD12: =IF($B$16*12/3-Q12+1>0,-PMT($BB12/4,$B$16*12/3-Q12+1,BC12),0) -> 9104.9118 | BE12: =BC12*($BB12/4) -> 7859.3152 | BF12: =BD12-BE12 -> 1245.5966 | BG12: =AT12+AY12+BD12 -> 10560.912 | BH12: =INDEX(cpi!B:B,MATCH($L12,cpi!A:A)) -> 91.6 | BI12: =100*BH12/BH$3 -> 108.27423 | BJ12: =100*AC12/AC$3 -> 118.56173 | BK12: =100*AD12/AD$3 -> 123.59997 | BL12: =BJ12*GlobalPortfolio+BK12*AusPortfolio -> 120.07321 | BM12: =100*AE12/$AE$3 -> 162.37241 | BN12: =100*AR12/AR$3 -> 108.47826 | BO12: =100*AX12/AX$3 -> 103.37111
A13: Council/Area | B13: Greater Sydney | C13: Greater Sydney | L13: =DATE(YEAR(L12),MONTH(L12)+3,1) -> 39692 | M13: =AP13 -> 225654.89 | N13: =AX13-BC13 -> 78140.348 | O13: =M13/N13 -> 2.8878153 | P13: =X13/BG13 -> 0.41192349 | Q13: 11 | R13: =EOMONTH(L13,0)-EOMONTH(L13,-3) -> 92 | T13: =IF($B$10="3BR_H", INDEX('3BR_H-combined'!$C:$BH,MATCH($L13,'3BR_H-combined'!$B:$B,0),MATCH(Council_Area,'3BR_H-combined'!$C$1:$BH$1,0)), INDEX('2BR_F-combined'!$C:$BH,MATCH($L13,'2BR_F-combined'!$B:$B,0),MATCH(Council_Area,'2BR_F-combined'!$C$1:$BH$1,0))) -> 347.5 | U13: =IF(MOD(Q13,4)=1,T13,U12) -> 320 | V13: =U13*(R13)/7 -> 4205.7143 | W13: =$B$53/4*BH13/_xlfn.XLOOKUP(Q_end,cpi!A:A,cpi!B:B) -> 127.98894 | X13: =V13+W13 -> 4333.7032 | Y13: =BG13-X13 -> 6186.9476 | Z13: =Y13*$B$47 -> 1979.8232 | AA13: =(Y13+Z13)*eff_invest -> 8166.7708 | AB13: =AA13*(_xlfn.XLOOKUP(Q_end,cpi!A:A,cpi!B:B)/BH13) -> 12761.682 | AC13: {=INDEX('msci-indices'!C:C,MATCH($L13,'msci-indices'!$B:$B)-2)} -> 881.79174 | AD13: {=INDEX('msci-indices'!D:D,MATCH($L13,'msci-indices'!$B:$B)-2)} -> 867.41147 | AE13: =AI12+AA13 -> 262026.14 | AF13: {=INDEX('msci-indices'!C:C,MATCH($L13,'msci-indices'!$B:$B)+1)} -> 747.65998 | AG13: {=INDEX('msci-indices'!D:D,MATCH($L13,'msci-indices'!$B:$B)+1)} -> 775.74397 | AH13: =(InvestFees/4)*AE13 -> 163.76634 | AI13: =((AF13/AC13)*GlobalPortfolio+(AG13/AD13)*AusPortfolio)*AE13-AH13 -> 225654.89 | AJ13: =AJ12+AA13 -> 236089.7 | AK13: =AI13-AJ13 -> -10434.809 | AL13: =AJ13*(_xlfn.XLOOKUP(Q_end,cpi!A:A,cpi!B:B)/BH13) -> 368922.02 | AM13: {=SUMPRODUCT($AA$3:AA13,_xlfn.SORTBY($BH$3:BH13,_xlfn.SEQUENCE(ROWS($BH$3:BH13)),-1)/$BH$3)} -> 253927.66 | AN13: =AI13-AM13 -> -28272.77 | AO13: =IF($B$49="Real gains",MAX($B$50*AN13,0),IF($B$49="Discounted nominal gains",MAX($B$50*AK13/2,0),0)) -> 0 | AP13: =AI13-AO13 -> 225654.89 | AR13: =IF($B$10="3BR_H", INDEX('ns-combined'!$C:$BH,MATCH($L13,'ns-combined'!$B:$B,0),MATCH(Council_Area,'ns-combined'!$C$1:$BH$1,0))*1000, INDEX('s-combined'!$C:$BH,MATCH($L13,'s-combined'!$B:$B,0),MATCH(Council_Area,'s-combined'!$C$1:$BH$1,0))*1000) -> 470000 | AS13: =AS12+$AS$3 -> 12650 | AT13: 0 | AU13: =SUM($B$28:$B$29)*AR13 -> 9400 | AV13: =AR13*$B$15/4 -> 1351.25 | AW13: =SUM($AV$3:AV13) -> 15430.125 | AX13: =AR13-AS13-AU13-AW13 -> 432519.88 | AY13: =$B$36*V13 -> 1472 | AZ13: =SUM(AY13:AY13)*4/AR13 -> 0.01252766 | BA13: =SUM(AY13:AY13)/V13 -> 0.35 | BB13: =IF(MortgageRate="Discounted",_xlfn.XLOOKUP(L13,'mortgage-rates'!$A:$A,'mortgage-rates'!$E:$E)/100,_xlfn.XLOOKUP(L13,'mortgage-rates'!$A:$A,'mortgage-rates'!$D:$D)/100) -> 0.0876 | BC13: =BC12-BF12 -> 354379.53 | BD13: =IF($B$16*12/3-Q13+1>0,-PMT($BB13/4,$B$16*12/3-Q13+1,BC13),0) -> 9048.6508 | BE13: =BC13*($BB13/4) -> 7760.9116 | BF13: =BD13-BE13 -> 1287.7392 | BG13: =AT13+AY13+BD13 -> 10520.651 | BH13: =INDEX(cpi!B:B,MATCH($L13,cpi!A:A)) -> 92.6 | BI13: =100*BH13/BH$3 -> 109.45626 | BJ13: =100*AC13/AC$3 -> 116.81223 | BK13: =100*AD13/AD$3 -> 121.66405 | BL13: =BJ13*GlobalPortfolio+BK13*AusPortfolio -> 118.26778 | BM13: =100*AE13/$AE$3 -> 164.97261 | BN13: =100*AR13/AR$3 -> 102.17391 | BO13: =100*AX13/AX$3 -> 96.47409
A14: Depreciation (% of initial home value per year) | B14: 0.01 | C14: 0.01 | L14: =DATE(YEAR(L13),MONTH(L13)+3,1) -> 39783 | M14: =AP14 -> 182515.55 | N14: =AX14-BC14 -> 66178.462 | O14: =M14/N14 -> 2.7579298 | P14: =X14/BG14 -> 0.49178915 | Q14: 12 | R14: =EOMONTH(L14,0)-EOMONTH(L14,-3) -> 92 | T14: =IF($B$10="3BR_H", INDEX('3BR_H-combined'!$C:$BH,MATCH($L14,'3BR_H-combined'!$B:$B,0),MATCH(Council_Area,'3BR_H-combined'!$C$1:$BH$1,0)), INDEX('2BR_F-combined'!$C:$BH,MATCH($L14,'2BR_F-combined'!$B:$B,0),MATCH(Council_Area,'2BR_F-combined'!$C$1:$BH$1,0))) -> 350 | U14: =IF(MOD(Q14,4)=1,T14,U13) -> 320 | V14: =U14*(R14)/7 -> 4205.7143 | W14: =$B$53/4*BH14/_xlfn.XLOOKUP(Q_end,cpi!A:A,cpi!B:B) -> 127.98894 | X14: =V14+W14 -> 4333.7032 | Y14: =BG14-X14 -> 4478.4132 | Z14: =Y14*$B$47 -> 1433.0922 | AA14: =(Y14+Z14)*eff_invest -> 5911.5054 | AB14: =AA14*(_xlfn.XLOOKUP(Q_end,cpi!A:A,cpi!B:B)/BH14) -> 9237.5253 | AC14: {=INDEX('msci-indices'!C:C,MATCH($L14,'msci-indices'!$B:$B)-2)} -> 747.65998 | AD14: {=INDEX('msci-indices'!D:D,MATCH($L14,'msci-indices'!$B:$B)-2)} -> 775.74397 | AE14: =AI13+AA14 -> 231566.39 | AF14: {=INDEX('msci-indices'!C:C,MATCH($L14,'msci-indices'!$B:$B)+1)} -> 582.01082 | AG14: {=INDEX('msci-indices'!D:D,MATCH($L14,'msci-indices'!$B:$B)+1)} -> 630.6613 | AH14: =(InvestFees/4)*AE14 -> 144.729 | AI14: =((AF14/AC14)*GlobalPortfolio+(AG14/AD14)*AusPortfolio)*AE14-AH14 -> 182515.55 | AJ14: =AJ13+AA14 -> 242001.2 | AK14: =AI14-AJ14 -> -59485.653 | AL14: =AJ14*(_xlfn.XLOOKUP(Q_end,cpi!A:A,cpi!B:B)/BH14) -> 378159.55 | AM14: {=SUMPRODUCT($AA$3:AA14,_xlfn.SORTBY($BH$3:BH14,_xlfn.SEQUENCE(ROWS($BH$3:BH14)),-1)/$BH$3)} -> 260563.12 | AN14: =AI14-AM14 -> -78047.573 | AO14: =IF($B$49="Real gains",MAX($B$50*AN14,0),IF($B$49="Discounted nominal gains",MAX($B$50*AK14/2,0),0)) -> 0 | AP14: =AI14-AO14 -> 182515.55 | AR14: =IF($B$10="3BR_H", INDEX('ns-combined'!$C:$BH,MATCH($L14,'ns-combined'!$B:$B,0),MATCH(Council_Area,'ns-combined'!$C$1:$BH$1,0))*1000, INDEX('s-combined'!$C:$BH,MATCH($L14,'s-combined'!$B:$B,0),MATCH(Council_Area,'s-combined'!$C$1:$BH$1,0))*1000) -> 459000 | AS14: =AS13+$AS$3 -> 13800 | AT14: 0 | AU14: =SUM($B$28:$B$29)*AR14 -> 9180 | AV14: =AR14*$B$15/4 -> 1319.625 | AW14: =SUM($AV$3:AV14) -> 16749.75 | AX14: =AR14-AS14-AU14-AW14 -> 419270.25 | AY14: =$B$36*V14 -> 1472 | AZ14: =SUM(AY14:AY14)*4/AR14 -> 0.012827887 | BA14: =SUM(AY14:AY14)/V14 -> 0.35 | BB14: =IF(MortgageRate="Discounted",_xlfn.XLOOKUP(L14,'mortgage-rates'!$A:$A,'mortgage-rates'!$E:$E)/100,_xlfn.XLOOKUP(L14,'mortgage-rates'!$A:$A,'mortgage-rates'!$D:$D)/100) -> 0.062 | BC14: =BC13-BF13 -> 353091.79 | BD14: =IF($B$16*12/3-Q14+1>0,-PMT($BB14/4,$B$16*12/3-Q14+1,BC14),0) -> 7340.1164 | BE14: =BC14*($BB14/4) -> 5472.9227 | BF14: =BD14-BE14 -> 1867.1937 | BG14: =AT14+AY14+BD14 -> 8812.1164 | BH14: =INDEX(cpi!B:B,MATCH($L14,cpi!A:A)) -> 92.6 | BI14: =100*BH14/BH$3 -> 109.45626 | BJ14: =100*AC14/AC$3 -> 99.043605 | BK14: =100*AD14/AD$3 -> 108.80667 | BL14: =BJ14*GlobalPortfolio+BK14*AusPortfolio -> 101.97253 | BM14: =100*AE14/$AE$3 -> 145.79504 | BN14: =100*AR14/AR$3 -> 99.782609 | BO14: =100*AX14/AX$3 -> 93.518745
A15: Renovations, alterations, and additions (% of current home value per year) | B15: 0.0115 | C15: 0.0115 | L15: =DATE(YEAR(L14),MONTH(L14)+3,1) -> 39873 | M15: =AP15 -> 170999.66 | N15: =AX15-BC15 -> 47010.656 | O15: =M15/N15 -> 3.6374659 | P15: =X15/BG15 -> 0.55848576 | Q15: 13 | R15: =EOMONTH(L15,0)-EOMONTH(L15,-3) -> 90 | T15: =IF($B$10="3BR_H", INDEX('3BR_H-combined'!$C:$BH,MATCH($L15,'3BR_H-combined'!$B:$B,0),MATCH(Council_Area,'3BR_H-combined'!$C$1:$BH$1,0)), INDEX('2BR_F-combined'!$C:$BH,MATCH($L15,'2BR_F-combined'!$B:$B,0),MATCH(Council_Area,'2BR_F-combined'!$C$1:$BH$1,0))) -> 350 | U15: =IF(MOD(Q15,4)=1,T15,U14) -> 350 | V15: =U15*(R15)/7 -> 4500 | W15: =$B$53/4*BH15/_xlfn.XLOOKUP(Q_end,cpi!A:A,cpi!B:B) -> 127.85073 | X15: =V15+W15 -> 4627.8507 | Y15: =BG15-X15 -> 3658.575 | Z15: =Y15*$B$47 -> 1170.744 | AA15: =(Y15+Z15)*eff_invest -> 4829.319 | AB15: =AA15*(_xlfn.XLOOKUP(Q_end,cpi!A:A,cpi!B:B)/BH15) -> 7554.6212 | AC15: {=INDEX('msci-indices'!C:C,MATCH($L15,'msci-indices'!$B:$B)-2)} -> 582.01082 | AD15: {=INDEX('msci-indices'!D:D,MATCH($L15,'msci-indices'!$B:$B)-2)} -> 630.6613 | AE15: =AI14+AA15 -> 187344.87 | AF15: {=INDEX('msci-indices'!C:C,MATCH($L15,'msci-indices'!$B:$B)+1)} -> 513.55423 | AG15: {=INDEX('msci-indices'!D:D,MATCH($L15,'msci-indices'!$B:$B)+1)} -> 621.64895 | AH15: =(InvestFees/4)*AE15 -> 117.09054 | AI15: =((AF15/AC15)*GlobalPortfolio+(AG15/AD15)*AusPortfolio)*AE15-AH15 -> 170999.66 | AJ15: =AJ14+AA15 -> 246830.52 | AK15: =AI15-AJ15 -> -75830.867 | AL15: =AJ15*(_xlfn.XLOOKUP(Q_end,cpi!A:A,cpi!B:B)/BH15) -> 386122.99 | AM15: {=SUMPRODUCT($AA$3:AA15,_xlfn.SORTBY($BH$3:BH15,_xlfn.SEQUENCE(ROWS($BH$3:BH15)),-1)/$BH$3)} -> 265901.29 | AN15: =AI15-AM15 -> -94901.639 | AO15: =IF($B$49="Real gains",MAX($B$50*AN15,0),IF($B$49="Discounted nominal gains",MAX($B$50*AK15/2,0),0)) -> 0 | AP15: =AI15-AO15 -> 170999.66 | AR15: =IF($B$10="3BR_H", INDEX('ns-combined'!$C:$BH,MATCH($L15,'ns-combined'!$B:$B,0),MATCH(Council_Area,'ns-combined'!$C$1:$BH$1,0))*1000, INDEX('s-combined'!$C:$BH,MATCH($L15,'s-combined'!$B:$B,0),MATCH(Council_Area,'s-combined'!$C$1:$BH$1,0))*1000) -> 440000 | AS15: =AS14+$AS$3 -> 14950 | AT15: 0 | AU15: =SUM($B$28:$B$29)*AR15 -> 8800 | AV15: =AR15*$B$15/4 -> 1265 | AW15: =SUM($AV$3:AV15) -> 18014.75 | AX15: =AR15-AS15-AU15-AW15 -> 398235.25 | AY15: =$B$36*V15 -> 1575 | AZ15: =SUM(AY15:AY15)*4/AR15 -> 0.014318182 | BA15: =SUM(AY15:AY15)/V15 -> 0.35 | BB15: =IF(MortgageRate="Discounted",_xlfn.XLOOKUP(L15,'mortgage-rates'!$A:$A,'mortgage-rates'!$E:$E)/100,_xlfn.XLOOKUP(L15,'mortgage-rates'!$A:$A,'mortgage-rates'!$D:$D)/100) -> 0.0518 | BC15: =BC14-BF14 -> 351224.59 | BD15: =IF($B$16*12/3-Q15+1>0,-PMT($BB15/4,$B$16*12/3-Q15+1,BC15),0) -> 6711.4257 | BE15: =BC15*($BB15/4) -> 4548.3585 | BF15: =BD15-BE15 -> 2163.0672 | BG15: =AT15+AY15+BD15 -> 8286.4257 | BH15: =INDEX(cpi!B:B,MATCH($L15,cpi!A:A)) -> 92.5 | BI15: =100*BH15/BH$3 -> 109.33806 | BJ15: =100*AC15/AC$3 -> 77.099819 | BK15: =100*AD15/AD$3 -> 88.457223 | BL15: =BJ15*GlobalPortfolio+BK15*AusPortfolio -> 80.50704 | BM15: =100*AE15/$AE$3 -> 117.95301 | BN15: =100*AR15/AR$3 -> 95.652174 | BO15: =100*AX15/AX$3 -> 88.826862
A16: Loan term (years) | B16: 25 | C16: 25 | L16: =DATE(YEAR(L15),MONTH(L15)+3,1) -> 39965 | M16: =AP16 -> 208361.68 | N16: =AX16-BC16 -> 90729.348 | O16: =M16/N16 -> 2.2965191 | P16: =X16/BG16 -> 0.56503703 | Q16: 14 | R16: =EOMONTH(L16,0)-EOMONTH(L16,-3) -> 91 | T16: =IF($B$10="3BR_H", INDEX('3BR_H-combined'!$C:$BH,MATCH($L16,'3BR_H-combined'!$B:$B,0),MATCH(Council_Area,'3BR_H-combined'!$C$1:$BH$1,0)), INDEX('2BR_F-combined'!$C:$BH,MATCH($L16,'2BR_F-combined'!$B:$B,0),MATCH(Council_Area,'2BR_F-combined'!$C$1:$BH$1,0))) -> 350 | U16: =IF(MOD(Q16,4)=1,T16,U15) -> 350 | V16: =U16*(R16)/7 -> 4550 | W16: =$B$53/4*BH16/_xlfn.XLOOKUP(Q_end,cpi!A:A,cpi!B:B) -> 128.54181 | X16: =V16+W16 -> 4678.5418 | Y16: =BG16-X16 -> 3601.5205 | Z16: =Y16*$B$47 -> 1152.4866 | AA16: =(Y16+Z16)*eff_invest -> 4754.0071 | AB16: =AA16*(_xlfn.XLOOKUP(Q_end,cpi!A:A,cpi!B:B)/BH16) -> 7396.8261 | AC16: {=INDEX('msci-indices'!C:C,MATCH($L16,'msci-indices'!$B:$B)-2)} -> 513.55423 | AD16: {=INDEX('msci-indices'!D:D,MATCH($L16,'msci-indices'!$B:$B)-2)} -> 621.64895 | AE16: =AI15+AA16 -> 175753.66 | AF16: {=INDEX('msci-indices'!C:C,MATCH($L16,'msci-indices'!$B:$B)+1)} -> 624.35598 | AG16: {=INDEX('msci-indices'!D:D,MATCH($L16,'msci-indices'!$B:$B)+1)} -> 694.44245 | AH16: =(InvestFees/4)*AE16 -> 109.84604 | AI16: =((AF16/AC16)*GlobalPortfolio+(AG16/AD16)*AusPortfolio)*AE16-AH16 -> 208361.68 | AJ16: =AJ15+AA16 -> 251584.53 | AK16: =AI16-AJ16 -> -43222.845 | AL16: =AJ16*(_xlfn.XLOOKUP(Q_end,cpi!A:A,cpi!B:B)/BH16) -> 391443.89 | AM16: {=SUMPRODUCT($AA$3:AA16,_xlfn.SORTBY($BH$3:BH16,_xlfn.SEQUENCE(ROWS($BH$3:BH16)),-1)/$BH$3)} -> 272254.54 | AN16: =AI16-AM16 -> -63892.852 | AO16: =IF($B$49="Real gains",MAX($B$50*AN16,0),IF($B$49="Discounted nominal gains",MAX($B$50*AK16/2,0),0)) -> 0 | AP16: =AI16-AO16 -> 208361.68 | AR16: =IF($B$10="3BR_H", INDEX('ns-combined'!$C:$BH,MATCH($L16,'ns-combined'!$B:$B,0),MATCH(Council_Area,'ns-combined'!$C$1:$BH$1,0))*1000, INDEX('s-combined'!$C:$BH,MATCH($L16,'s-combined'!$B:$B,0),MATCH(Council_Area,'s-combined'!$C$1:$BH$1,0))*1000) -> 485000 | AS16: =AS15+$AS$3 -> 16100 | AT16: 0 | AU16: =SUM($B$28:$B$29)*AR16 -> 9700 | AV16: =AR16*$B$15/4 -> 1394.375 | AW16: =SUM($AV$3:AV16) -> 19409.125 | AX16: =AR16-AS16-AU16-AW16 -> 439790.88 | AY16: =$B$36*V16 -> 1592.5 | AZ16: =SUM(AY16:AY16)*4/AR16 -> 0.013134021 | BA16: =SUM(AY16:AY16)/V16 -> 0.35 | BB16: =IF(MortgageRate="Discounted",_xlfn.XLOOKUP(L16,'mortgage-rates'!$A:$A,'mortgage-rates'!$E:$E)/100,_xlfn.XLOOKUP(L16,'mortgage-rates'!$A:$A,'mortgage-rates'!$D:$D)/100) -> 0.0514 | BC16: =BC15-BF15 -> 349061.53 | BD16: =IF($B$16*12/3-Q16+1>0,-PMT($BB16/4,$B$16*12/3-Q16+1,BC16),0) -> 6687.5624 | BE16: =BC16*($BB16/4) -> 4485.4406 | BF16: =BD16-BE16 -> 2202.1217 | BG16: =AT16+AY16+BD16 -> 8280.0624 | BH16: =INDEX(cpi!B:B,MATCH($L16,cpi!A:A)) -> 93 | BI16: =100*BH16/BH$3 -> 109.92908 | BJ16: =100*AC16/AC$3 -> 68.031276 | BK16: =100*AD16/AD$3 -> 87.193142 | BL16: =BJ16*GlobalPortfolio+BK16*AusPortfolio -> 73.779836 | BM16: =100*AE16/$AE$3 -> 110.65514 | BN16: =100*AR16/AR$3 -> 105.43478 | BO16: =100*AX16/AX$3 -> 98.095895
L17: =DATE(YEAR(L16),MONTH(L16)+3,1) -> 40057 | M17: =AP17 -> 254076.64 | N17: =AX17-BC17 -> 98204.095 | O17: =M17/N17 -> 2.5872306 | P17: =X17/BG17 -> 0.5699878 | Q17: 15 | R17: =EOMONTH(L17,0)-EOMONTH(L17,-3) -> 92 | T17: =IF($B$10="3BR_H", INDEX('3BR_H-combined'!$C:$BH,MATCH($L17,'3BR_H-combined'!$B:$B,0),MATCH(Council_Area,'3BR_H-combined'!$C$1:$BH$1,0)), INDEX('2BR_F-combined'!$C:$BH,MATCH($L17,'2BR_F-combined'!$B:$B,0),MATCH(Council_Area,'2BR_F-combined'!$C$1:$BH$1,0))) -> 360 | U17: =IF(MOD(Q17,4)=1,T17,U16) -> 350 | V17: =U17*(R17)/7 -> 4600 | W17: =$B$53/4*BH17/_xlfn.XLOOKUP(Q_end,cpi!A:A,cpi!B:B) -> 129.50933 | X17: =V17+W17 -> 4729.5093 | Y17: =BG17-X17 -> 3568.053 | Z17: =Y17*$B$47 -> 1141.777 | AA17: =(Y17+Z17)*eff_invest -> 4709.83 | AB17: =AA17*(_xlfn.XLOOKUP(Q_end,cpi!A:A,cpi!B:B)/BH17) -> 7273.3447 | AC17: {=INDEX('msci-indices'!C:C,MATCH($L17,'msci-indices'!$B:$B)-2)} -> 624.35598 | AD17: {=INDEX('msci-indices'!D:D,MATCH($L17,'msci-indices'!$B:$B)-2)} -> 694.44245 | AE17: =AI16+AA17 -> 213071.51 | AF17: {=INDEX('msci-indices'!C:C,MATCH($L17,'msci-indices'!$B:$B)+1)} -> 736.86333 | AG17: {=INDEX('msci-indices'!D:D,MATCH($L17,'msci-indices'!$B:$B)+1)} -> 849.38296 | AH17: =(InvestFees/4)*AE17 -> 133.1697 | AI17: =((AF17/AC17)*GlobalPortfolio+(AG17/AD17)*AusPortfolio)*AE17-AH17 -> 254076.64 | AJ17: =AJ16+AA17 -> 256294.36 | AK17: =AI17-AJ17 -> -2217.7222 | AL17: =AJ17*(_xlfn.XLOOKUP(Q_end,cpi!A:A,cpi!B:B)/BH17) -> 395792.89 | AM17: {=SUMPRODUCT($AA$3:AA17,_xlfn.SORTBY($BH$3:BH17,_xlfn.SEQUENCE(ROWS($BH$3:BH17)),-1)/$BH$3)} -> 278975.09 | AN17: =AI17-AM17 -> -24898.448 | AO17: =IF($B$49="Real gains",MAX($B$50*AN17,0),IF($B$49="Discounted nominal gains",MAX($B$50*AK17/2,0),0)) -> 0 | AP17: =AI17-AO17 -> 254076.64 | AR17: =IF($B$10="3BR_H", INDEX('ns-combined'!$C:$BH,MATCH($L17,'ns-combined'!$B:$B,0),MATCH(Council_Area,'ns-combined'!$C$1:$BH$1,0))*1000, INDEX('s-combined'!$C:$BH,MATCH($L17,'s-combined'!$B:$B,0),MATCH(Council_Area,'s-combined'!$C$1:$BH$1,0))*1000) -> 493000 | AS17: =AS16+$AS$3 -> 17250 | AT17: 0 | AU17: =SUM($B$28:$B$29)*AR17 -> 9860 | AV17: =AR17*$B$15/4 -> 1417.375 | AW17: =SUM($AV$3:AV17) -> 20826.5 | AX17: =AR17-AS17-AU17-AW17 -> 445063.5 | AY17: =$B$36*V17 -> 1610 | AZ17: =SUM(AY17:AY17)*4/AR17 -> 0.01306288 | BA17: =SUM(AY17:AY17)/V17 -> 0.35 | BB17: =IF(MortgageRate="Discounted",_xlfn.XLOOKUP(L17,'mortgage-rates'!$A:$A,'mortgage-rates'!$E:$E)/100,_xlfn.XLOOKUP(L17,'mortgage-rates'!$A:$A,'mortgage-rates'!$D:$D)/100) -> 0.0514 | BC17: =BC16-BF16 -> 346859.41 | BD17: =IF($B$16*12/3-Q17+1>0,-PMT($BB17/4,$B$16*12/3-Q17+1,BC17),0) -> 6687.5624 | BE17: =BC17*($BB17/4) -> 4457.1434 | BF17: =BD17-BE17 -> 2230.419 | BG17: =AT17+AY17+BD17 -> 8297.5624 | BH17: =INDEX(cpi!B:B,MATCH($L17,cpi!A:A)) -> 93.7 | BI17: =100*BH17/BH$3 -> 110.7565 | BJ17: =100*AC17/AC$3 -> 82.709345 | BK17: =100*AD17/AD$3 -> 97.403235 | BL17: =BJ17*GlobalPortfolio+BK17*AusPortfolio -> 87.117512 | BM17: =100*AE17/$AE$3 -> 134.1506 | BN17: =100*AR17/AR$3 -> 107.17391 | BO17: =100*AX17/AX$3 -> 99.271961
A18: Mortgage | L18: =DATE(YEAR(L17),MONTH(L17)+3,1) -> 40148 | M18: =AP18 -> 269071.98 | N18: =AX18-BC18 -> 180922.76 | O18: =M18/N18 -> 1.4872201 | P18: =X18/BG18 -> 0.53691924 | Q18: 16 | R18: =EOMONTH(L18,0)-EOMONTH(L18,-3) -> 92 | T18: =IF($B$10="3BR_H", INDEX('3BR_H-combined'!$C:$BH,MATCH($L18,'3BR_H-combined'!$B:$B,0),MATCH(Council_Area,'3BR_H-combined'!$C$1:$BH$1,0)), INDEX('2BR_F-combined'!$C:$BH,MATCH($L18,'2BR_F-combined'!$B:$B,0),MATCH(Council_Area,'2BR_F-combined'!$C$1:$BH$1,0))) -> 370 | U18: =IF(MOD(Q18,4)=1,T18,U17) -> 350 | V18: =U18*(R18)/7 -> 4600 | W18: =$B$53/4*BH18/_xlfn.XLOOKUP(Q_end,cpi!A:A,cpi!B:B) -> 130.61507 | X18: =V18+W18 -> 4730.6151 | Y18: =BG18-X18 -> 4080.0491 | Z18: =Y18*$B$47 -> 1305.6157 | AA18: =(Y18+Z18)*eff_invest -> 5385.6648 | AB18: =AA18*(_xlfn.XLOOKUP(Q_end,cpi!A:A,cpi!B:B)/BH18) -> 8246.6211 | AC18: {=INDEX('msci-indices'!C:C,MATCH($L18,'msci-indices'!$B:$B)-2)} -> 736.86333 | AD18: {=INDEX('msci-indices'!D:D,MATCH($L18,'msci-indices'!$B:$B)-2)} -> 849.38296 | AE18: =AI17+AA18 -> 259462.3 | AF18: {=INDEX('msci-indices'!C:C,MATCH($L18,'msci-indices'!$B:$B)+1)} -> 765.74116 | AG18: {=INDEX('msci-indices'!D:D,MATCH($L18,'msci-indices'!$B:$B)+1)} -> 878.3433 | AH18: =(InvestFees/4)*AE18 -> 162.16394 | AI18: =((AF18/AC18)*GlobalPortfolio+(AG18/AD18)*AusPortfolio)*AE18-AH18 -> 269071.98 | AJ18: =AJ17+AA18 -> 261680.02 | AK18: =AI18-AJ18 -> 7391.9501 | AL18: =AJ18*(_xlfn.XLOOKUP(Q_end,cpi!A:A,cpi!B:B)/BH18) -> 400688.88 | AM18: {=SUMPRODUCT($AA$3:AA18,_xlfn.SORTBY($BH$3:BH18,_xlfn.SEQUENCE(ROWS($BH$3:BH18)),-1)/$BH$3)} -> 286624.92 | AN18: =AI18-AM18 -> -17552.943 | AO18: =IF($B$49="Real gains",MAX($B$50*AN18,0),IF($B$49="Discounted nominal gains",MAX($B$50*AK18/2,0),0)) -> 0 | AP18: =AI18-AO18 -> 269071.98 | AR18: =IF($B$10="3BR_H", INDEX('ns-combined'!$C:$BH,MATCH($L18,'ns-combined'!$B:$B,0),MATCH(Council_Area,'ns-combined'!$C$1:$BH$1,0))*1000, INDEX('s-combined'!$C:$BH,MATCH($L18,'s-combined'!$B:$B,0),MATCH(Council_Area,'s-combined'!$C$1:$BH$1,0))*1000) -> 578000 | AS18: =AS17+$AS$3 -> 18400 | AT18: 0 | AU18: =SUM($B$28:$B$29)*AR18 -> 11560 | AV18: =AR18*$B$15/4 -> 1661.75 | AW18: =SUM($AV$3:AV18) -> 22488.25 | AX18: =AR18-AS18-AU18-AW18 -> 525551.75 | AY18: =$B$36*V18 -> 1610 | AZ18: =SUM(AY18:AY18)*4/AR18 -> 0.011141869 | BA18: =SUM(AY18:AY18)/V18 -> 0.35 | BB18: =IF(MortgageRate="Discounted",_xlfn.XLOOKUP(L18,'mortgage-rates'!$A:$A,'mortgage-rates'!$E:$E)/100,_xlfn.XLOOKUP(L18,'mortgage-rates'!$A:$A,'mortgage-rates'!$D:$D)/100) -> 0.06 | BC18: =BC17-BF17 -> 344628.99 | BD18: =IF($B$16*12/3-Q18+1>0,-PMT($BB18/4,$B$16*12/3-Q18+1,BC18),0) -> 7200.6642 | BE18: =BC18*($BB18/4) -> 5169.4348 | BF18: =BD18-BE18 -> 2031.2294 | BG18: =AT18+AY18+BD18 -> 8810.6642 | BH18: =INDEX(cpi!B:B,MATCH($L18,cpi!A:A)) -> 94.5 | BI18: =100*BH18/BH$3 -> 111.70213 | BJ18: =100*AC18/AC$3 -> 97.613357 | BK18: =100*AD18/AD$3 -> 119.13536 | BL18: =BJ18*GlobalPortfolio+BK18*AusPortfolio -> 104.06996 | BM18: =100*AE18/$AE$3 -> 163.35841 | BN18: =100*AR18/AR$3 -> 125.65217 | BO18: =100*AX18/AX$3 -> 117.22496
A19: Mortgage rates (Standard/Discounted) | B19: Discounted | C19: Discounted | L19: =DATE(YEAR(L18),MONTH(L18)+3,1) -> 40238 | M19: =AP19 -> 282918.25 | N19: =AX19-BC19 -> 168416.74 | O19: =M19/N19 -> 1.6798701 | P19: =X19/BG19 -> 0.55366017 | Q19: 17 | R19: =EOMONTH(L19,0)-EOMONTH(L19,-3) -> 90 | T19: =IF($B$10="3BR_H", INDEX('3BR_H-combined'!$C:$BH,MATCH($L19,'3BR_H-combined'!$B:$B,0),MATCH(Council_Area,'3BR_H-combined'!$C$1:$BH$1,0)), INDEX('2BR_F-combined'!$C:$BH,MATCH($L19,'2BR_F-combined'!$B:$B,0),MATCH(Council_Area,'2BR_F-combined'!$C$1:$BH$1,0))) -> 380 | U19: =IF(MOD(Q19,4)=1,T19,U18) -> 380 | V19: =U19*(R19)/7 -> 4885.7143 | W19: =$B$53/4*BH19/_xlfn.XLOOKUP(Q_end,cpi!A:A,cpi!B:B) -> 131.58258 | X19: =V19+W19 -> 5017.2969 | Y19: =BG19-X19 -> 4044.7544 | Z19: =Y19*$B$47 -> 1294.3214 | AA19: =(Y19+Z19)*eff_invest -> 5339.0758 | AB19: =AA19*(_xlfn.XLOOKUP(Q_end,cpi!A:A,cpi!B:B)/BH19) -> 8115.1708 | AC19: {=INDEX('msci-indices'!C:C,MATCH($L19,'msci-indices'!$B:$B)-2)} -> 765.74116 | AD19: {=INDEX('msci-indices'!D:D,MATCH($L19,'msci-indices'!$B:$B)-2)} -> 878.3433 | AE19: =AI18+AA19 -> 274411.05 | AF19: {=INDEX('msci-indices'!C:C,MATCH($L19,'msci-indices'!$B:$B)+1)} -> 794.63718 | AG19: {=INDEX('msci-indices'!D:D,MATCH($L19,'msci-indices'!$B:$B)+1)} -> 893.60148 | AH19: =(InvestFees/4)*AE19 -> 171.50691 | AI19: =((AF19/AC19)*GlobalPortfolio+(AG19/AD19)*AusPortfolio)*AE19-AH19 -> 282918.25 | AJ19: =AJ18+AA19 -> 267019.1 | AK19: =AI19-AJ19 -> 15899.151 | AL19: =AJ19*(_xlfn.XLOOKUP(Q_end,cpi!A:A,cpi!B:B)/BH19) -> 405857.81 | AM19: {=SUMPRODUCT($AA$3:AA19,_xlfn.SORTBY($BH$3:BH19,_xlfn.SEQUENCE(ROWS($BH$3:BH19)),-1)/$BH$3)} -> 294104.56 | AN19: =AI19-AM19 -> -11186.31 | AO19: =IF($B$49="Real gains",MAX($B$50*AN19,0),IF($B$49="Discounted nominal gains",MAX($B$50*AK19/2,0),0)) -> 0 | AP19: =AI19-AO19 -> 282918.25 | AR19: =IF($B$10="3BR_H", INDEX('ns-combined'!$C:$BH,MATCH($L19,'ns-combined'!$B:$B,0),MATCH(Council_Area,'ns-combined'!$C$1:$BH$1,0))*1000, INDEX('s-combined'!$C:$BH,MATCH($L19,'s-combined'!$B:$B,0),MATCH(Council_Area,'s-combined'!$C$1:$BH$1,0))*1000) -> 566000 | AS19: =AS18+$AS$3 -> 19550 | AT19: 0 | AU19: =SUM($B$28:$B$29)*AR19 -> 11320 | AV19: =AR19*$B$15/4 -> 1627.25 | AW19: =SUM($AV$3:AV19) -> 24115.5 | AX19: =AR19-AS19-AU19-AW19 -> 511014.5 | AY19: =$B$36*V19 -> 1710 | AZ19: =SUM(AY19:AY19)*4/AR19 -> 0.012084806 | BA19: =SUM(AY19:AY19)/V19 -> 0.35 | BB19: =IF(MortgageRate="Discounted",_xlfn.XLOOKUP(L19,'mortgage-rates'!$A:$A,'mortgage-rates'!$E:$E)/100,_xlfn.XLOOKUP(L19,'mortgage-rates'!$A:$A,'mortgage-rates'!$D:$D)/100) -> 0.0625 | BC19: =BC18-BF18 -> 342597.76 | BD19: =IF($B$16*12/3-Q19+1>0,-PMT($BB19/4,$B$16*12/3-Q19+1,BC19),0) -> 7352.0512 | BE19: =BC19*($BB19/4) -> 5353.09 | BF19: =BD19-BE19 -> 1998.9613 | BG19: =AT19+AY19+BD19 -> 9062.0512 | BH19: =INDEX(cpi!B:B,MATCH($L19,cpi!A:A)) -> 95.2 | BI19: =100*BH19/BH$3 -> 112.52955 | BJ19: =100*AC19/AC$3 -> 101.43885 | BK19: =100*AD19/AD$3 -> 123.19736 | BL19: =BJ19*GlobalPortfolio+BK19*AusPortfolio -> 107.9664 | BM19: =100*AE19/$AE$3 -> 172.77019 | BN19: =100*AR19/AR$3 -> 123.04348 | BO19: =100*AX19/AX$3 -> 113.98241
