Workbook
Name A83728543L: 'ABS-total-value-dwellings'!$AF$1:$AF$10,'ABS-total-value-dwellings'!$AF$11:$AF$106
Name A83728543L_Data: 'ABS-total-value-dwellings'!$AF$11:$AF$106
Name A83728543L_Latest: 'ABS-total-value-dwellings'!$AF$106
Name A83728544R: 'ABS-total-value-dwellings'!$AU$1:$AU$10,'ABS-total-value-dwellings'!$AU$17:$AU$106
Name A83728544R_Data: 'ABS-total-value-dwellings'!$AU$17:$AU$106
Name A83728544R_Latest: 'ABS-total-value-dwellings'!$AU$106
Name A83728545T: 'ABS-total-value-dwellings'!$B$1:$B$10,'ABS-total-value-dwellings'!$B$11:$B$106
Name A83728545T_Data: 'ABS-total-value-dwellings'!$B$11:$B$106
Name A83728545T_Latest: 'ABS-total-value-dwellings'!$B$106
Name A83728546V: 'ABS-total-value-dwellings'!$Q$1:$Q$10,'ABS-total-value-dwellings'!$Q$17:$Q$106
Name A83728546V_Data: 'ABS-total-value-dwellings'!$Q$17:$Q$106
Name A83728546V_Latest: 'ABS-total-value-dwellings'!$Q$106
Name A83728547W: 'ABS-total-value-dwellings'!$AH$1:$AH$10,'ABS-total-value-dwellings'!$AH$11:$AH$106
Name A83728547W_Data: 'ABS-total-value-dwellings'!$AH$11:$AH$106
Name A83728547W_Latest: 'ABS-total-value-dwellings'!$AH$106
Name A83728548X: 'ABS-total-value-dwellings'!$AW$1:$AW$10,'ABS-total-value-dwellings'!$AW$17:$AW$106
Name A83728548X_Data: 'ABS-total-value-dwellings'!$AW$17:$AW$106
Name A83728548X_Latest: 'ABS-total-value-dwellings'!$AW$106
Name A83728549A: 'ABS-total-value-dwellings'!$D$1:$D$10,'ABS-total-value-dwellings'!$D$11:$D$106
Name A83728549A_Data: 'ABS-total-value-dwellings'!$D$11:$D$106
Name A83728549A_Latest: 'ABS-total-value-dwellings'!$D$106
Name A83728550K: 'ABS-total-value-dwellings'!$S$1:$S$10,'ABS-total-value-dwellings'!$S$17:$S$106
Name A83728550K_Data: 'ABS-total-value-dwellings'!$S$17:$S$106
Name A83728550K_Latest: 'ABS-total-value-dwellings'!$S$106
Name A83728551L: 'ABS-total-value-dwellings'!$AJ$1:$AJ$10,'ABS-total-value-dwellings'!$AJ$11:$AJ$106
Name A83728551L_Data: 'ABS-total-value-dwellings'!$AJ$11:$AJ$106
Name A83728551L_Latest: 'ABS-total-value-dwellings'!$AJ$106
Name A83728552R: 'ABS-total-value-dwellings'!$AY$1:$AY$10,'ABS-total-value-dwellings'!$AY$17:$AY$106
Name A83728552R_Data: 'ABS-total-value-dwellings'!$AY$17:$AY$106
Name A83728552R_Latest: 'ABS-total-value-dwellings'!$AY$106
Name A83728553T: 'ABS-total-value-dwellings'!$F$1:$F$10,'ABS-total-value-dwellings'!$F$11:$F$106
Name A83728553T_Data: 'ABS-total-value-dwellings'!$F$11:$F$106
Name A83728553T_Latest: 'ABS-total-value-dwellings'!$F$106
Name A83728554V: 'ABS-total-value-dwellings'!$U$1:$U$10,'ABS-total-value-dwellings'!$U$17:$U$106
Name A83728554V_Data: 'ABS-total-value-dwellings'!$U$17:$U$106
Name A83728554V_Latest: 'ABS-total-value-dwellings'!$U$106
Name A83728555W: 'ABS-total-value-dwellings'!$AL$1:$AL$10,'ABS-total-value-dwellings'!$AL$11:$AL$106
Name A83728555W_Data: 'ABS-total-value-dwellings'!$AL$11:$AL$106
Name A83728555W_Latest: 'ABS-total-value-dwellings'!$AL$106
Name A83728556X: 'ABS-total-value-dwellings'!$BA$1:$BA$10,'ABS-total-value-dwellings'!$BA$17:$BA$106
Name A83728556X_Data: 'ABS-total-value-dwellings'!$BA$17:$BA$106
Name A83728556X_Latest: 'ABS-total-value-dwellings'!$BA$106
Name A83728557A: 'ABS-total-value-dwellings'!$H$1:$H$10,'ABS-total-value-dwellings'!$H$11:$H$106
Name A83728557A_Data: 'ABS-total-value-dwellings'!$H$11:$H$106
Name A83728557A_Latest: 'ABS-total-value-dwellings'!$H$106
Name A83728558C: 'ABS-total-value-dwellings'!$W$1:$W$10,'ABS-total-value-dwellings'!$W$17:$W$106
Name A83728558C_Data: 'ABS-total-value-dwellings'!$W$17:$W$106
Name A83728558C_Latest: 'ABS-total-value-dwellings'!$W$106
Name A83728559F: 'ABS-total-value-dwellings'!$AN$1:$AN$10,'ABS-total-value-dwellings'!$AN$11:$AN$106
Name A83728559F_Data: 'ABS-total-value-dwellings'!$AN$11:$AN$106
Name A83728559F_Latest: 'ABS-total-value-dwellings'!$AN$106
Name A83728560R: 'ABS-total-value-dwellings'!$BC$1:$BC$10,'ABS-total-value-dwellings'!$BC$17:$BC$106
Name A83728560R_Data: 'ABS-total-value-dwellings'!$BC$17:$BC$106
Name A83728560R_Latest: 'ABS-total-value-dwellings'!$BC$106
Name A83728561T: 'ABS-total-value-dwellings'!$J$1:$J$10,'ABS-total-value-dwellings'!$J$11:$J$106
Name A83728561T_Data: 'ABS-total-value-dwellings'!$J$11:$J$106
Name A83728561T_Latest: 'ABS-total-value-dwellings'!$J$106
Name A83728562V: 'ABS-total-value-dwellings'!$Y$1:$Y$10,'ABS-total-value-dwellings'!$Y$17:$Y$106
Name A83728562V_Data: 'ABS-total-value-dwellings'!$Y$17:$Y$106
Name A83728562V_Latest: 'ABS-total-value-dwellings'!$Y$106

Sheet analysis
A1: Rent vs buy analysis - Adelaide | B1: Set values | C1: Default values | T1: Renter calcs >> | X1: {=SUM(_xlfn._xlws.FILTER(X3:X82,ISNUMBER(X3:X82)))} -> 393021.7 | AI1: CGT calcs | AR1: Buyer calcs >> | AY1: Maintenance and renovation | BB1: Mortgage | BG1: {=SUM(_xlfn._xlws.FILTER(BG3:BG82,ISNUMBER(BG3:BG82)))} -> 546411.05 | BH1: Comparison vs inflation
A2: Ending renter-to-owner wealth ratio | B2: =_xlfn.XLOOKUP(Q_end,L:L,O:O) -> 0.94039311 | E2: ="Renter vs owner wealth, "&Council_Area&IF(B10="2BR_F"," 2-bedroom flat"," 3-bedroom house") -> Renter vs owner wealth, Adelaide 3-bedroom house | L2: Quarter ending | M2: Renter's portfolio | N2: Owner's home equity | O2: Renter-to-owner wealth ratio | P2: Renter-to-owner cash needs | Q2: Quarter of analysis | R2: Days in quarter | T2: Median weekly rents, new bonds | U2: Renter's rents | V2: Quarterly rent | W2: Other renter costs | X2: Renter's cashflow costs | Y2: Renter additional cashflow | Z2: Tax concessions | AA2: Renter investment contributions | AB2: Contributions (CPI-adjusted to Q_end) | AC2: MSCI World index, start Q | AD2: MSCI Aus index, start Q | AE2: Portfolio, start Q | AF2: MSCI World index, end Q | AG2: MSCI Aus index, end Q | AH2: Investment fees | AI2: Portfolio, end Q, before CGT | AJ2: Cost base (nominal) | AK2: Nominal gains ($) | AL2: Cost base (CPI-adjusted to Q_end) | AM2: Cost base + CPI to current quarter | AN2: Real gains ($) | AO2: CGT on withdrawals | AP2: Portfolio, end Q | AR2: Median home price | AS2: Depreciation | AT2: Home purchase costs | AU2: Home sale costs | AV2: Renovation | AW2: Renovation, cumulative | AX2: Adjusted home price | AY2: Maintenance | AZ2: Total p.a. as % of home value | BA2: Total p.a. as % of rent | BB2: Mortgage rates | BC2: Loan balance | BD2: Mortgage payment | BE2: Mortgage interest | BF2: Mortgage - principal component | BG2: Owner's cashflow costs | BH2: CPI | BI2: CPI (Q_st art = 100) | BJ2: MSCI World (Q_start=100) | BK2: MSCI Aus (Q_start=100) | BL2: Portfolio index (Q_start=100) | BM2: Portfolio (Q_start=100) | BN2: Median home price (Q_start = 100) | BO2: Adjusted home price (Q_start = 100)
A3: Average renter-to-owner cashflow needs excl. home purchase costs | B3: {=SUM(_xlfn._xlws.FILTER($X$3:$X$82,ISNUMBER($X$3:$X$82)))/(SUM(_xlfn._xlws.FILTER($BG$3:$BG$82,ISNUMBER($BG$3:$BG$82)))-AT3)} -> 0.82596899 | L3: =Q_start -> 38777 | M3: =AP3 -> 78787.253 | N3: =AX3-BC3 -> 48895 | O3: =M3/N3 -> 1.611356 | P3: =X3/BG3 -> 0.041768055 | Q3: 1 | R3: =EOMONTH(L3,0)-EOMONTH(L3,-3) -> 90 | T3: =IF($B$10="3BR_H", INDEX('3BR_H-processed'!$E:$F,MATCH($L3,'3BR_H-processed'!$B:$B,0),MATCH(Council_Area,'3BR_H-processed'!$E$1:$F$1,0)), INDEX('2BR_F-processed'!$E:$F,MATCH($L3,'2BR_F-processed'!$B:$B,0),MATCH(Council_Area,'2BR_F-processed'!$E$1:$F$1,0))) -> 238.64607 | U3: =IF(MOD(Q3,4)=1,T3,U2) -> 238.64607 | V3: =U3*(R3)/7 -> 3068.3066 | W3: =$B$53/4*BH3/_xlfn.XLOOKUP(Q_end,cpi!A:A,cpi!B:B) -> 116.93158 | X3: =V3+W3 -> 3185.2382 | Y3: =BG3-X3 -> 73074.912 | Z3: =MAX(0,Y3*$B$47) -> 0 | AA3: {=(Y3+Z3)*eff_invest} -> 73074.912 | AB3: =AA3*(_xlfn.XLOOKUP(Q_end,cpi!A:A,cpi!B:B)/BH3) -> 124987.47 | AC3: {=INDEX('msci-indices'!C:C,MATCH($L3,'msci-indices'!$B:$B)-2)} -> 754.87961 | AD3: {=INDEX('msci-indices'!D:D,MATCH($L3,'msci-indices'!$B:$B)-2)} -> 712.95625 | AE3: =AA3 -> 73074.912 | AF3: {=INDEX('msci-indices'!C:C,MATCH($L3,'msci-indices'!$B:$B)+1)} -> 809.32012 | AG3: {=INDEX('msci-indices'!D:D,MATCH($L3,'msci-indices'!$B:$B)+1)} -> 780.24347 | AH3: =(InvestFees/4)*AE3 -> 45.67182 | AI3: =((AF3/AC3)*GlobalPortfolio+(AG3/AD3)*AusPortfolio)*AE3-AH3 -> 78787.253 | AJ3: =AA3 -> 73074.912 | AK3: =AI3-AJ3 -> 5712.3407 | AL3: =AJ3*(_xlfn.XLOOKUP(Q_end,cpi!A:A,cpi!B:B)/BH3) -> 124987.47 | AM3: =AA3 -> 73074.912 | AN3: =AI3-AM3 -> 5712.3407 | AO3: =IF($B$49="Real gains",MAX($B$50*AN3,0),IF($B$49="Discounted nominal gains",MAX($B$50*AK3/2,0),0)) -> 0 | AP3: =AI3-AO3 -> 78787.253 | AR3: =IF($B$10="3BR_H", INDEX('ns-combined'!$C:$D,MATCH($L3,'ns-combined'!$B:$B,0),MATCH(Council_Area,'ns-combined'!$C$1:$D$1,0))*1000, INDEX('s-combined'!$C:$D,MATCH($L3,'s-combined'!$B:$B,0),MATCH(Council_Area,'s-combined'!$C$1:$D$1,0))*1000) -> 280000 | AS3: =AR3*$B$14/4 -> 700 | AT3: =SUM(B20:B26)*AR3 -> 70580 | AU3: =SUM($B$28:$B$29)*AR3 -> 5600 | AV3: =AR3*$B$15/4 -> 805 | AW3: =SUM($AV$3:AV3) -> 805 | AX3: =AR3-AS3-AU3-AW3 -> 272895 | AY3: =$B$36*V3 -> 1073.9073 | AZ3: =SUM(AY3:AY3)*4/AR3 -> 0.015341533 | BA3: =SUM(AY3:AY3)/V3 -> 0.35 | BB3: =IF(MortgageRate="Discounted",_xlfn.XLOOKUP(L3,'mortgage-rates'!$A:$A,'mortgage-rates'!$E:$E)/100,_xlfn.XLOOKUP(L3,'mortgage-rates'!$A:$A,'mortgage-rates'!$D:$D)/100) -> 0.0664 | BC3: =(1-B20)*AR3 -> 224000 | BD3: =IF($B$16*12/3-Q3+1>0,-PMT($BB3/4,$B$16*12/3-Q3+1,BC3),0) -> 4606.2433 | BE3: =BC3*($BB3/4) -> 3718.4 | BF3: =BD3-BE3 -> 887.84334 | BG3: =AT3+AY3+BD3 -> 76260.151 | BH3: =INDEX(cpi!B:B,MATCH($L3,cpi!A:A)) -> 84.6 | BI3: =100*BH3/BH$3 -> 100 | BJ3: =100*AC3/AC$3 -> 100 | BK3: =100*AD3/AD$3 -> 100 | BL3: =BJ3*GlobalPortfolio+BK3*AusPortfolio -> 100 | BM3: =100*AE3/$AE$3 -> 100 | BN3: =100*AR3/AR$3 -> 100 | BO3: =100*AX3/AX$3 -> 100
A4: Median home price growth p.a. | B4: =((_xlfn.XLOOKUP(Q_end,L:L,AR:AR)/_xlfn.XLOOKUP(Q_start,L:L,AR:AR))^(1/YEARFRAC(EOMONTH(Q_start,-3)+1,EOMONTH(Q_end,0))))-1 -> 0.062987797 | L4: =IF(DATE(YEAR(L3),MONTH(L3)+3,1)<=Q_end,DATE(YEAR(L3),MONTH(L3)+3,1),"") -> 38869 | M4: =AP4 -> 80853.41 | N4: =AX4-BC4 -> 54140.593 | O4: =M4/N4 -> 1.4933972 | P4: =X4/BG4 -> 0.55396017 | Q4: 2 | R4: =EOMONTH(L4,0)-EOMONTH(L4,-3) -> 91 | T4: =IF($B$10="3BR_H", INDEX('3BR_H-processed'!$E:$F,MATCH($L4,'3BR_H-processed'!$B:$B,0),MATCH(Council_Area,'3BR_H-processed'!$E$1:$F$1,0)), INDEX('2BR_F-processed'!$E:$F,MATCH($L4,'2BR_F-processed'!$B:$B,0),MATCH(Council_Area,'2BR_F-processed'!$E$1:$F$1,0))) -> 238.64607 | U4: =IF(MOD(Q4,4)=1,T4,U3) -> 238.64607 | V4: =U4*(R4)/7 -> 3102.3989 | W4: =$B$53/4*BH4/_xlfn.XLOOKUP(Q_end,cpi!A:A,cpi!B:B) -> 118.7284 | X4: =V4+W4 -> 3221.1273 | Y4: =BG4-X4 -> 2593.5999 | Z4: =Y4*$B$47 -> 0 | AA4: {=(Y4+Z4)*eff_invest} -> 2593.5999 | AB4: =AA4*(_xlfn.XLOOKUP(Q_end,cpi!A:A,cpi!B:B)/BH4) -> 4368.9629 | AC4: {=INDEX('msci-indices'!C:C,MATCH($L4,'msci-indices'!$B:$B)-2)} -> 809.32012 | AD4: {=INDEX('msci-indices'!D:D,MATCH($L4,'msci-indices'!$B:$B)-2)} -> 780.24347 | AE4: =AI3+AA4 -> 81380.853 | AF4: {=INDEX('msci-indices'!C:C,MATCH($L4,'msci-indices'!$B:$B)+1)} -> 802.64573 | AG4: {=INDEX('msci-indices'!D:D,MATCH($L4,'msci-indices'!$B:$B)+1)} -> 780.02674 | AH4: =(InvestFees/4)*AE4 -> 50.863033 | AI4: =((AF4/AC4)*GlobalPortfolio+(AG4/AD4)*AusPortfolio)*AE4-AH4 -> 80853.41 | AJ4: =AJ3+AA4 -> 75668.512 | AK4: =AI4-AJ4 -> 5184.898 | AL4: =AJ4*(_xlfn.XLOOKUP(Q_end,cpi!A:A,cpi!B:B)/BH4) -> 127464.89 | AM4: {=SUMPRODUCT($AA$3:AA4,_xlfn.SORTBY($BH$3:BH4,_xlfn.SEQUENCE(ROWS($BH$3:BH4)),-1)/$BH$3)} -> 76791.413 | AN4: =AI4-AM4 -> 4061.9975 | AO4: =IF($B$49="Real gains",MAX($B$50*AN4,0),IF($B$49="Discounted nominal gains",MAX($B$50*AK4/2,0),0)) -> 0 | AP4: =AI4-AO4 -> 80853.41 | AR4: =IF($B$10="3BR_H", INDEX('ns-combined'!$C:$D,MATCH($L4,'ns-combined'!$B:$B,0),MATCH(Council_Area,'ns-combined'!$C$1:$D$1,0))*1000, INDEX('s-combined'!$C:$D,MATCH($L4,'s-combined'!$B:$B,0),MATCH(Council_Area,'s-combined'!$C$1:$D$1,0))*1000) -> 286000 | AS4: =AS3+$AS$3 -> 1400 | AT4: 0 | AU4: =SUM($B$28:$B$29)*AR4 -> 5720 | AV4: =AR4*$B$15/4 -> 822.25 | AW4: =SUM($AV$3:AV4) -> 1627.25 | AX4: =AR4-AS4-AU4-AW4 -> 277252.75 | AY4: =$B$36*V4 -> 1085.8396 | AZ4: =SUM(AY4:AY4)*4/AR4 -> 0.015186568 | BA4: =SUM(AY4:AY4)/V4 -> 0.35 | BB4: =IF(MortgageRate="Discounted",_xlfn.XLOOKUP(L4,'mortgage-rates'!$A:$A,'mortgage-rates'!$E:$E)/100,_xlfn.XLOOKUP(L4,'mortgage-rates'!$A:$A,'mortgage-rates'!$D:$D)/100) -> 0.0693 | BC4: =BC3-BF3 -> 223112.16 | BD4: =IF($B$16*12/3-Q4+1>0,-PMT($BB4/4,$B$16*12/3-Q4+1,BC4),0) -> 4728.8876 | BE4: =BC4*($BB4/4) -> 3865.4181 | BF4: =BD4-BE4 -> 863.4695 | BG4: =AT4+AY4+BD4 -> 5814.7272 | BH4: =INDEX(cpi!B:B,MATCH($L4,cpi!A:A)) -> 85.9 | BI4: =100*BH4/BH$3 -> 101.53664 | BJ4: =100*AC4/AC$3 -> 107.21181 | BK4: =100*AD4/AD$3 -> 109.43778 | BL4: =BJ4*GlobalPortfolio+BK4*AusPortfolio -> 107.8796 | BM4: =100*AE4/$AE$3 -> 111.36634 | BN4: =100*AR4/AR$3 -> 102.14286 | BO4: =100*AX4/AX$3 -> 101.59686
A5: Adjusted home price growth p.a. | B5: =((_xlfn.XLOOKUP(Q_end,L:L,AX:AX)/_xlfn.XLOOKUP(Q_start,L:L,AX:AX))^(1/YEARFRAC(EOMONTH(Q_start,-3)+1,EOMONTH(Q_end,0))))-1 -> 0.052745728 | L5: =DATE(YEAR(L4),MONTH(L4)+3,1) -> 38961 | M5: =AP5 -> 86543.751 | N5: =AX5-BC5 -> 57390.313 | O5: =M5/N5 -> 1.5079853 | P5: =X5/BG5 -> 0.54726718 | Q5: 3 | R5: =EOMONTH(L5,0)-EOMONTH(L5,-3) -> 92 | T5: =IF($B$10="3BR_H", INDEX('3BR_H-processed'!$E:$F,MATCH($L5,'3BR_H-processed'!$B:$B,0),MATCH(Council_Area,'3BR_H-processed'!$E$1:$F$1,0)), INDEX('2BR_F-processed'!$E:$F,MATCH($L5,'2BR_F-processed'!$B:$B,0),MATCH(Council_Area,'2BR_F-processed'!$E$1:$F$1,0))) -> 238.64607 | U5: =IF(MOD(Q5,4)=1,T5,U4) -> 238.64607 | V5: =U5*(R5)/7 -> 3136.4912 | W5: =$B$53/4*BH5/_xlfn.XLOOKUP(Q_end,cpi!A:A,cpi!B:B) -> 119.69592 | X5: =V5+W5 -> 3256.1871 | Y5: =BG5-X5 -> 2693.7167 | Z5: =Y5*$B$47 -> 0 | AA5: {=(Y5+Z5)*eff_invest} -> 2693.7167 | AB5: =AA5*(_xlfn.XLOOKUP(Q_end,cpi!A:A,cpi!B:B)/BH5) -> 4500.9331 | AC5: {=INDEX('msci-indices'!C:C,MATCH($L5,'msci-indices'!$B:$B)-2)} -> 802.64573 | AD5: {=INDEX('msci-indices'!D:D,MATCH($L5,'msci-indices'!$B:$B)-2)} -> 780.02674 | AE5: =AI4+AA5 -> 83547.127 | AF5: {=INDEX('msci-indices'!C:C,MATCH($L5,'msci-indices'!$B:$B)+1)} -> 835.13401 | AG5: {=INDEX('msci-indices'!D:D,MATCH($L5,'msci-indices'!$B:$B)+1)} -> 801.24067 | AH5: =(InvestFees/4)*AE5 -> 52.216954 | AI5: =((AF5/AC5)*GlobalPortfolio+(AG5/AD5)*AusPortfolio)*AE5-AH5 -> 86543.751 | AJ5: =AJ4+AA5 -> 78362.229 | AK5: =AI5-AJ5 -> 8181.5218 | AL5: =AJ5*(_xlfn.XLOOKUP(Q_end,cpi!A:A,cpi!B:B)/BH5) -> 130935.5 | AM5: {=SUMPRODUCT($AA$3:AA5,_xlfn.SORTBY($BH$3:BH5,_xlfn.SEQUENCE(ROWS($BH$3:BH5)),-1)/$BH$3)} -> 80129.623 | AN5: =AI5-AM5 -> 6414.1281 | AO5: =IF($B$49="Real gains",MAX($B$50*AN5,0),IF($B$49="Discounted nominal gains",MAX($B$50*AK5/2,0),0)) -> 0 | AP5: =AI5-AO5 -> 86543.751 | AR5: =IF($B$10="3BR_H", INDEX('ns-combined'!$C:$D,MATCH($L5,'ns-combined'!$B:$B,0),MATCH(Council_Area,'ns-combined'!$C$1:$D$1,0))*1000, INDEX('s-combined'!$C:$D,MATCH($L5,'s-combined'!$B:$B,0),MATCH(Council_Area,'s-combined'!$C$1:$D$1,0))*1000) -> 290000 | AS5: =AS4+$AS$3 -> 2100 | AT5: 0 | AU5: =SUM($B$28:$B$29)*AR5 -> 5800 | AV5: =AR5*$B$15/4 -> 833.75 | AW5: =SUM($AV$3:AV5) -> 2461 | AX5: =AR5-AS5-AU5-AW5 -> 279639 | AY5: =$B$36*V5 -> 1097.7719 | AZ5: =SUM(AY5:AY5)*4/AR5 -> 0.015141682 | BA5: =SUM(AY5:AY5)/V5 -> 0.35 | BB5: =IF(MortgageRate="Discounted",_xlfn.XLOOKUP(L5,'mortgage-rates'!$A:$A,'mortgage-rates'!$E:$E)/100,_xlfn.XLOOKUP(L5,'mortgage-rates'!$A:$A,'mortgage-rates'!$D:$D)/100) -> 0.0722 | BC5: =BC4-BF4 -> 222248.69 | BD5: =IF($B$16*12/3-Q5+1>0,-PMT($BB5/4,$B$16*12/3-Q5+1,BC5),0) -> 4852.1319 | BE5: =BC5*($BB5/4) -> 4011.5888 | BF5: =BD5-BE5 -> 840.54311 | BG5: =AT5+AY5+BD5 -> 5949.9038 | BH5: =INDEX(cpi!B:B,MATCH($L5,cpi!A:A)) -> 86.6 | BI5: =100*BH5/BH$3 -> 102.36407 | BJ5: =100*AC5/AC$3 -> 106.32765 | BK5: =100*AD5/AD$3 -> 109.40738 | BL5: =BJ5*GlobalPortfolio+BK5*AusPortfolio -> 107.25157 | BM5: =100*AE5/$AE$3 -> 114.33079 | BN5: =100*AR5/AR$3 -> 103.57143 | BO5: =100*AX5/AX$3 -> 102.47128
A6: Rent growth p.a. | B6: =((_xlfn.XLOOKUP(Q_end,L:L,U:U)/_xlfn.XLOOKUP(Q_start,L:L,U:U))^(1/YEARFRAC(EOMONTH(Q_start,-3)+1,EOMONTH(Q_end,0))))-1 -> 0.046296774 | L6: =DATE(YEAR(L5),MONTH(L5)+3,1) -> 39052 | M6: =AP6 -> 97451.217 | N6: =AX6-BC6 -> 66468.356 | O6: =M6/N6 -> 1.4661295 | P6: =X6/BG6 -> 0.53765358 | Q6: 4 | R6: =EOMONTH(L6,0)-EOMONTH(L6,-3) -> 92 | T6: =IF($B$10="3BR_H", INDEX('3BR_H-processed'!$E:$F,MATCH($L6,'3BR_H-processed'!$B:$B,0),MATCH(Council_Area,'3BR_H-processed'!$E$1:$F$1,0)), INDEX('2BR_F-processed'!$E:$F,MATCH($L6,'2BR_F-processed'!$B:$B,0),MATCH(Council_Area,'2BR_F-processed'!$E$1:$F$1,0))) -> 238.64607 | U6: =IF(MOD(Q6,4)=1,T6,U5) -> 238.64607 | V6: =U6*(R6)/7 -> 3136.4912 | W6: =$B$53/4*BH6/_xlfn.XLOOKUP(Q_end,cpi!A:A,cpi!B:B) -> 119.83414 | X6: =V6+W6 -> 3256.3253 | Y6: =BG6-X6 -> 2800.2238 | Z6: =Y6*$B$47 -> 0 | AA6: {=(Y6+Z6)*eff_invest} -> 2800.2238 | AB6: =AA6*(_xlfn.XLOOKUP(Q_end,cpi!A:A,cpi!B:B)/BH6) -> 4673.4993 | AC6: {=INDEX('msci-indices'!C:C,MATCH($L6,'msci-indices'!$B:$B)-2)} -> 835.13401 | AD6: {=INDEX('msci-indices'!D:D,MATCH($L6,'msci-indices'!$B:$B)-2)} -> 801.24067 | AE6: =AI5+AA6 -> 89343.975 | AF6: {=INDEX('msci-indices'!C:C,MATCH($L6,'msci-indices'!$B:$B)+1)} -> 906.58022 | AG6: {=INDEX('msci-indices'!D:D,MATCH($L6,'msci-indices'!$B:$B)+1)} -> 885.32149 | AH6: =(InvestFees/4)*AE6 -> 55.839984 | AI6: =((AF6/AC6)*GlobalPortfolio+(AG6/AD6)*AusPortfolio)*AE6-AH6 -> 97451.217 | AJ6: =AJ5+AA6 -> 81162.453 | AK6: =AI6-AJ6 -> 16288.764 | AL6: =AJ6*(_xlfn.XLOOKUP(Q_end,cpi!A:A,cpi!B:B)/BH6) -> 135457.98 | AM6: {=SUMPRODUCT($AA$3:AA6,_xlfn.SORTBY($BH$3:BH6,_xlfn.SEQUENCE(ROWS($BH$3:BH6)),-1)/$BH$3)} -> 83079.076 | AN6: =AI6-AM6 -> 14372.14 | AO6: =IF($B$49="Real gains",MAX($B$50*AN6,0),IF($B$49="Discounted nominal gains",MAX($B$50*AK6/2,0),0)) -> 0 | AP6: =AI6-AO6 -> 97451.217 | AR6: =IF($B$10="3BR_H", INDEX('ns-combined'!$C:$D,MATCH($L6,'ns-combined'!$B:$B,0),MATCH(Council_Area,'ns-combined'!$C$1:$D$1,0))*1000, INDEX('s-combined'!$C:$D,MATCH($L6,'s-combined'!$B:$B,0),MATCH(Council_Area,'s-combined'!$C$1:$D$1,0))*1000) -> 300000 | AS6: =AS5+$AS$3 -> 2800 | AT6: 0 | AU6: =SUM($B$28:$B$29)*AR6 -> 6000 | AV6: =AR6*$B$15/4 -> 862.5 | AW6: =SUM($AV$3:AV6) -> 3323.5 | AX6: =AR6-AS6-AU6-AW6 -> 287876.5 | AY6: =$B$36*V6 -> 1097.7719 | AZ6: =SUM(AY6:AY6)*4/AR6 -> 0.014636959 | BA6: =SUM(AY6:AY6)/V6 -> 0.35 | BB6: =IF(MortgageRate="Discounted",_xlfn.XLOOKUP(L6,'mortgage-rates'!$A:$A,'mortgage-rates'!$E:$E)/100,_xlfn.XLOOKUP(L6,'mortgage-rates'!$A:$A,'mortgage-rates'!$D:$D)/100) -> 0.0747 | BC6: =BC5-BF5 -> 221408.14 | BD6: =IF($B$16*12/3-Q6+1>0,-PMT($BB6/4,$B$16*12/3-Q6+1,BC6),0) -> 4958.7772 | BE6: =BC6*($BB6/4) -> 4134.7971 | BF6: =BD6-BE6 -> 823.98014 | BG6: =AT6+AY6+BD6 -> 6056.5492 | BH6: =INDEX(cpi!B:B,MATCH($L6,cpi!A:A)) -> 86.7 | BI6: =100*BH6/BH$3 -> 102.48227 | BJ6: =100*AC6/AC$3 -> 110.63142 | BK6: =100*AD6/AD$3 -> 112.38287 | BL6: =BJ6*GlobalPortfolio+BK6*AusPortfolio -> 111.15685 | BM6: =100*AE6/$AE$3 -> 122.26354 | BN6: =100*AR6/AR$3 -> 107.14286 | BO6: =100*AX6/AX$3 -> 105.48984
A7: Investment index (country-weighted) growth p.a. | B7: =((_xlfn.XLOOKUP(Q_end,L:L,BL:BL)/_xlfn.XLOOKUP(Q_start,L:L,BL:BL))^(1/YEARFRAC(EOMONTH(Q_start,-3)+1,EOMONTH(Q_end,0))))-1 -> 0.080631422 | L7: =DATE(YEAR(L6),MONTH(L6)+3,1) -> 39142 | M7: =AP7 -> 104138.17 | N7: =AX7-BC7 -> 70615.461 | O7: =M7/N7 -> 1.474722 | P7: =X7/BG7 -> 0.55539464 | Q7: 5 | R7: =EOMONTH(L7,0)-EOMONTH(L7,-3) -> 90 | T7: =IF($B$10="3BR_H", INDEX('3BR_H-processed'!$E:$F,MATCH($L7,'3BR_H-processed'!$B:$B,0),MATCH(Council_Area,'3BR_H-processed'!$E$1:$F$1,0)), INDEX('2BR_F-processed'!$E:$F,MATCH($L7,'2BR_F-processed'!$B:$B,0),MATCH(Council_Area,'2BR_F-processed'!$E$1:$F$1,0))) -> 254.32303 | U7: =IF(MOD(Q7,4)=1,T7,U6) -> 254.32303 | V7: =U7*(R7)/7 -> 3269.8676 | W7: =$B$53/4*BH7/_xlfn.XLOOKUP(Q_end,cpi!A:A,cpi!B:B) -> 119.83414 | X7: =V7+W7 -> 3389.7017 | Y7: =BG7-X7 -> 2713.5292 | Z7: =Y7*$B$47 -> 0 | AA7: {=(Y7+Z7)*eff_invest} -> 2713.5292 | AB7: =AA7*(_xlfn.XLOOKUP(Q_end,cpi!A:A,cpi!B:B)/BH7) -> 4528.8082 | AC7: {=INDEX('msci-indices'!C:C,MATCH($L7,'msci-indices'!$B:$B)-2)} -> 906.58022 | AD7: {=INDEX('msci-indices'!D:D,MATCH($L7,'msci-indices'!$B:$B)-2)} -> 885.32149 | AE7: =AI6+AA7 -> 100164.75 | AF7: {=INDEX('msci-indices'!C:C,MATCH($L7,'msci-indices'!$B:$B)+1)} -> 932.09759 | AG7: {=INDEX('msci-indices'!D:D,MATCH($L7,'msci-indices'!$B:$B)+1)} -> 946.08734 | AH7: =(InvestFees/4)*AE7 -> 62.602966 | AI7: =((AF7/AC7)*GlobalPortfolio+(AG7/AD7)*AusPortfolio)*AE7-AH7 -> 104138.17 | AJ7: =AJ6+AA7 -> 83875.982 | AK7: =AI7-AJ7 -> 20262.189 | AL7: =AJ7*(_xlfn.XLOOKUP(Q_end,cpi!A:A,cpi!B:B)/BH7) -> 139986.79 | AM7: {=SUMPRODUCT($AA$3:AA7,_xlfn.SORTBY($BH$3:BH7,_xlfn.SEQUENCE(ROWS($BH$3:BH7)),-1)/$BH$3)} -> 85860.989 | AN7: =AI7-AM7 -> 18277.182 | AO7: =IF($B$49="Real gains",MAX($B$50*AN7,0),IF($B$49="Discounted nominal gains",MAX($B$50*AK7/2,0),0)) -> 0 | AP7: =AI7-AO7 -> 104138.17 | AR7: =IF($B$10="3BR_H", INDEX('ns-combined'!$C:$D,MATCH($L7,'ns-combined'!$B:$B,0),MATCH(Council_Area,'ns-combined'!$C$1:$D$1,0))*1000, INDEX('s-combined'!$C:$D,MATCH($L7,'s-combined'!$B:$B,0),MATCH(Council_Area,'s-combined'!$C$1:$D$1,0))*1000) -> 305000 | AS7: =AS6+$AS$3 -> 3500 | AT7: 0 | AU7: =SUM($B$28:$B$29)*AR7 -> 6100 | AV7: =AR7*$B$15/4 -> 876.875 | AW7: =SUM($AV$3:AV7) -> 4200.375 | AX7: =AR7-AS7-AU7-AW7 -> 291199.62 | AY7: =$B$36*V7 -> 1144.4537 | AZ7: =SUM(AY7:AY7)*4/AR7 -> 0.015009228 | BA7: =SUM(AY7:AY7)/V7 -> 0.35 | BB7: =IF(MortgageRate="Discounted",_xlfn.XLOOKUP(L7,'mortgage-rates'!$A:$A,'mortgage-rates'!$E:$E)/100,_xlfn.XLOOKUP(L7,'mortgage-rates'!$A:$A,'mortgage-rates'!$D:$D)/100) -> 0.0747 | BC7: =BC6-BF6 -> 220584.16 | BD7: =IF($B$16*12/3-Q7+1>0,-PMT($BB7/4,$B$16*12/3-Q7+1,BC7),0) -> 4958.7772 | BE7: =BC7*($BB7/4) -> 4119.4093 | BF7: =BD7-BE7 -> 839.36797 | BG7: =AT7+AY7+BD7 -> 6103.2309 | BH7: =INDEX(cpi!B:B,MATCH($L7,cpi!A:A)) -> 86.7 | BI7: =100*BH7/BH$3 -> 102.48227 | BJ7: =100*AC7/AC$3 -> 120.096 | BK7: =100*AD7/AD$3 -> 124.17613 | BL7: =BJ7*GlobalPortfolio+BK7*AusPortfolio -> 121.32004 | BM7: =100*AE7/$AE$3 -> 137.07132 | BN7: =100*AR7/AR$3 -> 108.92857 | BO7: =100*AX7/AX$3 -> 106.70757
A8: CPI growth p.a. | B8: =((_xlfn.XLOOKUP(Q_end,L:L,BI:BI)/_xlfn.XLOOKUP(Q_start,L:L,BI:BI))^(1/YEARFRAC(EOMONTH(Q_start,-3)+1,EOMONTH(Q_end,0))))-1 -> 0.027199758 | L8: =DATE(YEAR(L7),MONTH(L7)+3,1) -> 39234 | M8: =AP8 -> 113401.63 | N8: =AX8-BC8 -> 79649.204 | O8: =M8/N8 -> 1.4237636 | P8: =X8/BG8 -> 0.56040638 | Q8: 6 | R8: =EOMONTH(L8,0)-EOMONTH(L8,-3) -> 91 | T8: =IF($B$10="3BR_H", INDEX('3BR_H-processed'!$E:$F,MATCH($L8,'3BR_H-processed'!$B:$B,0),MATCH(Council_Area,'3BR_H-processed'!$E$1:$F$1,0)), INDEX('2BR_F-processed'!$E:$F,MATCH($L8,'2BR_F-processed'!$B:$B,0),MATCH(Council_Area,'2BR_F-processed'!$E$1:$F$1,0))) -> 254.32303 | U8: =IF(MOD(Q8,4)=1,T8,U7) -> 254.32303 | V8: =U8*(R8)/7 -> 3306.1995 | W8: =$B$53/4*BH8/_xlfn.XLOOKUP(Q_end,cpi!A:A,cpi!B:B) -> 121.21631 | X8: =V8+W8 -> 3427.4158 | Y8: =BG8-X8 -> 2688.5313 | Z8: =Y8*$B$47 -> 0 | AA8: {=(Y8+Z8)*eff_invest} -> 2688.5313 | AB8: =AA8*(_xlfn.XLOOKUP(Q_end,cpi!A:A,cpi!B:B)/BH8) -> 4435.9233 | AC8: {=INDEX('msci-indices'!C:C,MATCH($L8,'msci-indices'!$B:$B)-2)} -> 932.09759 | AD8: {=INDEX('msci-indices'!D:D,MATCH($L8,'msci-indices'!$B:$B)-2)} -> 946.08734 | AE8: =AI7+AA8 -> 106826.7 | AF8: {=INDEX('msci-indices'!C:C,MATCH($L8,'msci-indices'!$B:$B)+1)} -> 991.70582 | AG8: {=INDEX('msci-indices'!D:D,MATCH($L8,'msci-indices'!$B:$B)+1)} -> 1000.9831 | AH8: =(InvestFees/4)*AE8 -> 66.766689 | AI8: =((AF8/AC8)*GlobalPortfolio+(AG8/AD8)*AusPortfolio)*AE8-AH8 -> 113401.63 | AJ8: =AJ7+AA8 -> 86564.513 | AK8: =AI8-AJ8 -> 26837.121 | AL8: =AJ8*(_xlfn.XLOOKUP(Q_end,cpi!A:A,cpi!B:B)/BH8) -> 142826.51 | AM8: {=SUMPRODUCT($AA$3:AA8,_xlfn.SORTBY($BH$3:BH8,_xlfn.SEQUENCE(ROWS($BH$3:BH8)),-1)/$BH$3)} -> 89481.341 | AN8: =AI8-AM8 -> 23920.293 | AO8: =IF($B$49="Real gains",MAX($B$50*AN8,0),IF($B$49="Discounted nominal gains",MAX($B$50*AK8/2,0),0)) -> 0 | AP8: =AI8-AO8 -> 113401.63 | AR8: =IF($B$10="3BR_H", INDEX('ns-combined'!$C:$D,MATCH($L8,'ns-combined'!$B:$B,0),MATCH(Council_Area,'ns-combined'!$C$1:$D$1,0))*1000, INDEX('s-combined'!$C:$D,MATCH($L8,'s-combined'!$B:$B,0),MATCH(Council_Area,'s-combined'!$C$1:$D$1,0))*1000) -> 315000 | AS8: =AS7+$AS$3 -> 4200 | AT8: 0 | AU8: =SUM($B$28:$B$29)*AR8 -> 6300 | AV8: =AR8*$B$15/4 -> 905.625 | AW8: =SUM($AV$3:AV8) -> 5106 | AX8: =AR8-AS8-AU8-AW8 -> 299394 | AY8: =$B$36*V8 -> 1157.1698 | AZ8: =SUM(AY8:AY8)*4/AR8 -> 0.01469422 | BA8: =SUM(AY8:AY8)/V8 -> 0.35 | BB8: =IF(MortgageRate="Discounted",_xlfn.XLOOKUP(L8,'mortgage-rates'!$A:$A,'mortgage-rates'!$E:$E)/100,_xlfn.XLOOKUP(L8,'mortgage-rates'!$A:$A,'mortgage-rates'!$D:$D)/100) -> 0.0747 | BC8: =BC7-BF7 -> 219744.8 | BD8: =IF($B$16*12/3-Q8+1>0,-PMT($BB8/4,$B$16*12/3-Q8+1,BC8),0) -> 4958.7772 | BE8: =BC8*($BB8/4) -> 4103.7341 | BF8: =BD8-BE8 -> 855.04317 | BG8: =AT8+AY8+BD8 -> 6115.947 | BH8: =INDEX(cpi!B:B,MATCH($L8,cpi!A:A)) -> 87.7 | BI8: =100*BH8/BH$3 -> 103.6643 | BJ8: =100*AC8/AC$3 -> 123.47632 | BK8: =100*AD8/AD$3 -> 132.69921 | BL8: =BJ8*GlobalPortfolio+BK8*AusPortfolio -> 126.24319 | BM8: =100*AE8/$AE$3 -> 146.18793 | BN8: =100*AR8/AR$3 -> 112.5 | BO8: =100*AX8/AX$3 -> 109.71033
L9: =DATE(YEAR(L8),MONTH(L8)+3,1) -> 39326 | M9: =AP9 -> 119680.18 | N9: =AX9-BC9 -> 98441.122 | O9: =M9/N9 -> 1.2157539 | P9: =X9/BG9 -> 0.55571823 | Q9: 7 | R9: =EOMONTH(L9,0)-EOMONTH(L9,-3) -> 92 | T9: =IF($B$10="3BR_H", INDEX('3BR_H-processed'!$E:$F,MATCH($L9,'3BR_H-processed'!$B:$B,0),MATCH(Council_Area,'3BR_H-processed'!$E$1:$F$1,0)), INDEX('2BR_F-processed'!$E:$F,MATCH($L9,'2BR_F-processed'!$B:$B,0),MATCH(Council_Area,'2BR_F-processed'!$E$1:$F$1,0))) -> 254.32303 | U9: =IF(MOD(Q9,4)=1,T9,U8) -> 254.32303 | V9: =U9*(R9)/7 -> 3342.5313 | W9: =$B$53/4*BH9/_xlfn.XLOOKUP(Q_end,cpi!A:A,cpi!B:B) -> 121.90739 | X9: =V9+W9 -> 3464.4387 | Y9: =BG9-X9 -> 2769.7255 | Z9: =Y9*$B$47 -> 0 | AA9: {=(Y9+Z9)*eff_invest} -> 2769.7255 | AB9: =AA9*(_xlfn.XLOOKUP(Q_end,cpi!A:A,cpi!B:B)/BH9) -> 4543.9828 | AC9: {=INDEX('msci-indices'!C:C,MATCH($L9,'msci-indices'!$B:$B)-2)} -> 991.70582 | AD9: {=INDEX('msci-indices'!D:D,MATCH($L9,'msci-indices'!$B:$B)-2)} -> 1000.9831 | AE9: =AI8+AA9 -> 116171.36 | AF9: {=INDEX('msci-indices'!C:C,MATCH($L9,'msci-indices'!$B:$B)+1)} -> 1009.8701 | AG9: {=INDEX('msci-indices'!D:D,MATCH($L9,'msci-indices'!$B:$B)+1)} -> 1061.067 | AH9: =(InvestFees/4)*AE9 -> 72.6071 | AI9: =((AF9/AC9)*GlobalPortfolio+(AG9/AD9)*AusPortfolio)*AE9-AH9 -> 119680.18 | AJ9: =AJ8+AA9 -> 89334.239 | AK9: =AI9-AJ9 -> 30345.941 | AL9: =AJ9*(_xlfn.XLOOKUP(Q_end,cpi!A:A,cpi!B:B)/BH9) -> 146560.82 | AM9: {=SUMPRODUCT($AA$3:AA9,_xlfn.SORTBY($BH$3:BH9,_xlfn.SEQUENCE(ROWS($BH$3:BH9)),-1)/$BH$3)} -> 92780.684 | AN9: =AI9-AM9 -> 26899.495 | AO9: =IF($B$49="Real gains",MAX($B$50*AN9,0),IF($B$49="Discounted nominal gains",MAX($B$50*AK9/2,0),0)) -> 0 | AP9: =AI9-AO9 -> 119680.18 | AR9: =IF($B$10="3BR_H", INDEX('ns-combined'!$C:$D,MATCH($L9,'ns-combined'!$B:$B,0),MATCH(Council_Area,'ns-combined'!$C$1:$D$1,0))*1000, INDEX('s-combined'!$C:$D,MATCH($L9,'s-combined'!$B:$B,0),MATCH(Council_Area,'s-combined'!$C$1:$D$1,0))*1000) -> 335000 | AS9: =AS8+$AS$3 -> 4900 | AT9: 0 | AU9: =SUM($B$28:$B$29)*AR9 -> 6700 | AV9: =AR9*$B$15/4 -> 963.125 | AW9: =SUM($AV$3:AV9) -> 6069.125 | AX9: =AR9-AS9-AU9-AW9 -> 317330.88 | AY9: =$B$36*V9 -> 1169.886 | AZ9: =SUM(AY9:AY9)*4/AR9 -> 0.013968788 | BA9: =SUM(AY9:AY9)/V9 -> 0.35 | BB9: =IF(MortgageRate="Discounted",_xlfn.XLOOKUP(L9,'mortgage-rates'!$A:$A,'mortgage-rates'!$E:$E)/100,_xlfn.XLOOKUP(L9,'mortgage-rates'!$A:$A,'mortgage-rates'!$D:$D)/100) -> 0.0772 | BC9: =BC8-BF8 -> 218889.75 | BD9: =IF($B$16*12/3-Q9+1>0,-PMT($BB9/4,$B$16*12/3-Q9+1,BC9),0) -> 5064.2783 | BE9: =BC9*($BB9/4) -> 4224.5722 | BF9: =BD9-BE9 -> 839.70606 | BG9: =AT9+AY9+BD9 -> 6234.1642 | BH9: =INDEX(cpi!B:B,MATCH($L9,cpi!A:A)) -> 88.2 | BI9: =100*BH9/BH$3 -> 104.25532 | BJ9: =100*AC9/AC$3 -> 131.37271 | BK9: =100*AD9/AD$3 -> 140.39895 | BL9: =BJ9*GlobalPortfolio+BK9*AusPortfolio -> 134.08059 | BM9: =100*AE9/$AE$3 -> 158.97571 | BN9: =100*AR9/AR$3 -> 119.64286 | BO9: =100*AX9/AX$3 -> 116.28314
A10: Dwelling type (3br house, 3BR_H; or 2br flat, 2BR_F) | B10: 3BR_H | C10: 3BR_H | L10: =DATE(YEAR(L9),MONTH(L9)+3,1) -> 39417 | M10: =AP10 -> 119165.39 | N10: =AX10-BC10 -> 120091.58 | O10: =M10/N10 -> 0.99228761 | P10: =X10/BG10 -> 0.54669013 | Q10: 8 | R10: =EOMONTH(L10,0)-EOMONTH(L10,-3) -> 92 | T10: =IF($B$10="3BR_H", INDEX('3BR_H-processed'!$E:$F,MATCH($L10,'3BR_H-processed'!$B:$B,0),MATCH(Council_Area,'3BR_H-processed'!$E$1:$F$1,0)), INDEX('2BR_F-processed'!$E:$F,MATCH($L10,'2BR_F-processed'!$B:$B,0),MATCH(Council_Area,'2BR_F-processed'!$E$1:$F$1,0))) -> 254.32303 | U10: =IF(MOD(Q10,4)=1,T10,U9) -> 254.32303 | V10: =U10*(R10)/7 -> 3342.5313 | W10: =$B$53/4*BH10/_xlfn.XLOOKUP(Q_end,cpi!A:A,cpi!B:B) -> 123.42778 | X10: =V10+W10 -> 3465.9591 | Y10: =BG10-X10 -> 2873.9378 | Z10: =Y10*$B$47 -> 0 | AA10: {=(Y10+Z10)*eff_invest} -> 2873.9378 | AB10: =AA10*(_xlfn.XLOOKUP(Q_end,cpi!A:A,cpi!B:B)/BH10) -> 4656.8735 | AC10: {=INDEX('msci-indices'!C:C,MATCH($L10,'msci-indices'!$B:$B)-2)} -> 1009.8701 | AD10: {=INDEX('msci-indices'!D:D,MATCH($L10,'msci-indices'!$B:$B)-2)} -> 1061.067 | AE10: =AI9+AA10 -> 122554.12 | AF10: {=INDEX('msci-indices'!C:C,MATCH($L10,'msci-indices'!$B:$B)+1)} -> 983.50383 | AG10: {=INDEX('msci-indices'!D:D,MATCH($L10,'msci-indices'!$B:$B)+1)} -> 1030.1196 | AH10: =(InvestFees/4)*AE10 -> 76.596323 | AI10: =((AF10/AC10)*GlobalPortfolio+(AG10/AD10)*AusPortfolio)*AE10-AH10 -> 119165.39 | AJ10: =AJ9+AA10 -> 92208.177 | AK10: =AI10-AJ10 -> 26957.209 | AL10: =AJ10*(_xlfn.XLOOKUP(Q_end,cpi!A:A,cpi!B:B)/BH10) -> 149412.35 | AM10: {=SUMPRODUCT($AA$3:AA10,_xlfn.SORTBY($BH$3:BH10,_xlfn.SEQUENCE(ROWS($BH$3:BH10)),-1)/$BH$3)} -> 96719.952 | AN10: =AI10-AM10 -> 22445.434 | AO10: =IF($B$49="Real gains",MAX($B$50*AN10,0),IF($B$49="Discounted nominal gains",MAX($B$50*AK10/2,0),0)) -> 0 | AP10: =AI10-AO10 -> 119165.39 | AR10: =IF($B$10="3BR_H", INDEX('ns-combined'!$C:$D,MATCH($L10,'ns-combined'!$B:$B,0),MATCH(Council_Area,'ns-combined'!$C$1:$D$1,0))*1000, INDEX('s-combined'!$C:$D,MATCH($L10,'s-combined'!$B:$B,0),MATCH(Council_Area,'s-combined'!$C$1:$D$1,0))*1000) -> 358000 | AS10: =AS9+$AS$3 -> 5600 | AT10: 0 | AU10: =SUM($B$28:$B$29)*AR10 -> 7160 | AV10: =AR10*$B$15/4 -> 1029.25 | AW10: =SUM($AV$3:AV10) -> 7098.375 | AX10: =AR10-AS10-AU10-AW10 -> 338141.62 | AY10: =$B$36*V10 -> 1169.886 | AZ10: =SUM(AY10:AY10)*4/AR10 -> 0.013071352 | BA10: =SUM(AY10:AY10)/V10 -> 0.35 | BB10: =IF(MortgageRate="Discounted",_xlfn.XLOOKUP(L10,'mortgage-rates'!$A:$A,'mortgage-rates'!$E:$E)/100,_xlfn.XLOOKUP(L10,'mortgage-rates'!$A:$A,'mortgage-rates'!$D:$D)/100) -> 0.0797 | BC10: =BC9-BF9 -> 218050.05 | BD10: =IF($B$16*12/3-Q10+1>0,-PMT($BB10/4,$B$16*12/3-Q10+1,BC10),0) -> 5170.011 | BE10: =BC10*($BB10/4) -> 4344.6472 | BF10: =BD10-BE10 -> 825.36378 | BG10: =AT10+AY10+BD10 -> 6339.8969 | BH10: =INDEX(cpi!B:B,MATCH($L10,cpi!A:A)) -> 89.3 | BI10: =100*BH10/BH$3 -> 105.55556 | BJ10: =100*AC10/AC$3 -> 133.77897 | BK10: =100*AD10/AD$3 -> 148.82639 | BL10: =BJ10*GlobalPortfolio+BK10*AusPortfolio -> 138.29319 | BM10: =100*AE10/$AE$3 -> 167.71025 | BN10: =100*AR10/AR$3 -> 127.85714 | BO10: =100*AX10/AX$3 -> 123.90906
A11: Analysis start quarter | B11: 38777 | C11: 38777 | L11: =DATE(YEAR(L10),MONTH(L10)+3,1) -> 39508 | M11: =AP11 -> 109163.03 | N11: =AX11-BC11 -> 121141.94 | O11: =M11/N11 -> 0.90111674 | P11: =X11/BG11 -> 0.54169253 | Q11: 9 | R11: =EOMONTH(L11,0)-EOMONTH(L11,-3) -> 91 | T11: =IF($B$10="3BR_H", INDEX('3BR_H-processed'!$E:$F,MATCH($L11,'3BR_H-processed'!$B:$B,0),MATCH(Council_Area,'3BR_H-processed'!$E$1:$F$1,0)), INDEX('2BR_F-processed'!$E:$F,MATCH($L11,'2BR_F-processed'!$B:$B,0),MATCH(Council_Area,'2BR_F-processed'!$E$1:$F$1,0))) -> 270 | U11: =IF(MOD(Q11,4)=1,T11,U10) -> 270 | V11: =U11*(R11)/7 -> 3510 | W11: =$B$53/4*BH11/_xlfn.XLOOKUP(Q_end,cpi!A:A,cpi!B:B) -> 124.94817 | X11: =V11+W11 -> 3634.9482 | Y11: =BG11-X11 -> 3075.4049 | Z11: =Y11*$B$47 -> 0 | AA11: {=(Y11+Z11)*eff_invest} -> 3075.4049 | AB11: =AA11*(_xlfn.XLOOKUP(Q_end,cpi!A:A,cpi!B:B)/BH11) -> 4922.6891 | AC11: {=INDEX('msci-indices'!C:C,MATCH($L11,'msci-indices'!$B:$B)-2)} -> 983.50383 | AD11: {=INDEX('msci-indices'!D:D,MATCH($L11,'msci-indices'!$B:$B)-2)} -> 1030.1196 | AE11: =AI10+AA11 -> 122240.79 | AF11: {=INDEX('msci-indices'!C:C,MATCH($L11,'msci-indices'!$B:$B)+1)} -> 894.99836 | AG11: {=INDEX('msci-indices'!D:D,MATCH($L11,'msci-indices'!$B:$B)+1)} -> 881.21373 | AH11: =(InvestFees/4)*AE11 -> 76.400494 | AI11: =((AF11/AC11)*GlobalPortfolio+(AG11/AD11)*AusPortfolio)*AE11-AH11 -> 109163.03 | AJ11: =AJ10+AA11 -> 95283.582 | AK11: =AI11-AJ11 -> 13879.45 | AL11: =AJ11*(_xlfn.XLOOKUP(Q_end,cpi!A:A,cpi!B:B)/BH11) -> 152516.97 | AM11: {=SUMPRODUCT($AA$3:AA11,_xlfn.SORTBY($BH$3:BH11,_xlfn.SEQUENCE(ROWS($BH$3:BH11)),-1)/$BH$3)} -> 100898.5 | AN11: =AI11-AM11 -> 8264.528 | AO11: =IF($B$49="Real gains",MAX($B$50*AN11,0),IF($B$49="Discounted nominal gains",MAX($B$50*AK11/2,0),0)) -> 0 | AP11: =AI11-AO11 -> 109163.03 | AR11: =IF($B$10="3BR_H", INDEX('ns-combined'!$C:$D,MATCH($L11,'ns-combined'!$B:$B,0),MATCH(Council_Area,'ns-combined'!$C$1:$D$1,0))*1000, INDEX('s-combined'!$C:$D,MATCH($L11,'s-combined'!$B:$B,0),MATCH(Council_Area,'s-combined'!$C$1:$D$1,0))*1000) -> 360000 | AS11: =AS10+$AS$3 -> 6300 | AT11: 0 | AU11: =SUM($B$28:$B$29)*AR11 -> 7200 | AV11: =AR11*$B$15/4 -> 1035 | AW11: =SUM($AV$3:AV11) -> 8133.375 | AX11: =AR11-AS11-AU11-AW11 -> 338366.62 | AY11: =$B$36*V11 -> 1228.5 | AZ11: =SUM(AY11:AY11)*4/AR11 -> 0.01365 | BA11: =SUM(AY11:AY11)/V11 -> 0.35 | BB11: =IF(MortgageRate="Discounted",_xlfn.XLOOKUP(L11,'mortgage-rates'!$A:$A,'mortgage-rates'!$E:$E)/100,_xlfn.XLOOKUP(L11,'mortgage-rates'!$A:$A,'mortgage-rates'!$D:$D)/100) -> 0.087 | BC11: =BC10-BF10 -> 217224.68 | BD11: =IF($B$16*12/3-Q11+1>0,-PMT($BB11/4,$B$16*12/3-Q11+1,BC11),0) -> 5481.8531 | BE11: =BC11*($BB11/4) -> 4724.6369 | BF11: =BD11-BE11 -> 757.21625 | BG11: =AT11+AY11+BD11 -> 6710.3531 | BH11: =INDEX(cpi!B:B,MATCH($L11,cpi!A:A)) -> 90.4 | BI11: =100*BH11/BH$3 -> 106.85579 | BJ11: =100*AC11/AC$3 -> 130.28618 | BK11: =100*AD11/AD$3 -> 144.48568 | BL11: =BJ11*GlobalPortfolio+BK11*AusPortfolio -> 134.54603 | BM11: =100*AE11/$AE$3 -> 167.28147 | BN11: =100*AR11/AR$3 -> 128.57143 | BO11: =100*AX11/AX$3 -> 123.99151
A12: Analysis end quarter | B12: 45992 | C12: 45992 | L12: =DATE(YEAR(L11),MONTH(L11)+3,1) -> 39600 | M12: =AP12 -> 110539.25 | N12: =AX12-BC12 -> 125049.78 | O12: =M12/N12 -> 0.88396197 | P12: =X12/BG12 -> 0.53711575 | Q12: 10 | R12: =EOMONTH(L12,0)-EOMONTH(L12,-3) -> 91 | T12: =IF($B$10="3BR_H", INDEX('3BR_H-processed'!$E:$F,MATCH($L12,'3BR_H-processed'!$B:$B,0),MATCH(Council_Area,'3BR_H-processed'!$E$1:$F$1,0)), INDEX('2BR_F-processed'!$E:$F,MATCH($L12,'2BR_F-processed'!$B:$B,0),MATCH(Council_Area,'2BR_F-processed'!$E$1:$F$1,0))) -> 270 | U12: =IF(MOD(Q12,4)=1,T12,U11) -> 270 | V12: =U12*(R12)/7 -> 3510 | W12: =$B$53/4*BH12/_xlfn.XLOOKUP(Q_end,cpi!A:A,cpi!B:B) -> 126.60677 | X12: =V12+W12 -> 3636.6068 | Y12: =BG12-X12 -> 3134.0135 | Z12: =Y12*$B$47 -> 0 | AA12: {=(Y12+Z12)*eff_invest} -> 3134.0135 | AB12: =AA12*(_xlfn.XLOOKUP(Q_end,cpi!A:A,cpi!B:B)/BH12) -> 4950.7833 | AC12: {=INDEX('msci-indices'!C:C,MATCH($L12,'msci-indices'!$B:$B)-2)} -> 894.99836 | AD12: {=INDEX('msci-indices'!D:D,MATCH($L12,'msci-indices'!$B:$B)-2)} -> 881.21373 | AE12: =AI11+AA12 -> 112297.04 | AF12: {=INDEX('msci-indices'!C:C,MATCH($L12,'msci-indices'!$B:$B)+1)} -> 881.79174 | AG12: {=INDEX('msci-indices'!D:D,MATCH($L12,'msci-indices'!$B:$B)+1)} -> 867.41147 | AH12: =(InvestFees/4)*AE12 -> 70.185653 | AI12: =((AF12/AC12)*GlobalPortfolio+(AG12/AD12)*AusPortfolio)*AE12-AH12 -> 110539.25 | AJ12: =AJ11+AA12 -> 98417.595 | AK12: =AI12-AJ12 -> 12121.658 | AL12: =AJ12*(_xlfn.XLOOKUP(Q_end,cpi!A:A,cpi!B:B)/BH12) -> 155469.72 | AM12: {=SUMPRODUCT($AA$3:AA12,_xlfn.SORTBY($BH$3:BH12,_xlfn.SEQUENCE(ROWS($BH$3:BH12)),-1)/$BH$3)} -> 105260.72 | AN12: =AI12-AM12 -> 5278.5284 | AO12: =IF($B$49="Real gains",MAX($B$50*AN12,0),IF($B$49="Discounted nominal gains",MAX($B$50*AK12/2,0),0)) -> 0 | AP12: =AI12-AO12 -> 110539.25 | AR12: =IF($B$10="3BR_H", INDEX('ns-combined'!$C:$D,MATCH($L12,'ns-combined'!$B:$B,0),MATCH(Council_Area,'ns-combined'!$C$1:$D$1,0))*1000, INDEX('s-combined'!$C:$D,MATCH($L12,'s-combined'!$B:$B,0),MATCH(Council_Area,'s-combined'!$C$1:$D$1,0))*1000) -> 365000 | AS12: =AS11+$AS$3 -> 7000 | AT12: 0 | AU12: =SUM($B$28:$B$29)*AR12 -> 7300 | AV12: =AR12*$B$15/4 -> 1049.375 | AW12: =SUM($AV$3:AV12) -> 9182.75 | AX12: =AR12-AS12-AU12-AW12 -> 341517.25 | AY12: =$B$36*V12 -> 1228.5 | AZ12: =SUM(AY12:AY12)*4/AR12 -> 0.013463014 | BA12: =SUM(AY12:AY12)/V12 -> 0.35 | BB12: =IF(MortgageRate="Discounted",_xlfn.XLOOKUP(L12,'mortgage-rates'!$A:$A,'mortgage-rates'!$E:$E)/100,_xlfn.XLOOKUP(L12,'mortgage-rates'!$A:$A,'mortgage-rates'!$D:$D)/100) -> 0.0884 | BC12: =BC11-BF11 -> 216467.47 | BD12: =IF($B$16*12/3-Q12+1>0,-PMT($BB12/4,$B$16*12/3-Q12+1,BC12),0) -> 5542.1202 | BE12: =BC12*($BB12/4) -> 4783.931 | BF12: =BD12-BE12 -> 758.18923 | BG12: =AT12+AY12+BD12 -> 6770.6202 | BH12: =INDEX(cpi!B:B,MATCH($L12,cpi!A:A)) -> 91.6 | BI12: =100*BH12/BH$3 -> 108.27423 | BJ12: =100*AC12/AC$3 -> 118.56173 | BK12: =100*AD12/AD$3 -> 123.59997 | BL12: =BJ12*GlobalPortfolio+BK12*AusPortfolio -> 120.07321 | BM12: =100*AE12/$AE$3 -> 153.67387 | BN12: =100*AR12/AR$3 -> 130.35714 | BO12: =100*AX12/AX$3 -> 125.14603
A13: Council/Area | B13: Adelaide | C13: Adelaide | L13: =DATE(YEAR(L12),MONTH(L12)+3,1) -> 39692 | M13: =AP13 -> 97842.264 | N13: =AX13-BC13 -> 119172.97 | O13: =M13/N13 -> 0.82101052 | P13: =X13/BG13 -> 0.54468574 | Q13: 11 | R13: =EOMONTH(L13,0)-EOMONTH(L13,-3) -> 92 | T13: =IF($B$10="3BR_H", INDEX('3BR_H-processed'!$E:$F,MATCH($L13,'3BR_H-processed'!$B:$B,0),MATCH(Council_Area,'3BR_H-processed'!$E$1:$F$1,0)), INDEX('2BR_F-processed'!$E:$F,MATCH($L13,'2BR_F-processed'!$B:$B,0),MATCH(Council_Area,'2BR_F-processed'!$E$1:$F$1,0))) -> 280 | U13: =IF(MOD(Q13,4)=1,T13,U12) -> 270 | V13: =U13*(R13)/7 -> 3548.5714 | W13: =$B$53/4*BH13/_xlfn.XLOOKUP(Q_end,cpi!A:A,cpi!B:B) -> 127.98894 | X13: =V13+W13 -> 3676.5604 | Y13: =BG13-X13 -> 3073.314 | Z13: =Y13*$B$47 -> 0 | AA13: {=(Y13+Z13)*eff_invest} -> 3073.314 | AB13: =AA13*(_xlfn.XLOOKUP(Q_end,cpi!A:A,cpi!B:B)/BH13) -> 4802.468 | AC13: {=INDEX('msci-indices'!C:C,MATCH($L13,'msci-indices'!$B:$B)-2)} -> 881.79174 | AD13: {=INDEX('msci-indices'!D:D,MATCH($L13,'msci-indices'!$B:$B)-2)} -> 867.41147 | AE13: =AI12+AA13 -> 113612.57 | AF13: {=INDEX('msci-indices'!C:C,MATCH($L13,'msci-indices'!$B:$B)+1)} -> 747.65998 | AG13: {=INDEX('msci-indices'!D:D,MATCH($L13,'msci-indices'!$B:$B)+1)} -> 775.74397 | AH13: =(InvestFees/4)*AE13 -> 71.007854 | AI13: =((AF13/AC13)*GlobalPortfolio+(AG13/AD13)*AusPortfolio)*AE13-AH13 -> 97842.264 | AJ13: =AJ12+AA13 -> 101490.91 | AK13: =AI13-AJ13 -> -3648.6448 | AL13: =AJ13*(_xlfn.XLOOKUP(Q_end,cpi!A:A,cpi!B:B)/BH13) -> 158593.25 | AM13: {=SUMPRODUCT($AA$3:AA13,_xlfn.SORTBY($BH$3:BH13,_xlfn.SEQUENCE(ROWS($BH$3:BH13)),-1)/$BH$3)} -> 109430.85 | AN13: =AI13-AM13 -> -11588.585 | AO13: =IF($B$49="Real gains",MAX($B$50*AN13,0),IF($B$49="Discounted nominal gains",MAX($B$50*AK13/2,0),0)) -> 0 | AP13: =AI13-AO13 -> 97842.264 | AR13: =IF($B$10="3BR_H", INDEX('ns-combined'!$C:$D,MATCH($L13,'ns-combined'!$B:$B,0),MATCH(Council_Area,'ns-combined'!$C$1:$D$1,0))*1000, INDEX('s-combined'!$C:$D,MATCH($L13,'s-combined'!$B:$B,0),MATCH(Council_Area,'s-combined'!$C$1:$D$1,0))*1000) -> 360000 | AS13: =AS12+$AS$3 -> 7700 | AT13: 0 | AU13: =SUM($B$28:$B$29)*AR13 -> 7200 | AV13: =AR13*$B$15/4 -> 1035 | AW13: =SUM($AV$3:AV13) -> 10217.75 | AX13: =AR13-AS13-AU13-AW13 -> 334882.25 | AY13: =$B$36*V13 -> 1242 | AZ13: =SUM(AY13:AY13)*4/AR13 -> 0.0138 | BA13: =SUM(AY13:AY13)/V13 -> 0.35 | BB13: =IF(MortgageRate="Discounted",_xlfn.XLOOKUP(L13,'mortgage-rates'!$A:$A,'mortgage-rates'!$E:$E)/100,_xlfn.XLOOKUP(L13,'mortgage-rates'!$A:$A,'mortgage-rates'!$D:$D)/100) -> 0.0876 | BC13: =BC12-BF12 -> 215709.28 | BD13: =IF($B$16*12/3-Q13+1>0,-PMT($BB13/4,$B$16*12/3-Q13+1,BC13),0) -> 5507.8744 | BE13: =BC13*($BB13/4) -> 4724.0332 | BF13: =BD13-BE13 -> 783.84123 | BG13: =AT13+AY13+BD13 -> 6749.8744 | BH13: =INDEX(cpi!B:B,MATCH($L13,cpi!A:A)) -> 92.6 | BI13: =100*BH13/BH$3 -> 109.45626 | BJ13: =100*AC13/AC$3 -> 116.81223 | BK13: =100*AD13/AD$3 -> 121.66405 | BL13: =BJ13*GlobalPortfolio+BK13*AusPortfolio -> 118.26778 | BM13: =100*AE13/$AE$3 -> 155.47411 | BN13: =100*AR13/AR$3 -> 128.57143 | BO13: =100*AX13/AX$3 -> 122.71469
A14: Depreciation (% of initial home value per year) | B14: 0.01 | C14: 0.01 | L14: =DATE(YEAR(L13),MONTH(L13)+3,1) -> 39783 | M14: =AP14 -> 78719.757 | N14: =AX14-BC14 -> 113336.19 | O14: =M14/N14 -> 0.69456859 | P14: =X14/BG14 -> 0.64389259 | Q14: 12 | R14: =EOMONTH(L14,0)-EOMONTH(L14,-3) -> 92 | T14: =IF($B$10="3BR_H", INDEX('3BR_H-processed'!$E:$F,MATCH($L14,'3BR_H-processed'!$B:$B,0),MATCH(Council_Area,'3BR_H-processed'!$E$1:$F$1,0)), INDEX('2BR_F-processed'!$E:$F,MATCH($L14,'2BR_F-processed'!$B:$B,0),MATCH(Council_Area,'2BR_F-processed'!$E$1:$F$1,0))) -> 280 | U14: =IF(MOD(Q14,4)=1,T14,U13) -> 270 | V14: =U14*(R14)/7 -> 3548.5714 | W14: =$B$53/4*BH14/_xlfn.XLOOKUP(Q_end,cpi!A:A,cpi!B:B) -> 127.98894 | X14: =V14+W14 -> 3676.5604 | Y14: =BG14-X14 -> 2033.3366 | Z14: =Y14*$B$47 -> 0 | AA14: {=(Y14+Z14)*eff_invest} -> 2033.3366 | AB14: =AA14*(_xlfn.XLOOKUP(Q_end,cpi!A:A,cpi!B:B)/BH14) -> 3177.3629 | AC14: {=INDEX('msci-indices'!C:C,MATCH($L14,'msci-indices'!$B:$B)-2)} -> 747.65998 | AD14: {=INDEX('msci-indices'!D:D,MATCH($L14,'msci-indices'!$B:$B)-2)} -> 775.74397 | AE14: =AI13+AA14 -> 99875.601 | AF14: {=INDEX('msci-indices'!C:C,MATCH($L14,'msci-indices'!$B:$B)+1)} -> 582.01082 | AG14: {=INDEX('msci-indices'!D:D,MATCH($L14,'msci-indices'!$B:$B)+1)} -> 630.6613 | AH14: =(InvestFees/4)*AE14 -> 62.422251 | AI14: =((AF14/AC14)*GlobalPortfolio+(AG14/AD14)*AusPortfolio)*AE14-AH14 -> 78719.757 | AJ14: =AJ13+AA14 -> 103524.25 | AK14: =AI14-AJ14 -> -24804.489 | AL14: =AJ14*(_xlfn.XLOOKUP(Q_end,cpi!A:A,cpi!B:B)/BH14) -> 161770.61 | AM14: {=SUMPRODUCT($AA$3:AA14,_xlfn.SORTBY($BH$3:BH14,_xlfn.SEQUENCE(ROWS($BH$3:BH14)),-1)/$BH$3)} -> 111730.17 | AN14: =AI14-AM14 -> -33010.409 | AO14: =IF($B$49="Real gains",MAX($B$50*AN14,0),IF($B$49="Discounted nominal gains",MAX($B$50*AK14/2,0),0)) -> 0 | AP14: =AI14-AO14 -> 78719.757 | AR14: =IF($B$10="3BR_H", INDEX('ns-combined'!$C:$D,MATCH($L14,'ns-combined'!$B:$B,0),MATCH(Council_Area,'ns-combined'!$C$1:$D$1,0))*1000, INDEX('s-combined'!$C:$D,MATCH($L14,'s-combined'!$B:$B,0),MATCH(Council_Area,'s-combined'!$C$1:$D$1,0))*1000) -> 355000 | AS14: =AS13+$AS$3 -> 8400 | AT14: 0 | AU14: =SUM($B$28:$B$29)*AR14 -> 7100 | AV14: =AR14*$B$15/4 -> 1020.625 | AW14: =SUM($AV$3:AV14) -> 11238.375 | AX14: =AR14-AS14-AU14-AW14 -> 328261.62 | AY14: =$B$36*V14 -> 1242 | AZ14: =SUM(AY14:AY14)*4/AR14 -> 0.013994366 | BA14: =SUM(AY14:AY14)/V14 -> 0.35 | BB14: =IF(MortgageRate="Discounted",_xlfn.XLOOKUP(L14,'mortgage-rates'!$A:$A,'mortgage-rates'!$E:$E)/100,_xlfn.XLOOKUP(L14,'mortgage-rates'!$A:$A,'mortgage-rates'!$D:$D)/100) -> 0.062 | BC14: =BC13-BF13 -> 214925.44 | BD14: =IF($B$16*12/3-Q14+1>0,-PMT($BB14/4,$B$16*12/3-Q14+1,BC14),0) -> 4467.897 | BE14: =BC14*($BB14/4) -> 3331.3443 | BF14: =BD14-BE14 -> 1136.5527 | BG14: =AT14+AY14+BD14 -> 5709.897 | BH14: =INDEX(cpi!B:B,MATCH($L14,cpi!A:A)) -> 92.6 | BI14: =100*BH14/BH$3 -> 109.45626 | BJ14: =100*AC14/AC$3 -> 99.043605 | BK14: =100*AD14/AD$3 -> 108.80667 | BL14: =BJ14*GlobalPortfolio+BK14*AusPortfolio -> 101.97253 | BM14: =100*AE14/$AE$3 -> 136.67564 | BN14: =100*AR14/AR$3 -> 126.78571 | BO14: =100*AX14/AX$3 -> 120.28862
A15: Renovations, alterations, and additions (% of current home value per year) | B15: 0.0115 | C15: 0.0115 | L15: =DATE(YEAR(L14),MONTH(L14)+3,1) -> 39873 | M15: =AP15 -> 73251.696 | N15: =AX15-BC15 -> 111286.43 | O15: =M15/N15 -> 0.65822668 | P15: =X15/BG15 -> 0.71544858 | Q15: 13 | R15: =EOMONTH(L15,0)-EOMONTH(L15,-3) -> 90 | T15: =IF($B$10="3BR_H", INDEX('3BR_H-processed'!$E:$F,MATCH($L15,'3BR_H-processed'!$B:$B,0),MATCH(Council_Area,'3BR_H-processed'!$E$1:$F$1,0)), INDEX('2BR_F-processed'!$E:$F,MATCH($L15,'2BR_F-processed'!$B:$B,0),MATCH(Council_Area,'2BR_F-processed'!$E$1:$F$1,0))) -> 290 | U15: =IF(MOD(Q15,4)=1,T15,U14) -> 290 | V15: =U15*(R15)/7 -> 3728.5714 | W15: =$B$53/4*BH15/_xlfn.XLOOKUP(Q_end,cpi!A:A,cpi!B:B) -> 127.85073 | X15: =V15+W15 -> 3856.4222 | Y15: =BG15-X15 -> 1533.7935 | Z15: =Y15*$B$47 -> 0 | AA15: {=(Y15+Z15)*eff_invest} -> 1533.7935 | AB15: =AA15*(_xlfn.XLOOKUP(Q_end,cpi!A:A,cpi!B:B)/BH15) -> 2399.3505 | AC15: {=INDEX('msci-indices'!C:C,MATCH($L15,'msci-indices'!$B:$B)-2)} -> 582.01082 | AD15: {=INDEX('msci-indices'!D:D,MATCH($L15,'msci-indices'!$B:$B)-2)} -> 630.6613 | AE15: =AI14+AA15 -> 80253.551 | AF15: {=INDEX('msci-indices'!C:C,MATCH($L15,'msci-indices'!$B:$B)+1)} -> 513.55423 | AG15: {=INDEX('msci-indices'!D:D,MATCH($L15,'msci-indices'!$B:$B)+1)} -> 621.64895 | AH15: =(InvestFees/4)*AE15 -> 50.158469 | AI15: =((AF15/AC15)*GlobalPortfolio+(AG15/AD15)*AusPortfolio)*AE15-AH15 -> 73251.696 | AJ15: =AJ14+AA15 -> 105058.04 | AK15: =AI15-AJ15 -> -31806.343 | AL15: =AJ15*(_xlfn.XLOOKUP(Q_end,cpi!A:A,cpi!B:B)/BH15) -> 164344.85 | AM15: {=SUMPRODUCT($AA$3:AA15,_xlfn.SORTBY($BH$3:BH15,_xlfn.SEQUENCE(ROWS($BH$3:BH15)),-1)/$BH$3)} -> 113430.1 | AN15: =AI15-AM15 -> -40178.405 | AO15: =IF($B$49="Real gains",MAX($B$50*AN15,0),IF($B$49="Discounted nominal gains",MAX($B$50*AK15/2,0),0)) -> 0 | AP15: =AI15-AO15 -> 73251.696 | AR15: =IF($B$10="3BR_H", INDEX('ns-combined'!$C:$D,MATCH($L15,'ns-combined'!$B:$B,0),MATCH(Council_Area,'ns-combined'!$C$1:$D$1,0))*1000, INDEX('s-combined'!$C:$D,MATCH($L15,'s-combined'!$B:$B,0),MATCH(Council_Area,'s-combined'!$C$1:$D$1,0))*1000) -> 353500 | AS15: =AS14+$AS$3 -> 9100 | AT15: 0 | AU15: =SUM($B$28:$B$29)*AR15 -> 7070 | AV15: =AR15*$B$15/4 -> 1016.3125 | AW15: =SUM($AV$3:AV15) -> 12254.688 | AX15: =AR15-AS15-AU15-AW15 -> 325075.31 | AY15: =$B$36*V15 -> 1305 | AZ15: =SUM(AY15:AY15)*4/AR15 -> 0.01476662 | BA15: =SUM(AY15:AY15)/V15 -> 0.35 | BB15: =IF(MortgageRate="Discounted",_xlfn.XLOOKUP(L15,'mortgage-rates'!$A:$A,'mortgage-rates'!$E:$E)/100,_xlfn.XLOOKUP(L15,'mortgage-rates'!$A:$A,'mortgage-rates'!$D:$D)/100) -> 0.0518 | BC15: =BC14-BF14 -> 213788.88 | BD15: =IF($B$16*12/3-Q15+1>0,-PMT($BB15/4,$B$16*12/3-Q15+1,BC15),0) -> 4085.2157 | BE15: =BC15*($BB15/4) -> 2768.566 | BF15: =BD15-BE15 -> 1316.6496 | BG15: =AT15+AY15+BD15 -> 5390.2157 | BH15: =INDEX(cpi!B:B,MATCH($L15,cpi!A:A)) -> 92.5 | BI15: =100*BH15/BH$3 -> 109.33806 | BJ15: =100*AC15/AC$3 -> 77.099819 | BK15: =100*AD15/AD$3 -> 88.457223 | BL15: =BJ15*GlobalPortfolio+BK15*AusPortfolio -> 80.50704 | BM15: =100*AE15/$AE$3 -> 109.82367 | BN15: =100*AR15/AR$3 -> 126.25 | BO15: =100*AX15/AX$3 -> 119.12102
A16: Loan term (years) | B16: 25 | C16: 25 | L16: =DATE(YEAR(L15),MONTH(L15)+3,1) -> 39965 | M16: =AP16 -> 88610.666 | N16: =AX16-BC16 -> 120169.45 | O16: =M16/N16 -> 0.73738095 | P16: =X16/BG16 -> 0.7232661 | Q16: 14 | R16: =EOMONTH(L16,0)-EOMONTH(L16,-3) -> 91 | T16: =IF($B$10="3BR_H", INDEX('3BR_H-processed'!$E:$F,MATCH($L16,'3BR_H-processed'!$B:$B,0),MATCH(Council_Area,'3BR_H-processed'!$E$1:$F$1,0)), INDEX('2BR_F-processed'!$E:$F,MATCH($L16,'2BR_F-processed'!$B:$B,0),MATCH(Council_Area,'2BR_F-processed'!$E$1:$F$1,0))) -> 290 | U16: =IF(MOD(Q16,4)=1,T16,U15) -> 290 | V16: =U16*(R16)/7 -> 3770 | W16: =$B$53/4*BH16/_xlfn.XLOOKUP(Q_end,cpi!A:A,cpi!B:B) -> 128.54181 | X16: =V16+W16 -> 3898.5418 | Y16: =BG16-X16 -> 1491.6483 | Z16: =Y16*$B$47 -> 0 | AA16: {=(Y16+Z16)*eff_invest} -> 1491.6483 | AB16: =AA16*(_xlfn.XLOOKUP(Q_end,cpi!A:A,cpi!B:B)/BH16) -> 2320.8765 | AC16: {=INDEX('msci-indices'!C:C,MATCH($L16,'msci-indices'!$B:$B)-2)} -> 513.55423 | AD16: {=INDEX('msci-indices'!D:D,MATCH($L16,'msci-indices'!$B:$B)-2)} -> 621.64895 | AE16: =AI15+AA16 -> 74743.344 | AF16: {=INDEX('msci-indices'!C:C,MATCH($L16,'msci-indices'!$B:$B)+1)} -> 624.35598 | AG16: {=INDEX('msci-indices'!D:D,MATCH($L16,'msci-indices'!$B:$B)+1)} -> 694.44245 | AH16: =(InvestFees/4)*AE16 -> 46.71459 | AI16: =((AF16/AC16)*GlobalPortfolio+(AG16/AD16)*AusPortfolio)*AE16-AH16 -> 88610.666 | AJ16: =AJ15+AA16 -> 106549.69 | AK16: =AI16-AJ16 -> -17939.021 | AL16: =AJ16*(_xlfn.XLOOKUP(Q_end,cpi!A:A,cpi!B:B)/BH16) -> 165782.15 | AM16: {=SUMPRODUCT($AA$3:AA16,_xlfn.SORTBY($BH$3:BH16,_xlfn.SEQUENCE(ROWS($BH$3:BH16)),-1)/$BH$3)} -> 115590.49 | AN16: =AI16-AM16 -> -26979.826 | AO16: =IF($B$49="Real gains",MAX($B$50*AN16,0),IF($B$49="Discounted nominal gains",MAX($B$50*AK16/2,0),0)) -> 0 | AP16: =AI16-AO16 -> 88610.666 | AR16: =IF($B$10="3BR_H", INDEX('ns-combined'!$C:$D,MATCH($L16,'ns-combined'!$B:$B,0),MATCH(Council_Area,'ns-combined'!$C$1:$D$1,0))*1000, INDEX('s-combined'!$C:$D,MATCH($L16,'s-combined'!$B:$B,0),MATCH(Council_Area,'s-combined'!$C$1:$D$1,0))*1000) -> 363000 | AS16: =AS15+$AS$3 -> 9800 | AT16: 0 | AU16: =SUM($B$28:$B$29)*AR16 -> 7260 | AV16: =AR16*$B$15/4 -> 1043.625 | AW16: =SUM($AV$3:AV16) -> 13298.312 | AX16: =AR16-AS16-AU16-AW16 -> 332641.69 | AY16: =$B$36*V16 -> 1319.5 | AZ16: =SUM(AY16:AY16)*4/AR16 -> 0.014539945 | BA16: =SUM(AY16:AY16)/V16 -> 0.35 | BB16: =IF(MortgageRate="Discounted",_xlfn.XLOOKUP(L16,'mortgage-rates'!$A:$A,'mortgage-rates'!$E:$E)/100,_xlfn.XLOOKUP(L16,'mortgage-rates'!$A:$A,'mortgage-rates'!$D:$D)/100) -> 0.0514 | BC16: =BC15-BF15 -> 212472.23 | BD16: =IF($B$16*12/3-Q16+1>0,-PMT($BB16/4,$B$16*12/3-Q16+1,BC16),0) -> 4070.6901 | BE16: =BC16*($BB16/4) -> 2730.2682 | BF16: =BD16-BE16 -> 1340.4219 | BG16: =AT16+AY16+BD16 -> 5390.1901 | BH16: =INDEX(cpi!B:B,MATCH($L16,cpi!A:A)) -> 93 | BI16: =100*BH16/BH$3 -> 109.92908 | BJ16: =100*AC16/AC$3 -> 68.031276 | BK16: =100*AD16/AD$3 -> 87.193142 | BL16: =BJ16*GlobalPortfolio+BK16*AusPortfolio -> 73.779836 | BM16: =100*AE16/$AE$3 -> 102.28318 | BN16: =100*AR16/AR$3 -> 129.64286 | BO16: =100*AX16/AX$3 -> 121.89365
L17: =DATE(YEAR(L16),MONTH(L16)+3,1) -> 40057 | M17: =AP17 -> 107409.03 | N17: =AX17-BC17 -> 126606.13 | O17: =M17/N17 -> 0.84837154 | P17: =X17/BG17 -> 0.72917 | Q17: 15 | R17: =EOMONTH(L17,0)-EOMONTH(L17,-3) -> 92 | T17: =IF($B$10="3BR_H", INDEX('3BR_H-processed'!$E:$F,MATCH($L17,'3BR_H-processed'!$B:$B,0),MATCH(Council_Area,'3BR_H-processed'!$E$1:$F$1,0)), INDEX('2BR_F-processed'!$E:$F,MATCH($L17,'2BR_F-processed'!$B:$B,0),MATCH(Council_Area,'2BR_F-processed'!$E$1:$F$1,0))) -> 295 | U17: =IF(MOD(Q17,4)=1,T17,U16) -> 290 | V17: =U17*(R17)/7 -> 3811.4286 | W17: =$B$53/4*BH17/_xlfn.XLOOKUP(Q_end,cpi!A:A,cpi!B:B) -> 129.50933 | X17: =V17+W17 -> 3940.9379 | Y17: =BG17-X17 -> 1463.7522 | Z17: =Y17*$B$47 -> 0 | AA17: {=(Y17+Z17)*eff_invest} -> 1463.7522 | AB17: =AA17*(_xlfn.XLOOKUP(Q_end,cpi!A:A,cpi!B:B)/BH17) -> 2260.4584 | AC17: {=INDEX('msci-indices'!C:C,MATCH($L17,'msci-indices'!$B:$B)-2)} -> 624.35598 | AD17: {=INDEX('msci-indices'!D:D,MATCH($L17,'msci-indices'!$B:$B)-2)} -> 694.44245 | AE17: =AI16+AA17 -> 90074.419 | AF17: {=INDEX('msci-indices'!C:C,MATCH($L17,'msci-indices'!$B:$B)+1)} -> 736.86333 | AG17: {=INDEX('msci-indices'!D:D,MATCH($L17,'msci-indices'!$B:$B)+1)} -> 849.38296 | AH17: =(InvestFees/4)*AE17 -> 56.296512 | AI17: =((AF17/AC17)*GlobalPortfolio+(AG17/AD17)*AusPortfolio)*AE17-AH17 -> 107409.03 | AJ17: =AJ16+AA17 -> 108013.44 | AK17: =AI17-AJ17 -> -604.40635 | AL17: =AJ17*(_xlfn.XLOOKUP(Q_end,cpi!A:A,cpi!B:B)/BH17) -> 166804.11 | AM17: {=SUMPRODUCT($AA$3:AA17,_xlfn.SORTBY($BH$3:BH17,_xlfn.SEQUENCE(ROWS($BH$3:BH17)),-1)/$BH$3)} -> 117907.86 | AN17: =AI17-AM17 -> -10498.822 | AO17: =IF($B$49="Real gains",MAX($B$50*AN17,0),IF($B$49="Discounted nominal gains",MAX($B$50*AK17/2,0),0)) -> 0 | AP17: =AI17-AO17 -> 107409.03 | AR17: =IF($B$10="3BR_H", INDEX('ns-combined'!$C:$D,MATCH($L17,'ns-combined'!$B:$B,0),MATCH(Council_Area,'ns-combined'!$C$1:$D$1,0))*1000, INDEX('s-combined'!$C:$D,MATCH($L17,'s-combined'!$B:$B,0),MATCH(Council_Area,'s-combined'!$C$1:$D$1,0))*1000) -> 370000 | AS17: =AS16+$AS$3 -> 10500 | AT17: 0 | AU17: =SUM($B$28:$B$29)*AR17 -> 7400 | AV17: =AR17*$B$15/4 -> 1063.75 | AW17: =SUM($AV$3:AV17) -> 14362.062 | AX17: =AR17-AS17-AU17-AW17 -> 337737.94 | AY17: =$B$36*V17 -> 1334 | AZ17: =SUM(AY17:AY17)*4/AR17 -> 0.014421622 | BA17: =SUM(AY17:AY17)/V17 -> 0.35 | BB17: =IF(MortgageRate="Discounted",_xlfn.XLOOKUP(L17,'mortgage-rates'!$A:$A,'mortgage-rates'!$E:$E)/100,_xlfn.XLOOKUP(L17,'mortgage-rates'!$A:$A,'mortgage-rates'!$D:$D)/100) -> 0.0514 | BC17: =BC16-BF16 -> 211131.81 | BD17: =IF($B$16*12/3-Q17+1>0,-PMT($BB17/4,$B$16*12/3-Q17+1,BC17),0) -> 4070.6901 | BE17: =BC17*($BB17/4) -> 2713.0438 | BF17: =BD17-BE17 -> 1357.6463 | BG17: =AT17+AY17+BD17 -> 5404.6901 | BH17: =INDEX(cpi!B:B,MATCH($L17,cpi!A:A)) -> 93.7 | BI17: =100*BH17/BH$3 -> 110.7565 | BJ17: =100*AC17/AC$3 -> 82.709345 | BK17: =100*AD17/AD$3 -> 97.403235 | BL17: =BJ17*GlobalPortfolio+BK17*AusPortfolio -> 87.117512 | BM17: =100*AE17/$AE$3 -> 123.26312 | BN17: =100*AR17/AR$3 -> 132.14286 | BO17: =100*AX17/AX$3 -> 123.76113
A18: Mortgage | L18: =DATE(YEAR(L17),MONTH(L17)+3,1) -> 40148 | M18: =AP18 -> 113227.84 | N18: =AX18-BC18 -> 154341.22 | O18: =M18/N18 -> 0.73362019 | P18: =X18/BG18 -> 0.68952855 | Q18: 16 | R18: =EOMONTH(L18,0)-EOMONTH(L18,-3) -> 92 | T18: =IF($B$10="3BR_H", INDEX('3BR_H-processed'!$E:$F,MATCH($L18,'3BR_H-processed'!$B:$B,0),MATCH(Council_Area,'3BR_H-processed'!$E$1:$F$1,0)), INDEX('2BR_F-processed'!$E:$F,MATCH($L18,'2BR_F-processed'!$B:$B,0),MATCH(Council_Area,'2BR_F-processed'!$E$1:$F$1,0))) -> 300 | U18: =IF(MOD(Q18,4)=1,T18,U17) -> 290 | V18: =U18*(R18)/7 -> 3811.4286 | W18: =$B$53/4*BH18/_xlfn.XLOOKUP(Q_end,cpi!A:A,cpi!B:B) -> 130.61507 | X18: =V18+W18 -> 3942.0436 | Y18: =BG18-X18 -> 1774.9693 | Z18: =Y18*$B$47 -> 0 | AA18: {=(Y18+Z18)*eff_invest} -> 1774.9693 | AB18: =AA18*(_xlfn.XLOOKUP(Q_end,cpi!A:A,cpi!B:B)/BH18) -> 2717.8631 | AC18: {=INDEX('msci-indices'!C:C,MATCH($L18,'msci-indices'!$B:$B)-2)} -> 736.86333 | AD18: {=INDEX('msci-indices'!D:D,MATCH($L18,'msci-indices'!$B:$B)-2)} -> 849.38296 | AE18: =AI17+AA18 -> 109184 | AF18: {=INDEX('msci-indices'!C:C,MATCH($L18,'msci-indices'!$B:$B)+1)} -> 765.74116 | AG18: {=INDEX('msci-indices'!D:D,MATCH($L18,'msci-indices'!$B:$B)+1)} -> 878.3433 | AH18: =(InvestFees/4)*AE18 -> 68.240002 | AI18: =((AF18/AC18)*GlobalPortfolio+(AG18/AD18)*AusPortfolio)*AE18-AH18 -> 113227.84 | AJ18: =AJ17+AA18 -> 109788.41 | AK18: =AI18-AJ18 -> 3439.4277 | AL18: =AJ18*(_xlfn.XLOOKUP(Q_end,cpi!A:A,cpi!B:B)/BH18) -> 168109.87 | AM18: {=SUMPRODUCT($AA$3:AA18,_xlfn.SORTBY($BH$3:BH18,_xlfn.SEQUENCE(ROWS($BH$3:BH18)),-1)/$BH$3)} -> 120647.83 | AN18: =AI18-AM18 -> -7419.9938 | AO18: =IF($B$49="Real gains",MAX($B$50*AN18,0),IF($B$49="Discounted nominal gains",MAX($B$50*AK18/2,0),0)) -> 0 | AP18: =AI18-AO18 -> 113227.84 | AR18: =IF($B$10="3BR_H", INDEX('ns-combined'!$C:$D,MATCH($L18,'ns-combined'!$B:$B,0),MATCH(Council_Area,'ns-combined'!$C$1:$D$1,0))*1000, INDEX('s-combined'!$C:$D,MATCH($L18,'s-combined'!$B:$B,0),MATCH(Council_Area,'s-combined'!$C$1:$D$1,0))*1000) -> 398800 | AS18: =AS17+$AS$3 -> 11200 | AT18: 0 | AU18: =SUM($B$28:$B$29)*AR18 -> 7976 | AV18: =AR18*$B$15/4 -> 1146.55 | AW18: =SUM($AV$3:AV18) -> 15508.612 | AX18: =AR18-AS18-AU18-AW18 -> 364115.39 | AY18: =$B$36*V18 -> 1334 | AZ18: =SUM(AY18:AY18)*4/AR18 -> 0.01338014 | BA18: =SUM(AY18:AY18)/V18 -> 0.35 | BB18: =IF(MortgageRate="Discounted",_xlfn.XLOOKUP(L18,'mortgage-rates'!$A:$A,'mortgage-rates'!$E:$E)/100,_xlfn.XLOOKUP(L18,'mortgage-rates'!$A:$A,'mortgage-rates'!$D:$D)/100) -> 0.06 | BC18: =BC17-BF17 -> 209774.17 | BD18: =IF($B$16*12/3-Q18+1>0,-PMT($BB18/4,$B$16*12/3-Q18+1,BC18),0) -> 4383.013 | BE18: =BC18*($BB18/4) -> 3146.6125 | BF18: =BD18-BE18 -> 1236.4005 | BG18: =AT18+AY18+BD18 -> 5717.013 | BH18: =INDEX(cpi!B:B,MATCH($L18,cpi!A:A)) -> 94.5 | BI18: =100*BH18/BH$3 -> 111.70213 | BJ18: =100*AC18/AC$3 -> 97.613357 | BK18: =100*AD18/AD$3 -> 119.13536 | BL18: =BJ18*GlobalPortfolio+BK18*AusPortfolio -> 104.06996 | BM18: =100*AE18/$AE$3 -> 149.4138 | BN18: =100*AR18/AR$3 -> 142.42857 | BO18: =100*AX18/AX$3 -> 133.42692
A19: Mortgage rates (Standard/Discounted) | B19: Discounted | C19: Discounted | L19: =DATE(YEAR(L18),MONTH(L18)+3,1) -> 40238 | M19: =AP19 -> 118545.3 | N19: =AX19-BC19 -> 156857.87 | O19: =M19/N19 -> 0.75574973 | P19: =X19/BG19 -> 0.70139412 | Q19: 17 | R19: =EOMONTH(L19,0)-EOMONTH(L19,-3) -> 90 | T19: =IF($B$10="3BR_H", INDEX('3BR_H-processed'!$E:$F,MATCH($L19,'3BR_H-processed'!$B:$B,0),MATCH(Council_Area,'3BR_H-processed'!$E$1:$F$1,0)), INDEX('2BR_F-processed'!$E:$F,MATCH($L19,'2BR_F-processed'!$B:$B,0),MATCH(Council_Area,'2BR_F-processed'!$E$1:$F$1,0))) -> 310 | U19: =IF(MOD(Q19,4)=1,T19,U18) -> 310 | V19: =U19*(R19)/7 -> 3985.7143 | W19: =$B$53/4*BH19/_xlfn.XLOOKUP(Q_end,cpi!A:A,cpi!B:B) -> 131.58258 | X19: =V19+W19 -> 4117.2969 | Y19: =BG19-X19 -> 1752.8647 | Z19: =Y19*$B$47 -> 0 | AA19: {=(Y19+Z19)*eff_invest} -> 1752.8647 | AB19: =AA19*(_xlfn.XLOOKUP(Q_end,cpi!A:A,cpi!B:B)/BH19) -> 2664.2808 | AC19: {=INDEX('msci-indices'!C:C,MATCH($L19,'msci-indices'!$B:$B)-2)} -> 765.74116 | AD19: {=INDEX('msci-indices'!D:D,MATCH($L19,'msci-indices'!$B:$B)-2)} -> 878.3433 | AE19: =AI18+AA19 -> 114980.7 | AF19: {=INDEX('msci-indices'!C:C,MATCH($L19,'msci-indices'!$B:$B)+1)} -> 794.63718 | AG19: {=INDEX('msci-indices'!D:D,MATCH($L19,'msci-indices'!$B:$B)+1)} -> 893.60148 | AH19: =(InvestFees/4)*AE19 -> 71.862938 | AI19: =((AF19/AC19)*GlobalPortfolio+(AG19/AD19)*AusPortfolio)*AE19-AH19 -> 118545.3 | AJ19: =AJ18+AA19 -> 111541.27 | AK19: =AI19-AJ19 -> 7004.0214 | AL19: =AJ19*(_xlfn.XLOOKUP(Q_end,cpi!A:A,cpi!B:B)/BH19) -> 169538.05 | AM19: {=SUMPRODUCT($AA$3:AA19,_xlfn.SORTBY($BH$3:BH19,_xlfn.SEQUENCE(ROWS($BH$3:BH19)),-1)/$BH$3)} -> 123303.08 | AN19: =AI19-AM19 -> -4757.7846 | AO19: =IF($B$49="Real gains",MAX($B$50*AN19,0),IF($B$49="Discounted nominal gains",MAX($B$50*AK19/2,0),0)) -> 0 | AP19: =AI19-AO19 -> 118545.3 | AR19: =IF($B$10="3BR_H", INDEX('ns-combined'!$C:$D,MATCH($L19,'ns-combined'!$B:$B,0),MATCH(Council_Area,'ns-combined'!$C$1:$D$1,0))*1000, INDEX('s-combined'!$C:$D,MATCH($L19,'s-combined'!$B:$B,0),MATCH(Council_Area,'s-combined'!$C$1:$D$1,0))*1000) -> 402000 | AS19: =AS18+$AS$3 -> 11900 | AT19: 0 | AU19: =SUM($B$28:$B$29)*AR19 -> 8040 | AV19: =AR19*$B$15/4 -> 1155.75 | AW19: =SUM($AV$3:AV19) -> 16664.362 | AX19: =AR19-AS19-AU19-AW19 -> 365395.64 | AY19: =$B$36*V19 -> 1395 | AZ19: =SUM(AY19:AY19)*4/AR19 -> 0.013880597 | BA19: =SUM(AY19:AY19)/V19 -> 0.35 | BB19: =IF(MortgageRate="Discounted",_xlfn.XLOOKUP(L19,'mortgage-rates'!$A:$A,'mortgage-rates'!$E:$E)/100,_xlfn.XLOOKUP(L19,'mortgage-rates'!$A:$A,'mortgage-rates'!$D:$D)/100) -> 0.0625 | BC19: =BC18-BF18 -> 208537.77 | BD19: =IF($B$16*12/3-Q19+1>0,-PMT($BB19/4,$B$16*12/3-Q19+1,BC19),0) -> 4475.1616 | BE19: =BC19*($BB19/4) -> 3258.4026 | BF19: =BD19-BE19 -> 1216.759 | BG19: =AT19+AY19+BD19 -> 5870.1616 | BH19: =INDEX(cpi!B:B,MATCH($L19,cpi!A:A)) -> 95.2 | BI19: =100*BH19/BH$3 -> 112.52955 | BJ19: =100*AC19/AC$3 -> 101.43885 | BK19: =100*AD19/AD$3 -> 123.19736 | BL19: =BJ19*GlobalPortfolio+BK19*AusPortfolio -> 107.9664 | BM19: =100*AE19/$AE$3 -> 157.34634 | BN19: =100*AR19/AR$3 -> 143.57143 | BO19: =100*AX19/AX$3 -> 133.89605
